Workbook
Name NativeTimeline_Mese: #N/A

Sheet LuT_CdC
A1: Centro di Costo | B1: Descrizione
A2: 1 | B2: P01 - CONFEZIONAMENTO PDT
A3: 2 | B3: P02 - QC- STIRO - PACK
A4: 5 | B4: P05 - PROTOTIPIA PDT
A5: 6 | B5: P06 - CARCERE PDT
A6: 7 | B6: A06 - LOGIST/MAGAZ AUSIL
A7: 8 | B7: A07 - OPERATION AUSIL
A8: 9 | B8: A08 - UFF.PRODOTTO AUSIL
A9: 10 | B9: A09 - TEMPI E METOD AUSIL
A10: 11 | B10: A10 - COORD.CARCERE AUSIL
A11: 12 | B11: S10 - AMM DIREZ STRUTTURA
A12: 13 | B12: S11 - PERS&PROG STRUTTURA
A13: 14 | B13: S12 - COMM. MKTG. RETAIL
... A15: 17 | B15: P07 - TAGLIO

Sheet Pivot_MoM
A3: Sum of Actual | B3: Column Labels
A4: Row Labels | B4: 45688 | C4: 45716 | D4: 45747 | E4: 45777 | F4: 45808 | G4: 45838 | H4: 45869 | I4: 45900 | J4: 45930 | K4: 45961 | L4: 45991 | M4: 46022 | N4: Grand Total
A5: Diretti | B5: 193028.42 | C5: 181321.37 | D5: 186222.85 | E5: 206640.47 | F5: 202783.22 | G5: 193293.81 | H5: 0 | I5: 0 | J5: 0 | K5: 0 | L5: 0 | M5: 0 | N5: 1163290.1
A6: P01 - CONFEZIONAMENTO PDT | B6: 117894.08 | C6: 106929 | D6: 112390.03 | E6: 125311.36 | F6: 122130.72 | G6: 117990.91 | H6: 0 | I6: 0 | J6: 0 | K6: 0 | L6: 0 | M6: 0 | N6: 702646.1
A7: P02 - QC- STIRO - PACK | B7: 40071.55 | C7: 36944.3 | D7: 39823.61 | E7: 44384.09 | F7: 43077.97 | G7: 39944.35 | H7: 0 | I7: 0 | J7: 0 | K7: 0 | L7: 0 | M7: 0 | N7: 244245.87
A8: P05 - PROTOTIPIA PDT | B8: 4629.27 | C8: 4699.88 | D8: 4647.13 | E8: 4632.09 | F8: 4419.63 | G8: 4557.18 | H8: 0 | I8: 0 | J8: 0 | K8: 0 | L8: 0 | M8: 0 | N8: 27585.18
A9: P06 - CARCERE PDT | B9: 23507.35 | C9: 26188.71 | D9: 22262.63 | E9: 24756.65 | F9: 26163.98 | G9: 24066.34 | H9: 0 | I9: 0 | J9: 0 | K9: 0 | L9: 0 | M9: 0 | N9: 146945.66
A10: P07 - TAGLIO | B10: 6926.17 | C10: 6559.48 | D10: 7099.45 | E10: 7556.28 | F10: 6990.92 | G10: 6735.03 | H10: 0 | I10: 0 | J10: 0 | K10: 0 | L10: 0 | M10: 0 | N10: 41867.33
A11: Indiretti | B11: 67549.05 | C11: 61114.63 | D11: 66677.33 | E11: 71969.28 | F11: 55543.37 | G11: 63935.8 | H11: 0 | I11: 0 | J11: 0 | K11: 0 | L11: 0 | M11: 0 | N11: 386789.46
A12: A06 - LOGIST/MAGAZ AUSIL | B12: 14301.29 | C12: 13758.74 | D12: 14280.98 | E12: 15551.01 | F12: 14792.79 | G12: 14064.49 | H12: 0 | I12: 0 | J12: 0 | K12: 0 | L12: 0 | M12: 0 | N12: 86749.3
A13: A07 - OPERATION AUSIL | B13: 17823.19 | C13: 18005.2 | D13: 21717.1 | E13: 25866.42 | F13: 1122.71 | G13: 14013.05 | H13: 0 | I13: 0 | J13: 0 | K13: 0 | L13: 0 | M13: 0 | N13: 98547.67
A14: A08 - UFF.PRODOTTO AUSIL | B14: 18208.15 | C14: 15101.5 | D14: 15663.57 | E14: 15917.77 | F14: 26291.31 | G14: 17915.96 | H14: 0 | I14: 0 | J14: 0 | K14: 0 | L14: 0 | M14: 0 | N14: 109098.26
A15: A09 - TEMPI E METOD AUSIL | B15: 6092.07 | C15: 4117.82 | D15: 4246.26 | E15: 3270.4 | F15: 3976.38 | G15: 4894.86 | H15: 0 | I15: 0 | J15: 0 | K15: 0 | L15: 0 | M15: 0 | N15: 26597.79
A16: A10 - COORD.CARCERE AUSIL | B16: 11124.35 | C16: 10131.37 | D16: 10769.42 | E16: 11363.68 | F16: 9360.18 | G16: 13047.44 | H16: 0 | I16: 0 | J16: 0 | K16: 0 | L16: 0 | M16: 0 | N16: 65796.44
... A20: S12 - COMM. MKTG. RETAIL | B20: 45908.35 | C20: 41559.84 | D20: 46339.1 | E20: 51839.93 | F20: 29871.31 | G20: 37155.39 | H20: 0 | I20: 0 | J20: 0 | K20: 0 | L20: 0 | M20: 0 | N20: 252673.92
A21: Progetto Yeah | B21: 34764.63 | C21: 19465.94 | D21: 19923.73 | E21: 19121.6 | F21: 19458.51 | G21: 34336.95 | N21: 147071.36
A22: S13 - PROGETTO YEAH | B22: 34764.63 | C22: 19465.94 | D22: 19923.73 | E22: 19121.6 | F22: 19458.51 | G22: 34336.95 | N22: 147071.36
A23: Grand Total | B23: 373750.68 | C23: 339053.86 | D23: 354502.6 | E23: 393612.51 | F23: 364779.79 | G23: 366734.52 | H23: 0 | I23: 0 | J23: 0 | K23: 0 | L23: 0 | M23: 0 | N23: 2192434

Sheet Pivot_Scostamento
A10: Etichette di riga | B10: ORE LAV. | C10: ACTUAL | D10: BUDGET | E10: SCOST. | F10: (%)
A11: Group2 | B11: 72640.5 | C11: 1163290.1 | D11: 1159365.9 | E11: 3924.224 | F11: 0.0033848019
A12: P01 - CONFEZIONAMENTO PDT | B12: 42283.5 | C12: 702646.1 | D12: 682761.35 | E12: 19884.75 | F12: 0.029124012
A13: P02 - QC- STIRO - PACK | B13: 16025 | C13: 244245.87 | D13: 259108.09 | E13: -14862.22 | F13: -0.057359151
A14: P05 - PROTOTIPIA PDT | B14: 1536.75 | C14: 27585.18 | D14: 27633.6 | E14: -48.42 | F14: -0.0017522147
A15: P06 - CARCERE PDT | B15: 10383.75 | C15: 146945.66 | D15: 147704.12 | E15: -758.456 | F15: -0.0051349686
A16: P07 - TAGLIO | B16: 2411.5 | C16: 41867.33 | D16: 42158.76 | E16: -291.43 | F16: -0.0069126796
A17: Group1 | B17: 17055 | C17: 386789.46 | D17: 415575.13 | E17: -28785.665 | F17: -0.069267056
A18: A06 - LOGIST/MAGAZ AUSIL | B18: 4009.75 | C18: 86749.3 | D18: 128763.51 | E18: -42014.21 | F18: -0.32628972
A19: A07 - OPERATION AUSIL | B19: 3793.25 | C19: 98547.67 | D19: 89122.012 | E19: 9425.658 | F19: 0.10576128
A20: A08 - UFF.PRODOTTO AUSIL | B20: 5146.25 | C20: 109098.26 | D20: 108355.35 | E20: 742.90867 | F20: 0.006856225
A21: A09 - TEMPI E METOD AUSIL | B21: 879.75 | C21: 26597.79 | D21: 26043.516 | E21: 554.274 | F21: 0.02128261
A22: A10 - COORD.CARCERE AUSIL | B22: 3226 | C22: 65796.44 | D22: 63290.736 | E22: 2505.704 | F22: 0.039590375
... A24: Totale complessivo | B24: 107411.2 | C24: 2045362.6 | D24: 2060489 | E24: -15126.415 | F24: -0.0073411774

Sheet DB_Varianza BdgAct
A1: Matricola | B1: Dipendente | C1: Centro di Costo | D1: Mese | E1: Ore Lav | F1: Actual | G1: Budget
A2: 50 | B2: FENG XIUHUA | C2: P01 - CONFEZIONAMENTO PDT | D2: 45688 | E2: 148.25 | F2: 2099.2 | G2: 2099.2
A3: 50 | B3: FENG XIUHUA | C3: P01 - CONFEZIONAMENTO PDT | D3: 45716 | E3: 147.25 | F3: 1952.95 | G3: 1952.95
A4: 50 | B4: FENG XIUHUA | C4: P01 - CONFEZIONAMENTO PDT | D4: 45747 | E4: 142 | F4: 1874.56 | G4: 1874.56
A5: 50 | B5: FENG XIUHUA | C5: P01 - CONFEZIONAMENTO PDT | D5: 45777 | E5: 155.5 | F5: 2173.3 | G5: 2173.3
A6: 50 | B6: FENG XIUHUA | C6: P01 - CONFEZIONAMENTO PDT | D6: 45808 | E6: 153 | F6: 2066.46 | G6: 2066.46
A7: 50 | B7: FENG XIUHUA | C7: P01 - CONFEZIONAMENTO PDT | D7: 45838 | E7: 151.5 | F7: 2081.83 | G7: 2066.46
A8: 240 | B8: VALBUSA VALERIA | C8: P01 - CONFEZIONAMENTO PDT | D8: 45688 | E8: 97 | F8: 2127.2 | G8: 0
A9: 240 | B9: VALBUSA VALERIA | C9: P01 - CONFEZIONAMENTO PDT | D9: 45716 | E9: 47.25 | F9: 2426.78 | G9: 0
A10: 240 | B10: VALBUSA VALERIA | C10: P01 - CONFEZIONAMENTO PDT | D10: 45747 | E10: 17.5 | F10: 1083.14 | G10: 0
A11: 240 | B11: VALBUSA VALERIA | C11: P01 - CONFEZIONAMENTO PDT | D11: 45777 | E11: 0 | F11: 614.85 | G11: 0
A12: 240 | B12: VALBUSA VALERIA | C12: P01 - CONFEZIONAMENTO PDT | D12: 45808 | E12: -161.75 | F12: -6251.97 | G12: 0
A13: 550 | B13: ZANARDO FABIANA | C13: P01 - CONFEZIONAMENTO PDT | D13: 45688 | E13: 98.5 | F13: 1870.53 | G13: 1870.53
... A1204: 3120 | B1204: PASQUALI GIULIA | C1204: A08 - UFF.PRODOTTO AUSIL | D1204: 46022 | E1204: 0 | F1204: 0 | G1204: 3048.012
B1205: EUSEBIO CAMILLA | C1205: A08 - UFF.PRODOTTO AUSIL | D1205: 45961 | E1205: 0 | F1205: 0 | G1205: 2000
B1206: EUSEBIO CAMILLA | C1206: A08 - UFF.PRODOTTO AUSIL | D1206: 45991 | E1206: 0 | F1206: 0 | G1206: 2000
B1207: EUSEBIO CAMILLA | C1207: A08 - UFF.PRODOTTO AUSIL | D1207: 46022 | E1207: 0 | F1207: 0 | G1207: 2000
A1208: 4800 | B1208: BORLOVAN ALINA | C1208: A09 - TEMPI E METOD AUSIL | D1208: 45869 | E1208: 0 | F1208: 0 | G1208: 4340.586
A1209: 4800 | B1209: BORLOVAN ALINA | C1209: A09 - TEMPI E METOD AUSIL | D1209: 45900 | E1209: 0 | F1209: 0 | G1209: 4340.586
A1210: 4800 | B1210: BORLOVAN ALINA | C1210: A09 - TEMPI E METOD AUSIL | D1210: 45930 | E1210: 0 | F1210: 0 | G1210: 4340.586
A1211: 4800 | B1211: BORLOVAN ALINA | C1211: A09 - TEMPI E METOD AUSIL | D1211: 45961 | E1211: 0 | F1211: 0 | G1211: 4340.586
A1212: 4800 | B1212: BORLOVAN ALINA | C1212: A09 - TEMPI E METOD AUSIL | D1212: 45991 | E1212: 0 | F1212: 0 | G1212: 4340.586
A1213: 4800 | B1213: BORLOVAN ALINA | C1213: A09 - TEMPI E METOD AUSIL | D1213: 46022 | E1213: 0 | F1213: 0 | G1213: 4340.586
A1214: 4290 | B1214: ARAUJO ARLETE | C1214: A10 - COORD.CARCERE AUSIL | D1214: 45869 | E1214: 0 | F1214: 0 | G1214: 2900.14
A1215: 4290 | B1215: ARAUJO ARLETE | C1215: A10 - COORD.CARCERE AUSIL | D1215: 45900 | E1215: 0 | F1215: 0 | G1215: 2900.14
A1216: 4290 | B1216: ARAUJO ARLETE | C1216: A10 - COORD.CARCERE AUSIL | D1216: 45930 | E1216: 0 | F1216: 0 | G1216: 2900.14
A1217: 4290 | B1217: ARAUJO ARLETE | C1217: A10 - COORD.CARCERE AUSIL | D1217: 45961 | E1217: 0 | F1217: 0 | G1217: 2900.14
A1218: 4290 | B1218: ARAUJO ARLETE | C1218: A10 - COORD.CARCERE AUSIL | D1218: 45991 | E1218: 0 | F1218: 0 | G1218: 2900.14
A1219: 4290 | B1219: ARAUJO ARLETE | C1219: A10 - COORD.CARCERE AUSIL | D1219: 46022 | E1219: 0 | F1219: 0 | G1219: 2900.14
... A2098: 5930 | B2098: ZAMBELLI FRANCESCA | C2098: P06 - CARCERE PDT | D2098: 45777 | E2098: 0 | F2098: 0 | G2098: 0
B2099: PAGANOTTO SARA | C2099: P06 - CARCERE PDT | D2099: 45838 | E2099: 0 | F2099: 0 | G2099: 1647.386
B2100: PAGANOTTO SARA | C2100: P06 - CARCERE PDT | D2100: 45869 | E2100: 0 | F2100: 0 | G2100: 1647.386
B2101: PAGANOTTO SARA | C2101: P06 - CARCERE PDT | D2101: 45900 | E2101: 0 | F2101: 0 | G2101: 1647.386
B2102: PAGANOTTO SARA | C2102: P06 - CARCERE PDT | D2102: 45930 | E2102: 0 | F2102: 0 | G2102: 1647.386
B2103: PAGANOTTO SARA | C2103: P06 - CARCERE PDT | D2103: 45961 | E2103: 0 | F2103: 0 | G2103: 1647.386
B2104: PAGANOTTO SARA | C2104: P06 - CARCERE PDT | D2104: 45991 | E2104: 0 | F2104: 0 | G2104: 1647.386
B2105: PAGANOTTO SARA | C2105: P06 - CARCERE PDT | D2105: 46022 | E2105: 0 | F2105: 0 | G2105: 1647.386
B2106: CHAFAI HICHAM | C2106: P06 - CARCERE PDT | D2106: 45838 | E2106: 0 | F2106: 0 | G2106: 500
B2107: CHAFAI HICHAM | C2107: P06 - CARCERE PDT | D2107: 45869 | E2107: 0 | F2107: 0 | G2107: 500
B2108: CHAFAI HICHAM | C2108: P06 - CARCERE PDT | D2108: 45900 | E2108: 0 | F2108: 0 | G2108: 500
...

Sheet DB Costi-Ore YtD
A1: Name | B1: Matricola | C1: Cognome | D1: Nome | E1: Centro di Costo | F1: Ore Lavorate PRG | G1: Totale A.C. PRG
A2: 45688 | B2: 50 | C2: FENG | D2: XIUHUA | E2: P01 - CONFEZIONAMENTO PDT | F2: 148.25 | G2: 2099.2
A3: 45688 | B3: 240 | C3: VALBUSA | D3: VALERIA | E3: P01 - CONFEZIONAMENTO PDT | F3: 97 | G3: 2127.2
A4: 45688 | B4: 550 | C4: ZANARDO | D4: FABIANA | E4: P01 - CONFEZIONAMENTO PDT | F4: 98.5 | G4: 1870.53
A5: 45688 | B5: 590 | C5: RIGHETTI | D5: FLAVIA | E5: P01 - CONFEZIONAMENTO PDT | F5: 148 | G5: 3084.94
A6: 45688 | B6: 600 | C6: MOLINARI | D6: LAURA | E6: P01 - CONFEZIONAMENTO PDT | F6: 151.5 | G6: 2801.2
A7: 45688 | B7: 620 | C7: ANSELMI | D7: IVA | E7: P01 - CONFEZIONAMENTO PDT | F7: 142.5 | G7: 2898.5
A8: 45688 | B8: 150 | C8: ENGUIX GRIMALTOS | D8: GEMA MARIA | E8: P07 - TAGLIO | F8: 136 | G8: 3017.48
A9: 45688 | B9: 260 | C9: AVESANI | D9: SILVIA | E9: P02 - QC- STIRO - PACK | F9: 151.5 | G9: 3451.51
A10: 45688 | B10: 420 | C10: LUCACI | D10: ANGELICA | E10: P02 - QC- STIRO - PACK | F10: 159 | G10: 3140.28
A11: 45688 | B11: 310 | C11: ALDEGHERI | D11: MARA | E11: P05 - PROTOTIPIA PDT | F11: 91.25 | G11: 2358.38
A12: 45688 | B12: 640 | C12: DEDAJ | D12: EGLANTINA | E12: P05 - PROTOTIPIA PDT | F12: 127.5 | G12: 2270.89
A13: 45688 | B13: 270 | C13: FISCALE | D13: ANNA | E13: S12 - COMM. MKTG. RETAIL | F13: 117.5 | G13: 7620.16
... A1148: 45838 | B1148: 100000 | C1148: FISCALE | D1148: ANNA | E1148: S10 - AMM DIREZ STRUTTURA | F1148: 0 | G1148: 8700

Sheet DB Costo Mese
A1: Matricola | B1: Dipendente | C1: Centro di Costo | D1: 31/01/2025 | E1: 28/02/2025 | F1: 31/03/2025 | G1: 30/04/2025 | H1: 31/05/2025 | I1: 30/06/2025 | J1: 31/07/2025 | K1: 31/08/2025 | L1: 30/09/2025 | M1: 31/10/2025 | N1: 30/11/2025 | O1: 31/12/2025
A2: 50 | B2: FENG XIUHUA | C2: P01 - CONFEZIONAMENTO PDT | D2: =IF((D$1*1)<=MAX('DB Costi-Ore YtD'!$A:$A),SUMIFS('DB Costi-Ore YtD'!$G:$G,'DB Costi-Ore YtD'!$A:$A,D$1,'DB Costi-Ore YtD'!$B:$B,$A2,'DB Costi-Ore YtD'!$E:$E,$C2),0) -> 2099.2 | E2: =IF((E$1*1)<=MAX('DB Costi-Ore YtD'!$A:$A),SUMIFS('DB Costi-Ore YtD'!$G:$G,'DB Costi-Ore YtD'!$A:$A,E$1,'DB Costi-Ore YtD'!$B:$B,$A2,'DB Costi-Ore YtD'!$E:$E,$C2)-SUM($D2:D2),0) -> 1952.95 | F2: =IF((F$1*1)<=MAX('DB Costi-Ore YtD'!$A:$A),SUMIFS('DB Costi-Ore YtD'!$G:$G,'DB Costi-Ore YtD'!$A:$A,F$1,'DB Costi-Ore YtD'!$B:$B,$A2,'DB Costi-Ore YtD'!$E:$E,$C2)-SUM($D2:E2),0) -> 1874.56 | G2: =IF((G$1*1)<=MAX('DB Costi-Ore YtD'!$A:$A),SUMIFS('DB Costi-Ore YtD'!$G:$G,'DB Costi-Ore YtD'!$A:$A,G$1,'DB Costi-Ore YtD'!$B:$B,$A2,'DB Costi-Ore YtD'!$E:$E,$C2)-SUM($D2:F2),0) -> 2173.3 | H2: =IF((H$1*1)<=MAX('DB Costi-Ore YtD'!$A:$A),SUMIFS('DB Costi-Ore YtD'!$G:$G,'DB Costi-Ore YtD'!$A:$A,H$1,'DB Costi-Ore YtD'!$B:$B,$A2,'DB Costi-Ore YtD'!$E:$E,$C2)-SUM($D2:G2),0) -> 2066.46 | I2: =IF((I$1*1)<=MAX('DB Costi-Ore YtD'!$A:$A),SUMIFS('DB Costi-Ore YtD'!$G:$G,'DB Costi-Ore YtD'!$A:$A,I$1,'DB Costi-Ore YtD'!$B:$B,$A2,'DB Costi-Ore YtD'!$E:$E,$C2)-SUM($D2:H2),0) -> 2081.83 | J2: =IF((J$1*1)<=MAX('DB Costi-Ore YtD'!$A:$A),SUMIFS('DB Costi-Ore YtD'!$G:$G,'DB Costi-Ore YtD'!$A:$A,J$1,'DB Costi-Ore YtD'!$B:$B,$A2,'DB Costi-Ore YtD'!$E:$E,$C2)-SUM($D2:I2),0) -> 0 | K2: =IF((K$1*1)<=MAX('DB Costi-Ore YtD'!$A:$A),SUMIFS('DB Costi-Ore YtD'!$G:$G,'DB Costi-Ore YtD'!$A:$A,K$1,'DB Costi-Ore YtD'!$B:$B,$A2,'DB Costi-Ore YtD'!$E:$E,$C2)-SUM($D2:J2),0) -> 0 | L2: =IF((L$1*1)<=MAX('DB Costi-Ore YtD'!$A:$A),SUMIFS('DB Costi-Ore YtD'!$G:$G,'DB Costi-Ore YtD'!$A:$A,L$1,'DB Costi-Ore YtD'!$B:$B,$A2,'DB Costi-Ore YtD'!$E:$E,$C2)-SUM($D2:K2),0) -> 0 | ... O2: =IF((O$1*1)<=MAX('DB Costi-Ore YtD'!$A:$A),SUMIFS('DB Costi-Ore YtD'!$G:$G,'DB Costi-Ore YtD'!$A:$A,O$1,'DB Costi-Ore YtD'!$B:$B,$A2,'DB Costi-Ore YtD'!$E:$E,$C2)-SUM($D2:N2),0) -> 0
A3: 240 | B3: VALBUSA VALERIA | C3: P01 - CONFEZIONAMENTO PDT | D3: =IF((D$1*1)<=MAX('DB Costi-Ore YtD'!$A:$A),SUMIFS('DB Costi-Ore YtD'!$G:$G,'DB Costi-Ore YtD'!$A:$A,D$1,'DB Costi-Ore YtD'!$B:$B,$A3,'DB Costi-Ore YtD'!$E:$E,$C3),0) -> 2127.2 | E3: =IF((E$1*1)<=MAX('DB Costi-Ore YtD'!$A:$A),SUMIFS('DB Costi-Ore YtD'!$G:$G,'DB Costi-Ore YtD'!$A:$A,E$1,'DB Costi-Ore YtD'!$B:$B,$A3,'DB Costi-Ore YtD'!$E:$E,$C3)-SUM($D3:D3),0) -> 2426.78 | F3: =IF((F$1*1)<=MAX('DB Costi-Ore YtD'!$A:$A),SUMIFS('DB Costi-Ore YtD'!$G:$G,'DB Costi-Ore YtD'!$A:$A,F$1,'DB Costi-Ore YtD'!$B:$B,$A3,'DB Costi-Ore YtD'!$E:$E,$C3)-SUM($D3:E3),0) -> 1083.14 | G3: =IF((G$1*1)<=MAX('DB Costi-Ore YtD'!$A:$A),SUMIFS('DB Costi-Ore YtD'!$G:$G,'DB Costi-Ore YtD'!$A:$A,G$1,'DB Costi-Ore YtD'!$B:$B,$A3,'DB Costi-Ore YtD'!$E:$E,$C3)-SUM($D3:F3),0) -> 614.85 | H3: =IF((H$1*1)<=MAX('DB Costi-Ore YtD'!$A:$A),SUMIFS('DB Costi-Ore YtD'!$G:$G,'DB Costi-Ore YtD'!$A:$A,H$1,'DB Costi-Ore YtD'!$B:$B,$A3,'DB Costi-Ore YtD'!$E:$E,$C3)-SUM($D3:G3),0) -> -6251.97 | I3: =IF((I$1*1)<=MAX('DB Costi-Ore YtD'!$A:$A),SUMIFS('DB Costi-Ore YtD'!$G:$G,'DB Costi-Ore YtD'!$A:$A,I$1,'DB Costi-Ore YtD'!$B:$B,$A3,'DB Costi-Ore YtD'!$E:$E,$C3)-SUM($D3:H3),0) -> 0 | J3: =IF((J$1*1)<=MAX('DB Costi-Ore YtD'!$A:$A),SUMIFS('DB Costi-Ore YtD'!$G:$G,'DB Costi-Ore YtD'!$A:$A,J$1,'DB Costi-Ore YtD'!$B:$B,$A3,'DB Costi-Ore YtD'!$E:$E,$C3)-SUM($D3:I3),0) -> 0 | K3: =IF((K$1*1)<=MAX('DB Costi-Ore YtD'!$A:$A),SUMIFS('DB Costi-Ore YtD'!$G:$G,'DB Costi-Ore YtD'!$A:$A,K$1,'DB Costi-Ore YtD'!$B:$B,$A3,'DB Costi-Ore YtD'!$E:$E,$C3)-SUM($D3:J3),0) -> 0 | L3: =IF((L$1*1)<=MAX('DB Costi-Ore YtD'!$A:$A),SUMIFS('DB Costi-Ore YtD'!$G:$G,'DB Costi-Ore YtD'!$A:$A,L$1,'DB Costi-Ore YtD'!$B:$B,$A3,'DB Costi-Ore YtD'!$E:$E,$C3)-SUM($D3:K3),0) -> 0 | ... O3: =IF((O$1*1)<=MAX('DB Costi-Ore YtD'!$A:$A),SUMIFS('DB Costi-Ore YtD'!$G:$G,'DB Costi-Ore YtD'!$A:$A,O$1,'DB Costi-Ore YtD'!$B:$B,$A3,'DB Costi-Ore YtD'!$E:$E,$C3)-SUM($D3:N3),0) -> 0
A4: 550 | B4: ZANARDO FABIANA | C4: P01 - CONFEZIONAMENTO PDT | D4: =IF((D$1*1)<=MAX('DB Costi-Ore YtD'!$A:$A),SUMIFS('DB Costi-Ore YtD'!$G:$G,'DB Costi-Ore YtD'!$A:$A,D$1,'DB Costi-Ore YtD'!$B:$B,$A4,'DB Costi-Ore YtD'!$E:$E,$C4),0) -> 1870.53 | E4: =IF((E$1*1)<=MAX('DB Costi-Ore YtD'!$A:$A),SUMIFS('DB Costi-Ore YtD'!$G:$G,'DB Costi-Ore YtD'!$A:$A,E$1,'DB Costi-Ore YtD'!$B:$B,$A4,'DB Costi-Ore YtD'!$E:$E,$C4)-SUM($D4:D4),0) -> 1595.08 | F4: =IF((F$1*1)<=MAX('DB Costi-Ore YtD'!$A:$A),SUMIFS('DB Costi-Ore YtD'!$G:$G,'DB Costi-Ore YtD'!$A:$A,F$1,'DB Costi-Ore YtD'!$B:$B,$A4,'DB Costi-Ore YtD'!$E:$E,$C4)-SUM($D4:E4),0) -> 1992.53 | G4: =IF((G$1*1)<=MAX('DB Costi-Ore YtD'!$A:$A),SUMIFS('DB Costi-Ore YtD'!$G:$G,'DB Costi-Ore YtD'!$A:$A,G$1,'DB Costi-Ore YtD'!$B:$B,$A4,'DB Costi-Ore YtD'!$E:$E,$C4)-SUM($D4:F4),0) -> 1407.63 | H4: =IF((H$1*1)<=MAX('DB Costi-Ore YtD'!$A:$A),SUMIFS('DB Costi-Ore YtD'!$G:$G,'DB Costi-Ore YtD'!$A:$A,H$1,'DB Costi-Ore YtD'!$B:$B,$A4,'DB Costi-Ore YtD'!$E:$E,$C4)-SUM($D4:G4),0) -> 1031.29 | I4: =IF((I$1*1)<=MAX('DB Costi-Ore YtD'!$A:$A),SUMIFS('DB Costi-Ore YtD'!$G:$G,'DB Costi-Ore YtD'!$A:$A,I$1,'DB Costi-Ore YtD'!$B:$B,$A4,'DB Costi-Ore YtD'!$E:$E,$C4)-SUM($D4:H4),0) -> 927.38 | J4: =IF((J$1*1)<=MAX('DB Costi-Ore YtD'!$A:$A),SUMIFS('DB Costi-Ore YtD'!$G:$G,'DB Costi-Ore YtD'!$A:$A,J$1,'DB Costi-Ore YtD'!$B:$B,$A4,'DB Costi-Ore YtD'!$E:$E,$C4)-SUM($D4:I4),0) -> 0 | K4: =IF((K$1*1)<=MAX('DB Costi-Ore YtD'!$A:$A),SUMIFS('DB Costi-Ore YtD'!$G:$G,'DB Costi-Ore YtD'!$A:$A,K$1,'DB Costi-Ore YtD'!$B:$B,$A4,'DB Costi-Ore YtD'!$E:$E,$C4)-SUM($D4:J4),0) -> 0 | L4: =IF((L$1*1)<=MAX('DB Costi-Ore YtD'!$A:$A),SUMIFS('DB Costi-Ore YtD'!$G:$G,'DB Costi-Ore YtD'!$A:$A,L$1,'DB Costi-Ore YtD'!$B:$B,$A4,'DB Costi-Ore YtD'!$E:$E,$C4)-SUM($D4:K4),0) -> 0 | ... O4: =IF((O$1*1)<=MAX('DB Costi-Ore YtD'!$A:$A),SUMIFS('DB Costi-Ore YtD'!$G:$G,'DB Costi-Ore YtD'!$A:$A,O$1,'DB Costi-Ore YtD'!$B:$B,$A4,'DB Costi-Ore YtD'!$E:$E,$C4)-SUM($D4:N4),0) -> 0
A5: 590 | B5: RIGHETTI FLAVIA | C5: P01 - CONFEZIONAMENTO PDT | D5: =IF((D$1*1)<=MAX('DB Costi-Ore YtD'!$A:$A),SUMIFS('DB Costi-Ore YtD'!$G:$G,'DB Costi-Ore YtD'!$A:$A,D$1,'DB Costi-Ore YtD'!$B:$B,$A5,'DB Costi-Ore YtD'!$E:$E,$C5),0) -> 3084.94 | E5: =IF((E$1*1)<=MAX('DB Costi-Ore YtD'!$A:$A),SUMIFS('DB Costi-Ore YtD'!$G:$G,'DB Costi-Ore YtD'!$A:$A,E$1,'DB Costi-Ore YtD'!$B:$B,$A5,'DB Costi-Ore YtD'!$E:$E,$C5)-SUM($D5:D5),0) -> 2584.28 | F5: =IF((F$1*1)<=MAX('DB Costi-Ore YtD'!$A:$A),SUMIFS('DB Costi-Ore YtD'!$G:$G,'DB Costi-Ore YtD'!$A:$A,F$1,'DB Costi-Ore YtD'!$B:$B,$A5,'DB Costi-Ore YtD'!$E:$E,$C5)-SUM($D5:E5),0) -> 2950.69 | G5: =IF((G$1*1)<=MAX('DB Costi-Ore YtD'!$A:$A),SUMIFS('DB Costi-Ore YtD'!$G:$G,'DB Costi-Ore YtD'!$A:$A,G$1,'DB Costi-Ore YtD'!$B:$B,$A5,'DB Costi-Ore YtD'!$E:$E,$C5)-SUM($D5:F5),0) -> 3089.81 | H5: =IF((H$1*1)<=MAX('DB Costi-Ore YtD'!$A:$A),SUMIFS('DB Costi-Ore YtD'!$G:$G,'DB Costi-Ore YtD'!$A:$A,H$1,'DB Costi-Ore YtD'!$B:$B,$A5,'DB Costi-Ore YtD'!$E:$E,$C5)-SUM($D5:G5),0) -> 2933.17 | I5: =IF((I$1*1)<=MAX('DB Costi-Ore YtD'!$A:$A),SUMIFS('DB Costi-Ore YtD'!$G:$G,'DB Costi-Ore YtD'!$A:$A,I$1,'DB Costi-Ore YtD'!$B:$B,$A5,'DB Costi-Ore YtD'!$E:$E,$C5)-SUM($D5:H5),0) -> 2254.67 | J5: =IF((J$1*1)<=MAX('DB Costi-Ore YtD'!$A:$A),SUMIFS('DB Costi-Ore YtD'!$G:$G,'DB Costi-Ore YtD'!$A:$A,J$1,'DB Costi-Ore YtD'!$B:$B,$A5,'DB Costi-Ore YtD'!$E:$E,$C5)-SUM($D5:I5),0) -> 0 | K5: =IF((K$1*1)<=MAX('DB Costi-Ore YtD'!$A:$A),SUMIFS('DB Costi-Ore YtD'!$G:$G,'DB Costi-Ore YtD'!$A:$A,K$1,'DB Costi-Ore YtD'!$B:$B,$A5,'DB Costi-Ore YtD'!$E:$E,$C5)-SUM($D5:J5),0) -> 0 | L5: =IF((L$1*1)<=MAX('DB Costi-Ore YtD'!$A:$A),SUMIFS('DB Costi-Ore YtD'!$G:$G,'DB Costi-Ore YtD'!$A:$A,L$1,'DB Costi-Ore YtD'!$B:$B,$A5,'DB Costi-Ore YtD'!$E:$E,$C5)-SUM($D5:K5),0) -> 0 | ... O5: =IF((O$1*1)<=MAX('DB Costi-Ore YtD'!$A:$A),SUMIFS('DB Costi-Ore YtD'!$G:$G,'DB Costi-Ore YtD'!$A:$A,O$1,'DB Costi-Ore YtD'!$B:$B,$A5,'DB Costi-Ore YtD'!$E:$E,$C5)-SUM($D5:N5),0) -> 0
A6: 600 | B6: MOLINARI LAURA | C6: P01 - CONFEZIONAMENTO PDT | D6: =IF((D$1*1)<=MAX('DB Costi-Ore YtD'!$A:$A),SUMIFS('DB Costi-Ore YtD'!$G:$G,'DB Costi-Ore YtD'!$A:$A,D$1,'DB Costi-Ore YtD'!$B:$B,$A6,'DB Costi-Ore YtD'!$E:$E,$C6),0) -> 2801.2 | E6: =IF((E$1*1)<=MAX('DB Costi-Ore YtD'!$A:$A),SUMIFS('DB Costi-Ore YtD'!$G:$G,'DB Costi-Ore YtD'!$A:$A,E$1,'DB Costi-Ore YtD'!$B:$B,$A6,'DB Costi-Ore YtD'!$E:$E,$C6)-SUM($D6:D6),0) -> 2473.68 | F6: =IF((F$1*1)<=MAX('DB Costi-Ore YtD'!$A:$A),SUMIFS('DB Costi-Ore YtD'!$G:$G,'DB Costi-Ore YtD'!$A:$A,F$1,'DB Costi-Ore YtD'!$B:$B,$A6,'DB Costi-Ore YtD'!$E:$E,$C6)-SUM($D6:E6),0) -> 2692.87 | G6: =IF((G$1*1)<=MAX('DB Costi-Ore YtD'!$A:$A),SUMIFS('DB Costi-Ore YtD'!$G:$G,'DB Costi-Ore YtD'!$A:$A,G$1,'DB Costi-Ore YtD'!$B:$B,$A6,'DB Costi-Ore YtD'!$E:$E,$C6)-SUM($D6:F6),0) -> 2785.88 | H6: =IF((H$1*1)<=MAX('DB Costi-Ore YtD'!$A:$A),SUMIFS('DB Costi-Ore YtD'!$G:$G,'DB Costi-Ore YtD'!$A:$A,H$1,'DB Costi-Ore YtD'!$B:$B,$A6,'DB Costi-Ore YtD'!$E:$E,$C6)-SUM($D6:G6),0) -> 2315.83 | I6: =IF((I$1*1)<=MAX('DB Costi-Ore YtD'!$A:$A),SUMIFS('DB Costi-Ore YtD'!$G:$G,'DB Costi-Ore YtD'!$A:$A,I$1,'DB Costi-Ore YtD'!$B:$B,$A6,'DB Costi-Ore YtD'!$E:$E,$C6)-SUM($D6:H6),0) -> 1727.13 | J6: =IF((J$1*1)<=MAX('DB Costi-Ore YtD'!$A:$A),SUMIFS('DB Costi-Ore YtD'!$G:$G,'DB Costi-Ore YtD'!$A:$A,J$1,'DB Costi-Ore YtD'!$B:$B,$A6,'DB Costi-Ore YtD'!$E:$E,$C6)-SUM($D6:I6),0) -> 0 | K6: =IF((K$1*1)<=MAX('DB Costi-Ore YtD'!$A:$A),SUMIFS('DB Costi-Ore YtD'!$G:$G,'DB Costi-Ore YtD'!$A:$A,K$1,'DB Costi-Ore YtD'!$B:$B,$A6,'DB Costi-Ore YtD'!$E:$E,$C6)-SUM($D6:J6),0) -> 0 | L6: =IF((L$1*1)<=MAX('DB Costi-Ore YtD'!$A:$A),SUMIFS('DB Costi-Ore YtD'!$G:$G,'DB Costi-Ore YtD'!$A:$A,L$1,'DB Costi-Ore YtD'!$B:$B,$A6,'DB Costi-Ore YtD'!$E:$E,$C6)-SUM($D6:K6),0) -> 0 | ... O6: =IF((O$1*1)<=MAX('DB Costi-Ore YtD'!$A:$A),SUMIFS('DB Costi-Ore YtD'!$G:$G,'DB Costi-Ore YtD'!$A:$A,O$1,'DB Costi-Ore YtD'!$B:$B,$A6,'DB Costi-Ore YtD'!$E:$E,$C6)-SUM($D6:N6),0) -> 0
A7: 620 | B7: ANSELMI IVA | C7: P01 - CONFEZIONAMENTO PDT | D7: =IF((D$1*1)<=MAX('DB Costi-Ore YtD'!$A:$A),SUMIFS('DB Costi-Ore YtD'!$G:$G,'DB Costi-Ore YtD'!$A:$A,D$1,'DB Costi-Ore YtD'!$B:$B,$A7,'DB Costi-Ore YtD'!$E:$E,$C7),0) -> 2898.5 | E7: =IF((E$1*1)<=MAX('DB Costi-Ore YtD'!$A:$A),SUMIFS('DB Costi-Ore YtD'!$G:$G,'DB Costi-Ore YtD'!$A:$A,E$1,'DB Costi-Ore YtD'!$B:$B,$A7,'DB Costi-Ore YtD'!$E:$E,$C7)-SUM($D7:D7),0) -> 2631.93 | F7: =IF((F$1*1)<=MAX('DB Costi-Ore YtD'!$A:$A),SUMIFS('DB Costi-Ore YtD'!$G:$G,'DB Costi-Ore YtD'!$A:$A,F$1,'DB Costi-Ore YtD'!$B:$B,$A7,'DB Costi-Ore YtD'!$E:$E,$C7)-SUM($D7:E7),0) -> 2156.46 | G7: =IF((G$1*1)<=MAX('DB Costi-Ore YtD'!$A:$A),SUMIFS('DB Costi-Ore YtD'!$G:$G,'DB Costi-Ore YtD'!$A:$A,G$1,'DB Costi-Ore YtD'!$B:$B,$A7,'DB Costi-Ore YtD'!$E:$E,$C7)-SUM($D7:F7),0) -> 2803.7 | H7: =IF((H$1*1)<=MAX('DB Costi-Ore YtD'!$A:$A),SUMIFS('DB Costi-Ore YtD'!$G:$G,'DB Costi-Ore YtD'!$A:$A,H$1,'DB Costi-Ore YtD'!$B:$B,$A7,'DB Costi-Ore YtD'!$E:$E,$C7)-SUM($D7:G7),0) -> 2616.67 | I7: =IF((I$1*1)<=MAX('DB Costi-Ore YtD'!$A:$A),SUMIFS('DB Costi-Ore YtD'!$G:$G,'DB Costi-Ore YtD'!$A:$A,I$1,'DB Costi-Ore YtD'!$B:$B,$A7,'DB Costi-Ore YtD'!$E:$E,$C7)-SUM($D7:H7),0) -> 2806.11 | J7: =IF((J$1*1)<=MAX('DB Costi-Ore YtD'!$A:$A),SUMIFS('DB Costi-Ore YtD'!$G:$G,'DB Costi-Ore YtD'!$A:$A,J$1,'DB Costi-Ore YtD'!$B:$B,$A7,'DB Costi-Ore YtD'!$E:$E,$C7)-SUM($D7:I7),0) -> 0 | K7: =IF((K$1*1)<=MAX('DB Costi-Ore YtD'!$A:$A),SUMIFS('DB Costi-Ore YtD'!$G:$G,'DB Costi-Ore YtD'!$A:$A,K$1,'DB Costi-Ore YtD'!$B:$B,$A7,'DB Costi-Ore YtD'!$E:$E,$C7)-SUM($D7:J7),0) -> 0 | L7: =IF((L$1*1)<=MAX('DB Costi-Ore YtD'!$A:$A),SUMIFS('DB Costi-Ore YtD'!$G:$G,'DB Costi-Ore YtD'!$A:$A,L$1,'DB Costi-Ore YtD'!$B:$B,$A7,'DB Costi-Ore YtD'!$E:$E,$C7)-SUM($D7:K7),0) -> 0 | ... O7: =IF((O$1*1)<=MAX('DB Costi-Ore YtD'!$A:$A),SUMIFS('DB Costi-Ore YtD'!$G:$G,'DB Costi-Ore YtD'!$A:$A,O$1,'DB Costi-Ore YtD'!$B:$B,$A7,'DB Costi-Ore YtD'!$E:$E,$C7)-SUM($D7:N7),0) -> 0
A8: 150 | B8: ENGUIX GRIMALTOS GEMA MARIA | C8: P07 - TAGLIO | D8: =IF((D$1*1)<=MAX('DB Costi-Ore YtD'!$A:$A),SUMIFS('DB Costi-Ore YtD'!$G:$G,'DB Costi-Ore YtD'!$A:$A,D$1,'DB Costi-Ore YtD'!$B:$B,$A8,'DB Costi-Ore YtD'!$E:$E,$C8),0) -> 3017.48 | E8: =IF((E$1*1)<=MAX('DB Costi-Ore YtD'!$A:$A),SUMIFS('DB Costi-Ore YtD'!$G:$G,'DB Costi-Ore YtD'!$A:$A,E$1,'DB Costi-Ore YtD'!$B:$B,$A8,'DB Costi-Ore YtD'!$E:$E,$C8)-SUM($D8:D8),0) -> 3090.31 | F8: =IF((F$1*1)<=MAX('DB Costi-Ore YtD'!$A:$A),SUMIFS('DB Costi-Ore YtD'!$G:$G,'DB Costi-Ore YtD'!$A:$A,F$1,'DB Costi-Ore YtD'!$B:$B,$A8,'DB Costi-Ore YtD'!$E:$E,$C8)-SUM($D8:E8),0) -> 3312.89 | G8: =IF((G$1*1)<=MAX('DB Costi-Ore YtD'!$A:$A),SUMIFS('DB Costi-Ore YtD'!$G:$G,'DB Costi-Ore YtD'!$A:$A,G$1,'DB Costi-Ore YtD'!$B:$B,$A8,'DB Costi-Ore YtD'!$E:$E,$C8)-SUM($D8:F8),0) -> 3398.74 | H8: =IF((H$1*1)<=MAX('DB Costi-Ore YtD'!$A:$A),SUMIFS('DB Costi-Ore YtD'!$G:$G,'DB Costi-Ore YtD'!$A:$A,H$1,'DB Costi-Ore YtD'!$B:$B,$A8,'DB Costi-Ore YtD'!$E:$E,$C8)-SUM($D8:G8),0) -> 3160.76 | I8: =IF((I$1*1)<=MAX('DB Costi-Ore YtD'!$A:$A),SUMIFS('DB Costi-Ore YtD'!$G:$G,'DB Costi-Ore YtD'!$A:$A,I$1,'DB Costi-Ore YtD'!$B:$B,$A8,'DB Costi-Ore YtD'!$E:$E,$C8)-SUM($D8:H8),0) -> 3048.89 | J8: =IF((J$1*1)<=MAX('DB Costi-Ore YtD'!$A:$A),SUMIFS('DB Costi-Ore YtD'!$G:$G,'DB Costi-Ore YtD'!$A:$A,J$1,'DB Costi-Ore YtD'!$B:$B,$A8,'DB Costi-Ore YtD'!$E:$E,$C8)-SUM($D8:I8),0) -> 0 | K8: =IF((K$1*1)<=MAX('DB Costi-Ore YtD'!$A:$A),SUMIFS('DB Costi-Ore YtD'!$G:$G,'DB Costi-Ore YtD'!$A:$A,K$1,'DB Costi-Ore YtD'!$B:$B,$A8,'DB Costi-Ore YtD'!$E:$E,$C8)-SUM($D8:J8),0) -> 0 | L8: =IF((L$1*1)<=MAX('DB Costi-Ore YtD'!$A:$A),SUMIFS('DB Costi-Ore YtD'!$G:$G,'DB Costi-Ore YtD'!$A:$A,L$1,'DB Costi-Ore YtD'!$B:$B,$A8,'DB Costi-Ore YtD'!$E:$E,$C8)-SUM($D8:K8),0) -> 0 | ... O8: =IF((O$1*1)<=MAX('DB Costi-Ore YtD'!$A:$A),SUMIFS('DB Costi-Ore YtD'!$G:$G,'DB Costi-Ore YtD'!$A:$A,O$1,'DB Costi-Ore YtD'!$B:$B,$A8,'DB Costi-Ore YtD'!$E:$E,$C8)-SUM($D8:N8),0) -> 0
A9: 260 | B9: AVESANI SILVIA | C9: P02 - QC- STIRO - PACK | D9: =IF((D$1*1)<=MAX('DB Costi-Ore YtD'!$A:$A),SUMIFS('DB Costi-Ore YtD'!$G:$G,'DB Costi-Ore YtD'!$A:$A,D$1,'DB Costi-Ore YtD'!$B:$B,$A9,'DB Costi-Ore YtD'!$E:$E,$C9),0) -> 3451.51 | E9: =IF((E$1*1)<=MAX('DB Costi-Ore YtD'!$A:$A),SUMIFS('DB Costi-Ore YtD'!$G:$G,'DB Costi-Ore YtD'!$A:$A,E$1,'DB Costi-Ore YtD'!$B:$B,$A9,'DB Costi-Ore YtD'!$E:$E,$C9)-SUM($D9:D9),0) -> 2736.08 | F9: =IF((F$1*1)<=MAX('DB Costi-Ore YtD'!$A:$A),SUMIFS('DB Costi-Ore YtD'!$G:$G,'DB Costi-Ore YtD'!$A:$A,F$1,'DB Costi-Ore YtD'!$B:$B,$A9,'DB Costi-Ore YtD'!$E:$E,$C9)-SUM($D9:E9),0) -> 3106.81 | G9: =IF((G$1*1)<=MAX('DB Costi-Ore YtD'!$A:$A),SUMIFS('DB Costi-Ore YtD'!$G:$G,'DB Costi-Ore YtD'!$A:$A,G$1,'DB Costi-Ore YtD'!$B:$B,$A9,'DB Costi-Ore YtD'!$E:$E,$C9)-SUM($D9:F9),0) -> 3623.92 | H9: =IF((H$1*1)<=MAX('DB Costi-Ore YtD'!$A:$A),SUMIFS('DB Costi-Ore YtD'!$G:$G,'DB Costi-Ore YtD'!$A:$A,H$1,'DB Costi-Ore YtD'!$B:$B,$A9,'DB Costi-Ore YtD'!$E:$E,$C9)-SUM($D9:G9),0) -> 3024.26 | I9: =IF((I$1*1)<=MAX('DB Costi-Ore YtD'!$A:$A),SUMIFS('DB Costi-Ore YtD'!$G:$G,'DB Costi-Ore YtD'!$A:$A,I$1,'DB Costi-Ore YtD'!$B:$B,$A9,'DB Costi-Ore YtD'!$E:$E,$C9)-SUM($D9:H9),0) -> 3416.13 | J9: =IF((J$1*1)<=MAX('DB Costi-Ore YtD'!$A:$A),SUMIFS('DB Costi-Ore YtD'!$G:$G,'DB Costi-Ore YtD'!$A:$A,J$1,'DB Costi-Ore YtD'!$B:$B,$A9,'DB Costi-Ore YtD'!$E:$E,$C9)-SUM($D9:I9),0) -> 0 | K9: =IF((K$1*1)<=MAX('DB Costi-Ore YtD'!$A:$A),SUMIFS('DB Costi-Ore YtD'!$G:$G,'DB Costi-Ore YtD'!$A:$A,K$1,'DB Costi-Ore YtD'!$B:$B,$A9,'DB Costi-Ore YtD'!$E:$E,$C9)-SUM($D9:J9),0) -> 0 | L9: =IF((L$1*1)<=MAX('DB Costi-Ore YtD'!$A:$A),SUMIFS('DB Costi-Ore YtD'!$G:$G,'DB Costi-Ore YtD'!$A:$A,L$1,'DB Costi-Ore YtD'!$B:$B,$A9,'DB Costi-Ore YtD'!$E:$E,$C9)-SUM($D9:K9),0) -> 0 | ... O9: =IF((O$1*1)<=MAX('DB Costi-Ore YtD'!$A:$A),SUMIFS('DB Costi-Ore YtD'!$G:$G,'DB Costi-Ore YtD'!$A:$A,O$1,'DB Costi-Ore YtD'!$B:$B,$A9,'DB Costi-Ore YtD'!$E:$E,$C9)-SUM($D9:N9),0) -> 0
A10: 420 | B10: LUCACI ANGELICA | C10: P02 - QC- STIRO - PACK | D10: =IF((D$1*1)<=MAX('DB Costi-Ore YtD'!$A:$A),SUMIFS('DB Costi-Ore YtD'!$G:$G,'DB Costi-Ore YtD'!$A:$A,D$1,'DB Costi-Ore YtD'!$B:$B,$A10,'DB Costi-Ore YtD'!$E:$E,$C10),0) -> 3140.28 | E10: =IF((E$1*1)<=MAX('DB Costi-Ore YtD'!$A:$A),SUMIFS('DB Costi-Ore YtD'!$G:$G,'DB Costi-Ore YtD'!$A:$A,E$1,'DB Costi-Ore YtD'!$B:$B,$A10,'DB Costi-Ore YtD'!$E:$E,$C10)-SUM($D10:D10),0) -> 2780 | F10: =IF((F$1*1)<=MAX('DB Costi-Ore YtD'!$A:$A),SUMIFS('DB Costi-Ore YtD'!$G:$G,'DB Costi-Ore YtD'!$A:$A,F$1,'DB Costi-Ore YtD'!$B:$B,$A10,'DB Costi-Ore YtD'!$E:$E,$C10)-SUM($D10:E10),0) -> 2743.85 | G10: =IF((G$1*1)<=MAX('DB Costi-Ore YtD'!$A:$A),SUMIFS('DB Costi-Ore YtD'!$G:$G,'DB Costi-Ore YtD'!$A:$A,G$1,'DB Costi-Ore YtD'!$B:$B,$A10,'DB Costi-Ore YtD'!$E:$E,$C10)-SUM($D10:F10),0) -> 2927.28 | H10: =IF((H$1*1)<=MAX('DB Costi-Ore YtD'!$A:$A),SUMIFS('DB Costi-Ore YtD'!$G:$G,'DB Costi-Ore YtD'!$A:$A,H$1,'DB Costi-Ore YtD'!$B:$B,$A10,'DB Costi-Ore YtD'!$E:$E,$C10)-SUM($D10:G10),0) -> 2798.51 | I10: =IF((I$1*1)<=MAX('DB Costi-Ore YtD'!$A:$A),SUMIFS('DB Costi-Ore YtD'!$G:$G,'DB Costi-Ore YtD'!$A:$A,I$1,'DB Costi-Ore YtD'!$B:$B,$A10,'DB Costi-Ore YtD'!$E:$E,$C10)-SUM($D10:H10),0) -> 1593.43 | J10: =IF((J$1*1)<=MAX('DB Costi-Ore YtD'!$A:$A),SUMIFS('DB Costi-Ore YtD'!$G:$G,'DB Costi-Ore YtD'!$A:$A,J$1,'DB Costi-Ore YtD'!$B:$B,$A10,'DB Costi-Ore YtD'!$E:$E,$C10)-SUM($D10:I10),0) -> 0 | K10: =IF((K$1*1)<=MAX('DB Costi-Ore YtD'!$A:$A),SUMIFS('DB Costi-Ore YtD'!$G:$G,'DB Costi-Ore YtD'!$A:$A,K$1,'DB Costi-Ore YtD'!$B:$B,$A10,'DB Costi-Ore YtD'!$E:$E,$C10)-SUM($D10:J10),0) -> 0 | L10: =IF((L$1*1)<=MAX('DB Costi-Ore YtD'!$A:$A),SUMIFS('DB Costi-Ore YtD'!$G:$G,'DB Costi-Ore YtD'!$A:$A,L$1,'DB Costi-Ore YtD'!$B:$B,$A10,'DB Costi-Ore YtD'!$E:$E,$C10)-SUM($D10:K10),0) -> 0 | ... O10: =IF((O$1*1)<=MAX('DB Costi-Ore YtD'!$A:$A),SUMIFS('DB Costi-Ore YtD'!$G:$G,'DB Costi-Ore YtD'!$A:$A,O$1,'DB Costi-Ore YtD'!$B:$B,$A10,'DB Costi-Ore YtD'!$E:$E,$C10)-SUM($D10:N10),0) -> 0
A11: 310 | B11: ALDEGHERI MARA | C11: P05 - PROTOTIPIA PDT | D11: =IF((D$1*1)<=MAX('DB Costi-Ore YtD'!$A:$A),SUMIFS('DB Costi-Ore YtD'!$G:$G,'DB Costi-Ore YtD'!$A:$A,D$1,'DB Costi-Ore YtD'!$B:$B,$A11,'DB Costi-Ore YtD'!$E:$E,$C11),0) -> 2358.38 | E11: =IF((E$1*1)<=MAX('DB Costi-Ore YtD'!$A:$A),SUMIFS('DB Costi-Ore YtD'!$G:$G,'DB Costi-Ore YtD'!$A:$A,E$1,'DB Costi-Ore YtD'!$B:$B,$A11,'DB Costi-Ore YtD'!$E:$E,$C11)-SUM($D11:D11),0) -> 2462.43 | F11: =IF((F$1*1)<=MAX('DB Costi-Ore YtD'!$A:$A),SUMIFS('DB Costi-Ore YtD'!$G:$G,'DB Costi-Ore YtD'!$A:$A,F$1,'DB Costi-Ore YtD'!$B:$B,$A11,'DB Costi-Ore YtD'!$E:$E,$C11)-SUM($D11:E11),0) -> 2440.84 | G11: =IF((G$1*1)<=MAX('DB Costi-Ore YtD'!$A:$A),SUMIFS('DB Costi-Ore YtD'!$G:$G,'DB Costi-Ore YtD'!$A:$A,G$1,'DB Costi-Ore YtD'!$B:$B,$A11,'DB Costi-Ore YtD'!$E:$E,$C11)-SUM($D11:F11),0) -> 2496.13 | H11: =IF((H$1*1)<=MAX('DB Costi-Ore YtD'!$A:$A),SUMIFS('DB Costi-Ore YtD'!$G:$G,'DB Costi-Ore YtD'!$A:$A,H$1,'DB Costi-Ore YtD'!$B:$B,$A11,'DB Costi-Ore YtD'!$E:$E,$C11)-SUM($D11:G11),0) -> 2340.48 | I11: =IF((I$1*1)<=MAX('DB Costi-Ore YtD'!$A:$A),SUMIFS('DB Costi-Ore YtD'!$G:$G,'DB Costi-Ore YtD'!$A:$A,I$1,'DB Costi-Ore YtD'!$B:$B,$A11,'DB Costi-Ore YtD'!$E:$E,$C11)-SUM($D11:H11),0) -> 2302.07 | J11: =IF((J$1*1)<=MAX('DB Costi-Ore YtD'!$A:$A),SUMIFS('DB Costi-Ore YtD'!$G:$G,'DB Costi-Ore YtD'!$A:$A,J$1,'DB Costi-Ore YtD'!$B:$B,$A11,'DB Costi-Ore YtD'!$E:$E,$C11)-SUM($D11:I11),0) -> 0 | K11: =IF((K$1*1)<=MAX('DB Costi-Ore YtD'!$A:$A),SUMIFS('DB Costi-Ore YtD'!$G:$G,'DB Costi-Ore YtD'!$A:$A,K$1,'DB Costi-Ore YtD'!$B:$B,$A11,'DB Costi-Ore YtD'!$E:$E,$C11)-SUM($D11:J11),0) -> 0 | L11: =IF((L$1*1)<=MAX('DB Costi-Ore YtD'!$A:$A),SUMIFS('DB Costi-Ore YtD'!$G:$G,'DB Costi-Ore YtD'!$A:$A,L$1,'DB Costi-Ore YtD'!$B:$B,$A11,'DB Costi-Ore YtD'!$E:$E,$C11)-SUM($D11:K11),0) -> 0 | ... O11: =IF((O$1*1)<=MAX('DB Costi-Ore YtD'!$A:$A),SUMIFS('DB Costi-Ore YtD'!$G:$G,'DB Costi-Ore YtD'!$A:$A,O$1,'DB Costi-Ore YtD'!$B:$B,$A11,'DB Costi-Ore YtD'!$E:$E,$C11)-SUM($D11:N11),0) -> 0
A12: 640 | B12: DEDAJ EGLANTINA | C12: P05 - PROTOTIPIA PDT | D12: =IF((D$1*1)<=MAX('DB Costi-Ore YtD'!$A:$A),SUMIFS('DB Costi-Ore YtD'!$G:$G,'DB Costi-Ore YtD'!$A:$A,D$1,'DB Costi-Ore YtD'!$B:$B,$A12,'DB Costi-Ore YtD'!$E:$E,$C12),0) -> 2270.89 | E12: =IF((E$1*1)<=MAX('DB Costi-Ore YtD'!$A:$A),SUMIFS('DB Costi-Ore YtD'!$G:$G,'DB Costi-Ore YtD'!$A:$A,E$1,'DB Costi-Ore YtD'!$B:$B,$A12,'DB Costi-Ore YtD'!$E:$E,$C12)-SUM($D12:D12),0) -> 2237.45 | F12: =IF((F$1*1)<=MAX('DB Costi-Ore YtD'!$A:$A),SUMIFS('DB Costi-Ore YtD'!$G:$G,'DB Costi-Ore YtD'!$A:$A,F$1,'DB Costi-Ore YtD'!$B:$B,$A12,'DB Costi-Ore YtD'!$E:$E,$C12)-SUM($D12:E12),0) -> 2206.29 | G12: =IF((G$1*1)<=MAX('DB Costi-Ore YtD'!$A:$A),SUMIFS('DB Costi-Ore YtD'!$G:$G,'DB Costi-Ore YtD'!$A:$A,G$1,'DB Costi-Ore YtD'!$B:$B,$A12,'DB Costi-Ore YtD'!$E:$E,$C12)-SUM($D12:F12),0) -> 2135.96 | H12: =IF((H$1*1)<=MAX('DB Costi-Ore YtD'!$A:$A),SUMIFS('DB Costi-Ore YtD'!$G:$G,'DB Costi-Ore YtD'!$A:$A,H$1,'DB Costi-Ore YtD'!$B:$B,$A12,'DB Costi-Ore YtD'!$E:$E,$C12)-SUM($D12:G12),0) -> 2079.15 | I12: =IF((I$1*1)<=MAX('DB Costi-Ore YtD'!$A:$A),SUMIFS('DB Costi-Ore YtD'!$G:$G,'DB Costi-Ore YtD'!$A:$A,I$1,'DB Costi-Ore YtD'!$B:$B,$A12,'DB Costi-Ore YtD'!$E:$E,$C12)-SUM($D12:H12),0) -> 2255.11 | J12: =IF((J$1*1)<=MAX('DB Costi-Ore YtD'!$A:$A),SUMIFS('DB Costi-Ore YtD'!$G:$G,'DB Costi-Ore YtD'!$A:$A,J$1,'DB Costi-Ore YtD'!$B:$B,$A12,'DB Costi-Ore YtD'!$E:$E,$C12)-SUM($D12:I12),0) -> 0 | K12: =IF((K$1*1)<=MAX('DB Costi-Ore YtD'!$A:$A),SUMIFS('DB Costi-Ore YtD'!$G:$G,'DB Costi-Ore YtD'!$A:$A,K$1,'DB Costi-Ore YtD'!$B:$B,$A12,'DB Costi-Ore YtD'!$E:$E,$C12)-SUM($D12:J12),0) -> 0 | L12: =IF((L$1*1)<=MAX('DB Costi-Ore YtD'!$A:$A),SUMIFS('DB Costi-Ore YtD'!$G:$G,'DB Costi-Ore YtD'!$A:$A,L$1,'DB Costi-Ore YtD'!$B:$B,$A12,'DB Costi-Ore YtD'!$E:$E,$C12)-SUM($D12:K12),0) -> 0 | ... O12: =IF((O$1*1)<=MAX('DB Costi-Ore YtD'!$A:$A),SUMIFS('DB Costi-Ore YtD'!$G:$G,'DB Costi-Ore YtD'!$A:$A,O$1,'DB Costi-Ore YtD'!$B:$B,$A12,'DB Costi-Ore YtD'!$E:$E,$C12)-SUM($D12:N12),0) -> 0
A13: 270 | B13: FISCALE ANNA | C13: S12 - COMM. MKTG. RETAIL | D13: =IF((D$1*1)<=MAX('DB Costi-Ore YtD'!$A:$A),SUMIFS('DB Costi-Ore YtD'!$G:$G,'DB Costi-Ore YtD'!$A:$A,D$1,'DB Costi-Ore YtD'!$B:$B,$A13,'DB Costi-Ore YtD'!$E:$E,$C13),0) -> 7620.16 | E13: =IF((E$1*1)<=MAX('DB Costi-Ore YtD'!$A:$A),SUMIFS('DB Costi-Ore YtD'!$G:$G,'DB Costi-Ore YtD'!$A:$A,E$1,'DB Costi-Ore YtD'!$B:$B,$A13,'DB Costi-Ore YtD'!$E:$E,$C13)-SUM($D13:D13),0) -> 6877.57 | F13: =IF((F$1*1)<=MAX('DB Costi-Ore YtD'!$A:$A),SUMIFS('DB Costi-Ore YtD'!$G:$G,'DB Costi-Ore YtD'!$A:$A,F$1,'DB Costi-Ore YtD'!$B:$B,$A13,'DB Costi-Ore YtD'!$E:$E,$C13)-SUM($D13:E13),0) -> 6768.91 | G13: =IF((G$1*1)<=MAX('DB Costi-Ore YtD'!$A:$A),SUMIFS('DB Costi-Ore YtD'!$G:$G,'DB Costi-Ore YtD'!$A:$A,G$1,'DB Costi-Ore YtD'!$B:$B,$A13,'DB Costi-Ore YtD'!$E:$E,$C13)-SUM($D13:F13),0) -> 14328.57 | H13: =IF((H$1*1)<=MAX('DB Costi-Ore YtD'!$A:$A),SUMIFS('DB Costi-Ore YtD'!$G:$G,'DB Costi-Ore YtD'!$A:$A,H$1,'DB Costi-Ore YtD'!$B:$B,$A13,'DB Costi-Ore YtD'!$E:$E,$C13)-SUM($D13:G13),0) -> 7143.71 | I13: =IF((I$1*1)<=MAX('DB Costi-Ore YtD'!$A:$A),SUMIFS('DB Costi-Ore YtD'!$G:$G,'DB Costi-Ore YtD'!$A:$A,I$1,'DB Costi-Ore YtD'!$B:$B,$A13,'DB Costi-Ore YtD'!$E:$E,$C13)-SUM($D13:H13),0) -> 8434.19 | J13: =IF((J$1*1)<=MAX('DB Costi-Ore YtD'!$A:$A),SUMIFS('DB Costi-Ore YtD'!$G:$G,'DB Costi-Ore YtD'!$A:$A,J$1,'DB Costi-Ore YtD'!$B:$B,$A13,'DB Costi-Ore YtD'!$E:$E,$C13)-SUM($D13:I13),0) -> 0 | K13: =IF((K$1*1)<=MAX('DB Costi-Ore YtD'!$A:$A),SUMIFS('DB Costi-Ore YtD'!$G:$G,'DB Costi-Ore YtD'!$A:$A,K$1,'DB Costi-Ore YtD'!$B:$B,$A13,'DB Costi-Ore YtD'!$E:$E,$C13)-SUM($D13:J13),0) -> 0 | L13: =IF((L$1*1)<=MAX('DB Costi-Ore YtD'!$A:$A),SUMIFS('DB Costi-Ore YtD'!$G:$G,'DB Costi-Ore YtD'!$A:$A,L$1,'DB Costi-Ore YtD'!$B:$B,$A13,'DB Costi-Ore YtD'!$E:$E,$C13)-SUM($D13:K13),0) -> 0 | ... O13: =IF((O$1*1)<=MAX('DB Costi-Ore YtD'!$A:$A),SUMIFS('DB Costi-Ore YtD'!$G:$G,'DB Costi-Ore YtD'!$A:$A,O$1,'DB Costi-Ore YtD'!$B:$B,$A13,'DB Costi-Ore YtD'!$E:$E,$C13)-SUM($D13:N13),0) -> 0
... A214: 80800 | B214: VAROTTO TAMARA | C214: P06 - CARCERE PDT | D214: =IF((D$1*1)<=MAX('DB Costi-Ore YtD'!$A:$A),SUMIFS('DB Costi-Ore YtD'!$G:$G,'DB Costi-Ore YtD'!$A:$A,D$1,'DB Costi-Ore YtD'!$B:$B,$A214,'DB Costi-Ore YtD'!$E:$E,$C214),0) -> 0 | E214: =IF((E$1*1)<=MAX('DB Costi-Ore YtD'!$A:$A),SUMIFS('DB Costi-Ore YtD'!$G:$G,'DB Costi-Ore YtD'!$A:$A,E$1,'DB Costi-Ore YtD'!$B:$B,$A214,'DB Costi-Ore YtD'!$E:$E,$C214)-SUM($D214:D214),0) -> 0 | F214: =IF((F$1*1)<=MAX('DB Costi-Ore YtD'!$A:$A),SUMIFS('DB Costi-Ore YtD'!$G:$G,'DB Costi-Ore YtD'!$A:$A,F$1,'DB Costi-Ore YtD'!$B:$B,$A214,'DB Costi-Ore YtD'!$E:$E,$C214)-SUM($D214:E214),0) -> 0 | G214: =IF((G$1*1)<=MAX('DB Costi-Ore YtD'!$A:$A),SUMIFS('DB Costi-Ore YtD'!$G:$G,'DB Costi-Ore YtD'!$A:$A,G$1,'DB Costi-Ore YtD'!$B:$B,$A214,'DB Costi-Ore YtD'!$E:$E,$C214)-SUM($D214:F214),0) -> 0 | H214: =IF((H$1*1)<=MAX('DB Costi-Ore YtD'!$A:$A),SUMIFS('DB Costi-Ore YtD'!$G:$G,'DB Costi-Ore YtD'!$A:$A,H$1,'DB Costi-Ore YtD'!$B:$B,$A214,'DB Costi-Ore YtD'!$E:$E,$C214)-SUM($D214:G214),0) -> 0 | I214: =IF((I$1*1)<=MAX('DB Costi-Ore YtD'!$A:$A),SUMIFS('DB Costi-Ore YtD'!$G:$G,'DB Costi-Ore YtD'!$A:$A,I$1,'DB Costi-Ore YtD'!$B:$B,$A214,'DB Costi-Ore YtD'!$E:$E,$C214)-SUM($D214:H214),0) -> 566.08 | J214: =IF((J$1*1)<=MAX('DB Costi-Ore YtD'!$A:$A),SUMIFS('DB Costi-Ore YtD'!$G:$G,'DB Costi-Ore YtD'!$A:$A,J$1,'DB Costi-Ore YtD'!$B:$B,$A214,'DB Costi-Ore YtD'!$E:$E,$C214)-SUM($D214:I214),0) -> 0 | K214: =IF((K$1*1)<=MAX('DB Costi-Ore YtD'!$A:$A),SUMIFS('DB Costi-Ore YtD'!$G:$G,'DB Costi-Ore YtD'!$A:$A,K$1,'DB Costi-Ore YtD'!$B:$B,$A214,'DB Costi-Ore YtD'!$E:$E,$C214)-SUM($D214:J214),0) -> 0 | L214: =IF((L$1*1)<=MAX('DB Costi-Ore YtD'!$A:$A),SUMIFS('DB Costi-Ore YtD'!$G:$G,'DB Costi-Ore YtD'!$A:$A,L$1,'DB Costi-Ore YtD'!$B:$B,$A214,'DB Costi-Ore YtD'!$E:$E,$C214)-SUM($D214:K214),0) -> 0 | ... O214: =IF((O$1*1)<=MAX('DB Costi-Ore YtD'!$A:$A),SUMIFS('DB Costi-Ore YtD'!$G:$G,'DB Costi-Ore YtD'!$A:$A,O$1,'DB Costi-Ore YtD'!$B:$B,$A214,'DB Costi-Ore YtD'!$E:$E,$C214)-SUM($D214:N214),0) -> 0

Sheet DB Ore Mese
A1: Matricola | B1: Dipendente | C1: Centro di Costo | D1: 31/01/2025 | E1: 28/02/2025 | F1: 31/03/2025 | G1: 30/04/2025 | H1: 31/05/2025 | I1: 30/06/2025 | J1: 31/07/2025 | K1: 31/08/2025 | L1: 30/09/2025 | M1: 31/10/2025 | N1: 30/11/2025 | O1: 31/12/2025
A2: 50 | B2: FENG XIUHUA | C2: P01 - CONFEZIONAMENTO PDT | D2: =IF((D$1*1)<=MAX('DB Costi-Ore YtD'!$A:$A),SUMIFS('DB Costi-Ore YtD'!$F:$F,'DB Costi-Ore YtD'!$A:$A,D$1,'DB Costi-Ore YtD'!$B:$B,$A2,'DB Costi-Ore YtD'!$E:$E,$C2),0) -> 148.25 | E2: =IF((E$1*1)<=MAX('DB Costi-Ore YtD'!$A:$A),SUMIFS('DB Costi-Ore YtD'!$F:$F,'DB Costi-Ore YtD'!$A:$A,E$1,'DB Costi-Ore YtD'!$B:$B,$A2,'DB Costi-Ore YtD'!$E:$E,$C2)-SUM($D2:D2),0) -> 147.25 | F2: =IF((F$1*1)<=MAX('DB Costi-Ore YtD'!$A:$A),SUMIFS('DB Costi-Ore YtD'!$F:$F,'DB Costi-Ore YtD'!$A:$A,F$1,'DB Costi-Ore YtD'!$B:$B,$A2,'DB Costi-Ore YtD'!$E:$E,$C2)-SUM($D2:E2),0) -> 142 | G2: =IF((G$1*1)<=MAX('DB Costi-Ore YtD'!$A:$A),SUMIFS('DB Costi-Ore YtD'!$F:$F,'DB Costi-Ore YtD'!$A:$A,G$1,'DB Costi-Ore YtD'!$B:$B,$A2,'DB Costi-Ore YtD'!$E:$E,$C2)-SUM($D2:F2),0) -> 155.5 | H2: =IF((H$1*1)<=MAX('DB Costi-Ore YtD'!$A:$A),SUMIFS('DB Costi-Ore YtD'!$F:$F,'DB Costi-Ore YtD'!$A:$A,H$1,'DB Costi-Ore YtD'!$B:$B,$A2,'DB Costi-Ore YtD'!$E:$E,$C2)-SUM($D2:G2),0) -> 153 | I2: =IF((I$1*1)<=MAX('DB Costi-Ore YtD'!$A:$A),SUMIFS('DB Costi-Ore YtD'!$F:$F,'DB Costi-Ore YtD'!$A:$A,I$1,'DB Costi-Ore YtD'!$B:$B,$A2,'DB Costi-Ore YtD'!$E:$E,$C2)-SUM($D2:H2),0) -> 151.5 | J2: =IF((J$1*1)<=MAX('DB Costi-Ore YtD'!$A:$A),SUMIFS('DB Costi-Ore YtD'!$F:$F,'DB Costi-Ore YtD'!$A:$A,J$1,'DB Costi-Ore YtD'!$B:$B,$A2,'DB Costi-Ore YtD'!$E:$E,$C2)-SUM($D2:I2),0) -> 0 | K2: =IF((K$1*1)<=MAX('DB Costi-Ore YtD'!$A:$A),SUMIFS('DB Costi-Ore YtD'!$F:$F,'DB Costi-Ore YtD'!$A:$A,K$1,'DB Costi-Ore YtD'!$B:$B,$A2,'DB Costi-Ore YtD'!$E:$E,$C2)-SUM($D2:J2),0) -> 0 | L2: =IF((L$1*1)<=MAX('DB Costi-Ore YtD'!$A:$A),SUMIFS('DB Costi-Ore YtD'!$F:$F,'DB Costi-Ore YtD'!$A:$A,L$1,'DB Costi-Ore YtD'!$B:$B,$A2,'DB Costi-Ore YtD'!$E:$E,$C2)-SUM($D2:K2),0) -> 0 | ... O2: =IF((O$1*1)<=MAX('DB Costi-Ore YtD'!$A:$A),SUMIFS('DB Costi-Ore YtD'!$F:$F,'DB Costi-Ore YtD'!$A:$A,O$1,'DB Costi-Ore YtD'!$B:$B,$A2,'DB Costi-Ore YtD'!$E:$E,$C2)-SUM($D2:N2),0) -> 0
A3: 240 | B3: VALBUSA VALERIA | C3: P01 - CONFEZIONAMENTO PDT | D3: =IF((D$1*1)<=MAX('DB Costi-Ore YtD'!$A:$A),SUMIFS('DB Costi-Ore YtD'!$F:$F,'DB Costi-Ore YtD'!$A:$A,D$1,'DB Costi-Ore YtD'!$B:$B,$A3,'DB Costi-Ore YtD'!$E:$E,$C3),0) -> 97 | E3: =IF((E$1*1)<=MAX('DB Costi-Ore YtD'!$A:$A),SUMIFS('DB Costi-Ore YtD'!$F:$F,'DB Costi-Ore YtD'!$A:$A,E$1,'DB Costi-Ore YtD'!$B:$B,$A3,'DB Costi-Ore YtD'!$E:$E,$C3)-SUM($D3:D3),0) -> 47.25 | F3: =IF((F$1*1)<=MAX('DB Costi-Ore YtD'!$A:$A),SUMIFS('DB Costi-Ore YtD'!$F:$F,'DB Costi-Ore YtD'!$A:$A,F$1,'DB Costi-Ore YtD'!$B:$B,$A3,'DB Costi-Ore YtD'!$E:$E,$C3)-SUM($D3:E3),0) -> 17.5 | G3: =IF((G$1*1)<=MAX('DB Costi-Ore YtD'!$A:$A),SUMIFS('DB Costi-Ore YtD'!$F:$F,'DB Costi-Ore YtD'!$A:$A,G$1,'DB Costi-Ore YtD'!$B:$B,$A3,'DB Costi-Ore YtD'!$E:$E,$C3)-SUM($D3:F3),0) -> 0 | H3: =IF((H$1*1)<=MAX('DB Costi-Ore YtD'!$A:$A),SUMIFS('DB Costi-Ore YtD'!$F:$F,'DB Costi-Ore YtD'!$A:$A,H$1,'DB Costi-Ore YtD'!$B:$B,$A3,'DB Costi-Ore YtD'!$E:$E,$C3)-SUM($D3:G3),0) -> -161.75 | I3: =IF((I$1*1)<=MAX('DB Costi-Ore YtD'!$A:$A),SUMIFS('DB Costi-Ore YtD'!$F:$F,'DB Costi-Ore YtD'!$A:$A,I$1,'DB Costi-Ore YtD'!$B:$B,$A3,'DB Costi-Ore YtD'!$E:$E,$C3)-SUM($D3:H3),0) -> 0 | J3: =IF((J$1*1)<=MAX('DB Costi-Ore YtD'!$A:$A),SUMIFS('DB Costi-Ore YtD'!$F:$F,'DB Costi-Ore YtD'!$A:$A,J$1,'DB Costi-Ore YtD'!$B:$B,$A3,'DB Costi-Ore YtD'!$E:$E,$C3)-SUM($D3:I3),0) -> 0 | K3: =IF((K$1*1)<=MAX('DB Costi-Ore YtD'!$A:$A),SUMIFS('DB Costi-Ore YtD'!$F:$F,'DB Costi-Ore YtD'!$A:$A,K$1,'DB Costi-Ore YtD'!$B:$B,$A3,'DB Costi-Ore YtD'!$E:$E,$C3)-SUM($D3:J3),0) -> 0 | L3: =IF((L$1*1)<=MAX('DB Costi-Ore YtD'!$A:$A),SUMIFS('DB Costi-Ore YtD'!$F:$F,'DB Costi-Ore YtD'!$A:$A,L$1,'DB Costi-Ore YtD'!$B:$B,$A3,'DB Costi-Ore YtD'!$E:$E,$C3)-SUM($D3:K3),0) -> 0 | ... O3: =IF((O$1*1)<=MAX('DB Costi-Ore YtD'!$A:$A),SUMIFS('DB Costi-Ore YtD'!$F:$F,'DB Costi-Ore YtD'!$A:$A,O$1,'DB Costi-Ore YtD'!$B:$B,$A3,'DB Costi-Ore YtD'!$E:$E,$C3)-SUM($D3:N3),0) -> 0
A4: 550 | B4: ZANARDO FABIANA | C4: P01 - CONFEZIONAMENTO PDT | D4: =IF((D$1*1)<=MAX('DB Costi-Ore YtD'!$A:$A),SUMIFS('DB Costi-Ore YtD'!$F:$F,'DB Costi-Ore YtD'!$A:$A,D$1,'DB Costi-Ore YtD'!$B:$B,$A4,'DB Costi-Ore YtD'!$E:$E,$C4),0) -> 98.5 | E4: =IF((E$1*1)<=MAX('DB Costi-Ore YtD'!$A:$A),SUMIFS('DB Costi-Ore YtD'!$F:$F,'DB Costi-Ore YtD'!$A:$A,E$1,'DB Costi-Ore YtD'!$B:$B,$A4,'DB Costi-Ore YtD'!$E:$E,$C4)-SUM($D4:D4),0) -> 75.5 | F4: =IF((F$1*1)<=MAX('DB Costi-Ore YtD'!$A:$A),SUMIFS('DB Costi-Ore YtD'!$F:$F,'DB Costi-Ore YtD'!$A:$A,F$1,'DB Costi-Ore YtD'!$B:$B,$A4,'DB Costi-Ore YtD'!$E:$E,$C4)-SUM($D4:E4),0) -> 133 | G4: =IF((G$1*1)<=MAX('DB Costi-Ore YtD'!$A:$A),SUMIFS('DB Costi-Ore YtD'!$F:$F,'DB Costi-Ore YtD'!$A:$A,G$1,'DB Costi-Ore YtD'!$B:$B,$A4,'DB Costi-Ore YtD'!$E:$E,$C4)-SUM($D4:F4),0) -> 30 | H4: =IF((H$1*1)<=MAX('DB Costi-Ore YtD'!$A:$A),SUMIFS('DB Costi-Ore YtD'!$F:$F,'DB Costi-Ore YtD'!$A:$A,H$1,'DB Costi-Ore YtD'!$B:$B,$A4,'DB Costi-Ore YtD'!$E:$E,$C4)-SUM($D4:G4),0) -> 0 | I4: =IF((I$1*1)<=MAX('DB Costi-Ore YtD'!$A:$A),SUMIFS('DB Costi-Ore YtD'!$F:$F,'DB Costi-Ore YtD'!$A:$A,I$1,'DB Costi-Ore YtD'!$B:$B,$A4,'DB Costi-Ore YtD'!$E:$E,$C4)-SUM($D4:H4),0) -> 0 | J4: =IF((J$1*1)<=MAX('DB Costi-Ore YtD'!$A:$A),SUMIFS('DB Costi-Ore YtD'!$F:$F,'DB Costi-Ore YtD'!$A:$A,J$1,'DB Costi-Ore YtD'!$B:$B,$A4,'DB Costi-Ore YtD'!$E:$E,$C4)-SUM($D4:I4),0) -> 0 | K4: =IF((K$1*1)<=MAX('DB Costi-Ore YtD'!$A:$A),SUMIFS('DB Costi-Ore YtD'!$F:$F,'DB Costi-Ore YtD'!$A:$A,K$1,'DB Costi-Ore YtD'!$B:$B,$A4,'DB Costi-Ore YtD'!$E:$E,$C4)-SUM($D4:J4),0) -> 0 | L4: =IF((L$1*1)<=MAX('DB Costi-Ore YtD'!$A:$A),SUMIFS('DB Costi-Ore YtD'!$F:$F,'DB Costi-Ore YtD'!$A:$A,L$1,'DB Costi-Ore YtD'!$B:$B,$A4,'DB Costi-Ore YtD'!$E:$E,$C4)-SUM($D4:K4),0) -> 0 | ... O4: =IF((O$1*1)<=MAX('DB Costi-Ore YtD'!$A:$A),SUMIFS('DB Costi-Ore YtD'!$F:$F,'DB Costi-Ore YtD'!$A:$A,O$1,'DB Costi-Ore YtD'!$B:$B,$A4,'DB Costi-Ore YtD'!$E:$E,$C4)-SUM($D4:N4),0) -> 0
A5: 590 | B5: RIGHETTI FLAVIA | C5: P01 - CONFEZIONAMENTO PDT | D5: =IF((D$1*1)<=MAX('DB Costi-Ore YtD'!$A:$A),SUMIFS('DB Costi-Ore YtD'!$F:$F,'DB Costi-Ore YtD'!$A:$A,D$1,'DB Costi-Ore YtD'!$B:$B,$A5,'DB Costi-Ore YtD'!$E:$E,$C5),0) -> 148 | E5: =IF((E$1*1)<=MAX('DB Costi-Ore YtD'!$A:$A),SUMIFS('DB Costi-Ore YtD'!$F:$F,'DB Costi-Ore YtD'!$A:$A,E$1,'DB Costi-Ore YtD'!$B:$B,$A5,'DB Costi-Ore YtD'!$E:$E,$C5)-SUM($D5:D5),0) -> 135.5 | F5: =IF((F$1*1)<=MAX('DB Costi-Ore YtD'!$A:$A),SUMIFS('DB Costi-Ore YtD'!$F:$F,'DB Costi-Ore YtD'!$A:$A,F$1,'DB Costi-Ore YtD'!$B:$B,$A5,'DB Costi-Ore YtD'!$E:$E,$C5)-SUM($D5:E5),0) -> 160 | G5: =IF((G$1*1)<=MAX('DB Costi-Ore YtD'!$A:$A),SUMIFS('DB Costi-Ore YtD'!$F:$F,'DB Costi-Ore YtD'!$A:$A,G$1,'DB Costi-Ore YtD'!$B:$B,$A5,'DB Costi-Ore YtD'!$E:$E,$C5)-SUM($D5:F5),0) -> 154 | H5: =IF((H$1*1)<=MAX('DB Costi-Ore YtD'!$A:$A),SUMIFS('DB Costi-Ore YtD'!$F:$F,'DB Costi-Ore YtD'!$A:$A,H$1,'DB Costi-Ore YtD'!$B:$B,$A5,'DB Costi-Ore YtD'!$E:$E,$C5)-SUM($D5:G5),0) -> 140 | I5: =IF((I$1*1)<=MAX('DB Costi-Ore YtD'!$A:$A),SUMIFS('DB Costi-Ore YtD'!$F:$F,'DB Costi-Ore YtD'!$A:$A,I$1,'DB Costi-Ore YtD'!$B:$B,$A5,'DB Costi-Ore YtD'!$E:$E,$C5)-SUM($D5:H5),0) -> 101 | J5: =IF((J$1*1)<=MAX('DB Costi-Ore YtD'!$A:$A),SUMIFS('DB Costi-Ore YtD'!$F:$F,'DB Costi-Ore YtD'!$A:$A,J$1,'DB Costi-Ore YtD'!$B:$B,$A5,'DB Costi-Ore YtD'!$E:$E,$C5)-SUM($D5:I5),0) -> 0 | K5: =IF((K$1*1)<=MAX('DB Costi-Ore YtD'!$A:$A),SUMIFS('DB Costi-Ore YtD'!$F:$F,'DB Costi-Ore YtD'!$A:$A,K$1,'DB Costi-Ore YtD'!$B:$B,$A5,'DB Costi-Ore YtD'!$E:$E,$C5)-SUM($D5:J5),0) -> 0 | L5: =IF((L$1*1)<=MAX('DB Costi-Ore YtD'!$A:$A),SUMIFS('DB Costi-Ore YtD'!$F:$F,'DB Costi-Ore YtD'!$A:$A,L$1,'DB Costi-Ore YtD'!$B:$B,$A5,'DB Costi-Ore YtD'!$E:$E,$C5)-SUM($D5:K5),0) -> 0 | ... O5: =IF((O$1*1)<=MAX('DB Costi-Ore YtD'!$A:$A),SUMIFS('DB Costi-Ore YtD'!$F:$F,'DB Costi-Ore YtD'!$A:$A,O$1,'DB Costi-Ore YtD'!$B:$B,$A5,'DB Costi-Ore YtD'!$E:$E,$C5)-SUM($D5:N5),0) -> 0
A6: 600 | B6: MOLINARI LAURA | C6: P01 - CONFEZIONAMENTO PDT | D6: =IF((D$1*1)<=MAX('DB Costi-Ore YtD'!$A:$A),SUMIFS('DB Costi-Ore YtD'!$F:$F,'DB Costi-Ore YtD'!$A:$A,D$1,'DB Costi-Ore YtD'!$B:$B,$A6,'DB Costi-Ore YtD'!$E:$E,$C6),0) -> 151.5 | E6: =IF((E$1*1)<=MAX('DB Costi-Ore YtD'!$A:$A),SUMIFS('DB Costi-Ore YtD'!$F:$F,'DB Costi-Ore YtD'!$A:$A,E$1,'DB Costi-Ore YtD'!$B:$B,$A6,'DB Costi-Ore YtD'!$E:$E,$C6)-SUM($D6:D6),0) -> 144.5 | F6: =IF((F$1*1)<=MAX('DB Costi-Ore YtD'!$A:$A),SUMIFS('DB Costi-Ore YtD'!$F:$F,'DB Costi-Ore YtD'!$A:$A,F$1,'DB Costi-Ore YtD'!$B:$B,$A6,'DB Costi-Ore YtD'!$E:$E,$C6)-SUM($D6:E6),0) -> 156 | G6: =IF((G$1*1)<=MAX('DB Costi-Ore YtD'!$A:$A),SUMIFS('DB Costi-Ore YtD'!$F:$F,'DB Costi-Ore YtD'!$A:$A,G$1,'DB Costi-Ore YtD'!$B:$B,$A6,'DB Costi-Ore YtD'!$E:$E,$C6)-SUM($D6:F6),0) -> 151.5 | H6: =IF((H$1*1)<=MAX('DB Costi-Ore YtD'!$A:$A),SUMIFS('DB Costi-Ore YtD'!$F:$F,'DB Costi-Ore YtD'!$A:$A,H$1,'DB Costi-Ore YtD'!$B:$B,$A6,'DB Costi-Ore YtD'!$E:$E,$C6)-SUM($D6:G6),0) -> 124.75 | I6: =IF((I$1*1)<=MAX('DB Costi-Ore YtD'!$A:$A),SUMIFS('DB Costi-Ore YtD'!$F:$F,'DB Costi-Ore YtD'!$A:$A,I$1,'DB Costi-Ore YtD'!$B:$B,$A6,'DB Costi-Ore YtD'!$E:$E,$C6)-SUM($D6:H6),0) -> 46 | J6: =IF((J$1*1)<=MAX('DB Costi-Ore YtD'!$A:$A),SUMIFS('DB Costi-Ore YtD'!$F:$F,'DB Costi-Ore YtD'!$A:$A,J$1,'DB Costi-Ore YtD'!$B:$B,$A6,'DB Costi-Ore YtD'!$E:$E,$C6)-SUM($D6:I6),0) -> 0 | K6: =IF((K$1*1)<=MAX('DB Costi-Ore YtD'!$A:$A),SUMIFS('DB Costi-Ore YtD'!$F:$F,'DB Costi-Ore YtD'!$A:$A,K$1,'DB Costi-Ore YtD'!$B:$B,$A6,'DB Costi-Ore YtD'!$E:$E,$C6)-SUM($D6:J6),0) -> 0 | L6: =IF((L$1*1)<=MAX('DB Costi-Ore YtD'!$A:$A),SUMIFS('DB Costi-Ore YtD'!$F:$F,'DB Costi-Ore YtD'!$A:$A,L$1,'DB Costi-Ore YtD'!$B:$B,$A6,'DB Costi-Ore YtD'!$E:$E,$C6)-SUM($D6:K6),0) -> 0 | ... O6: =IF((O$1*1)<=MAX('DB Costi-Ore YtD'!$A:$A),SUMIFS('DB Costi-Ore YtD'!$F:$F,'DB Costi-Ore YtD'!$A:$A,O$1,'DB Costi-Ore YtD'!$B:$B,$A6,'DB Costi-Ore YtD'!$E:$E,$C6)-SUM($D6:N6),0) -> 0
A7: 620 | B7: ANSELMI IVA | C7: P01 - CONFEZIONAMENTO PDT | D7: =IF((D$1*1)<=MAX('DB Costi-Ore YtD'!$A:$A),SUMIFS('DB Costi-Ore YtD'!$F:$F,'DB Costi-Ore YtD'!$A:$A,D$1,'DB Costi-Ore YtD'!$B:$B,$A7,'DB Costi-Ore YtD'!$E:$E,$C7),0) -> 142.5 | E7: =IF((E$1*1)<=MAX('DB Costi-Ore YtD'!$A:$A),SUMIFS('DB Costi-Ore YtD'!$F:$F,'DB Costi-Ore YtD'!$A:$A,E$1,'DB Costi-Ore YtD'!$B:$B,$A7,'DB Costi-Ore YtD'!$E:$E,$C7)-SUM($D7:D7),0) -> 106.5 | F7: =IF((F$1*1)<=MAX('DB Costi-Ore YtD'!$A:$A),SUMIFS('DB Costi-Ore YtD'!$F:$F,'DB Costi-Ore YtD'!$A:$A,F$1,'DB Costi-Ore YtD'!$B:$B,$A7,'DB Costi-Ore YtD'!$E:$E,$C7)-SUM($D7:E7),0) -> 61 | G7: =IF((G$1*1)<=MAX('DB Costi-Ore YtD'!$A:$A),SUMIFS('DB Costi-Ore YtD'!$F:$F,'DB Costi-Ore YtD'!$A:$A,G$1,'DB Costi-Ore YtD'!$B:$B,$A7,'DB Costi-Ore YtD'!$E:$E,$C7)-SUM($D7:F7),0) -> 141 | H7: =IF((H$1*1)<=MAX('DB Costi-Ore YtD'!$A:$A),SUMIFS('DB Costi-Ore YtD'!$F:$F,'DB Costi-Ore YtD'!$A:$A,H$1,'DB Costi-Ore YtD'!$B:$B,$A7,'DB Costi-Ore YtD'!$E:$E,$C7)-SUM($D7:G7),0) -> 132.5 | I7: =IF((I$1*1)<=MAX('DB Costi-Ore YtD'!$A:$A),SUMIFS('DB Costi-Ore YtD'!$F:$F,'DB Costi-Ore YtD'!$A:$A,I$1,'DB Costi-Ore YtD'!$B:$B,$A7,'DB Costi-Ore YtD'!$E:$E,$C7)-SUM($D7:H7),0) -> 148 | J7: =IF((J$1*1)<=MAX('DB Costi-Ore YtD'!$A:$A),SUMIFS('DB Costi-Ore YtD'!$F:$F,'DB Costi-Ore YtD'!$A:$A,J$1,'DB Costi-Ore YtD'!$B:$B,$A7,'DB Costi-Ore YtD'!$E:$E,$C7)-SUM($D7:I7),0) -> 0 | K7: =IF((K$1*1)<=MAX('DB Costi-Ore YtD'!$A:$A),SUMIFS('DB Costi-Ore YtD'!$F:$F,'DB Costi-Ore YtD'!$A:$A,K$1,'DB Costi-Ore YtD'!$B:$B,$A7,'DB Costi-Ore YtD'!$E:$E,$C7)-SUM($D7:J7),0) -> 0 | L7: =IF((L$1*1)<=MAX('DB Costi-Ore YtD'!$A:$A),SUMIFS('DB Costi-Ore YtD'!$F:$F,'DB Costi-Ore YtD'!$A:$A,L$1,'DB Costi-Ore YtD'!$B:$B,$A7,'DB Costi-Ore YtD'!$E:$E,$C7)-SUM($D7:K7),0) -> 0 | ... O7: =IF((O$1*1)<=MAX('DB Costi-Ore YtD'!$A:$A),SUMIFS('DB Costi-Ore YtD'!$F:$F,'DB Costi-Ore YtD'!$A:$A,O$1,'DB Costi-Ore YtD'!$B:$B,$A7,'DB Costi-Ore YtD'!$E:$E,$C7)-SUM($D7:N7),0) -> 0
A8: 150 | B8: ENGUIX GRIMALTOS GEMA MARIA | C8: P07 - TAGLIO | D8: =IF((D$1*1)<=MAX('DB Costi-Ore YtD'!$A:$A),SUMIFS('DB Costi-Ore YtD'!$F:$F,'DB Costi-Ore YtD'!$A:$A,D$1,'DB Costi-Ore YtD'!$B:$B,$A8,'DB Costi-Ore YtD'!$E:$E,$C8),0) -> 136 | E8: =IF((E$1*1)<=MAX('DB Costi-Ore YtD'!$A:$A),SUMIFS('DB Costi-Ore YtD'!$F:$F,'DB Costi-Ore YtD'!$A:$A,E$1,'DB Costi-Ore YtD'!$B:$B,$A8,'DB Costi-Ore YtD'!$E:$E,$C8)-SUM($D8:D8),0) -> 143 | F8: =IF((F$1*1)<=MAX('DB Costi-Ore YtD'!$A:$A),SUMIFS('DB Costi-Ore YtD'!$F:$F,'DB Costi-Ore YtD'!$A:$A,F$1,'DB Costi-Ore YtD'!$B:$B,$A8,'DB Costi-Ore YtD'!$E:$E,$C8)-SUM($D8:E8),0) -> 152.75 | G8: =IF((G$1*1)<=MAX('DB Costi-Ore YtD'!$A:$A),SUMIFS('DB Costi-Ore YtD'!$F:$F,'DB Costi-Ore YtD'!$A:$A,G$1,'DB Costi-Ore YtD'!$B:$B,$A8,'DB Costi-Ore YtD'!$E:$E,$C8)-SUM($D8:F8),0) -> 140.5 | H8: =IF((H$1*1)<=MAX('DB Costi-Ore YtD'!$A:$A),SUMIFS('DB Costi-Ore YtD'!$F:$F,'DB Costi-Ore YtD'!$A:$A,H$1,'DB Costi-Ore YtD'!$B:$B,$A8,'DB Costi-Ore YtD'!$E:$E,$C8)-SUM($D8:G8),0) -> 120.5 | I8: =IF((I$1*1)<=MAX('DB Costi-Ore YtD'!$A:$A),SUMIFS('DB Costi-Ore YtD'!$F:$F,'DB Costi-Ore YtD'!$A:$A,I$1,'DB Costi-Ore YtD'!$B:$B,$A8,'DB Costi-Ore YtD'!$E:$E,$C8)-SUM($D8:H8),0) -> 133.75 | J8: =IF((J$1*1)<=MAX('DB Costi-Ore YtD'!$A:$A),SUMIFS('DB Costi-Ore YtD'!$F:$F,'DB Costi-Ore YtD'!$A:$A,J$1,'DB Costi-Ore YtD'!$B:$B,$A8,'DB Costi-Ore YtD'!$E:$E,$C8)-SUM($D8:I8),0) -> 0 | K8: =IF((K$1*1)<=MAX('DB Costi-Ore YtD'!$A:$A),SUMIFS('DB Costi-Ore YtD'!$F:$F,'DB Costi-Ore YtD'!$A:$A,K$1,'DB Costi-Ore YtD'!$B:$B,$A8,'DB Costi-Ore YtD'!$E:$E,$C8)-SUM($D8:J8),0) -> 0 | L8: =IF((L$1*1)<=MAX('DB Costi-Ore YtD'!$A:$A),SUMIFS('DB Costi-Ore YtD'!$F:$F,'DB Costi-Ore YtD'!$A:$A,L$1,'DB Costi-Ore YtD'!$B:$B,$A8,'DB Costi-Ore YtD'!$E:$E,$C8)-SUM($D8:K8),0) -> 0 | ... O8: =IF((O$1*1)<=MAX('DB Costi-Ore YtD'!$A:$A),SUMIFS('DB Costi-Ore YtD'!$F:$F,'DB Costi-Ore YtD'!$A:$A,O$1,'DB Costi-Ore YtD'!$B:$B,$A8,'DB Costi-Ore YtD'!$E:$E,$C8)-SUM($D8:N8),0) -> 0
A9: 260 | B9: AVESANI SILVIA | C9: P02 - QC- STIRO - PACK | D9: =IF((D$1*1)<=MAX('DB Costi-Ore YtD'!$A:$A),SUMIFS('DB Costi-Ore YtD'!$F:$F,'DB Costi-Ore YtD'!$A:$A,D$1,'DB Costi-Ore YtD'!$B:$B,$A9,'DB Costi-Ore YtD'!$E:$E,$C9),0) -> 151.5 | E9: =IF((E$1*1)<=MAX('DB Costi-Ore YtD'!$A:$A),SUMIFS('DB Costi-Ore YtD'!$F:$F,'DB Costi-Ore YtD'!$A:$A,E$1,'DB Costi-Ore YtD'!$B:$B,$A9,'DB Costi-Ore YtD'!$E:$E,$C9)-SUM($D9:D9),0) -> 128.75 | F9: =IF((F$1*1)<=MAX('DB Costi-Ore YtD'!$A:$A),SUMIFS('DB Costi-Ore YtD'!$F:$F,'DB Costi-Ore YtD'!$A:$A,F$1,'DB Costi-Ore YtD'!$B:$B,$A9,'DB Costi-Ore YtD'!$E:$E,$C9)-SUM($D9:E9),0) -> 148.75 | G9: =IF((G$1*1)<=MAX('DB Costi-Ore YtD'!$A:$A),SUMIFS('DB Costi-Ore YtD'!$F:$F,'DB Costi-Ore YtD'!$A:$A,G$1,'DB Costi-Ore YtD'!$B:$B,$A9,'DB Costi-Ore YtD'!$E:$E,$C9)-SUM($D9:F9),0) -> 152.25 | H9: =IF((H$1*1)<=MAX('DB Costi-Ore YtD'!$A:$A),SUMIFS('DB Costi-Ore YtD'!$F:$F,'DB Costi-Ore YtD'!$A:$A,H$1,'DB Costi-Ore YtD'!$B:$B,$A9,'DB Costi-Ore YtD'!$E:$E,$C9)-SUM($D9:G9),0) -> 138.5 | I9: =IF((I$1*1)<=MAX('DB Costi-Ore YtD'!$A:$A),SUMIFS('DB Costi-Ore YtD'!$F:$F,'DB Costi-Ore YtD'!$A:$A,I$1,'DB Costi-Ore YtD'!$B:$B,$A9,'DB Costi-Ore YtD'!$E:$E,$C9)-SUM($D9:H9),0) -> 144.5 | J9: =IF((J$1*1)<=MAX('DB Costi-Ore YtD'!$A:$A),SUMIFS('DB Costi-Ore YtD'!$F:$F,'DB Costi-Ore YtD'!$A:$A,J$1,'DB Costi-Ore YtD'!$B:$B,$A9,'DB Costi-Ore YtD'!$E:$E,$C9)-SUM($D9:I9),0) -> 0 | K9: =IF((K$1*1)<=MAX('DB Costi-Ore YtD'!$A:$A),SUMIFS('DB Costi-Ore YtD'!$F:$F,'DB Costi-Ore YtD'!$A:$A,K$1,'DB Costi-Ore YtD'!$B:$B,$A9,'DB Costi-Ore YtD'!$E:$E,$C9)-SUM($D9:J9),0) -> 0 | L9: =IF((L$1*1)<=MAX('DB Costi-Ore YtD'!$A:$A),SUMIFS('DB Costi-Ore YtD'!$F:$F,'DB Costi-Ore YtD'!$A:$A,L$1,'DB Costi-Ore YtD'!$B:$B,$A9,'DB Costi-Ore YtD'!$E:$E,$C9)-SUM($D9:K9),0) -> 0 | ... O9: =IF((O$1*1)<=MAX('DB Costi-Ore YtD'!$A:$A),SUMIFS('DB Costi-Ore YtD'!$F:$F,'DB Costi-Ore YtD'!$A:$A,O$1,'DB Costi-Ore YtD'!$B:$B,$A9,'DB Costi-Ore YtD'!$E:$E,$C9)-SUM($D9:N9),0) -> 0
A10: 420 | B10: LUCACI ANGELICA | C10: P02 - QC- STIRO - PACK | D10: =IF((D$1*1)<=MAX('DB Costi-Ore YtD'!$A:$A),SUMIFS('DB Costi-Ore YtD'!$F:$F,'DB Costi-Ore YtD'!$A:$A,D$1,'DB Costi-Ore YtD'!$B:$B,$A10,'DB Costi-Ore YtD'!$E:$E,$C10),0) -> 159 | E10: =IF((E$1*1)<=MAX('DB Costi-Ore YtD'!$A:$A),SUMIFS('DB Costi-Ore YtD'!$F:$F,'DB Costi-Ore YtD'!$A:$A,E$1,'DB Costi-Ore YtD'!$B:$B,$A10,'DB Costi-Ore YtD'!$E:$E,$C10)-SUM($D10:D10),0) -> 138.25 | F10: =IF((F$1*1)<=MAX('DB Costi-Ore YtD'!$A:$A),SUMIFS('DB Costi-Ore YtD'!$F:$F,'DB Costi-Ore YtD'!$A:$A,F$1,'DB Costi-Ore YtD'!$B:$B,$A10,'DB Costi-Ore YtD'!$E:$E,$C10)-SUM($D10:E10),0) -> 152.5 | G10: =IF((G$1*1)<=MAX('DB Costi-Ore YtD'!$A:$A),SUMIFS('DB Costi-Ore YtD'!$F:$F,'DB Costi-Ore YtD'!$A:$A,G$1,'DB Costi-Ore YtD'!$B:$B,$A10,'DB Costi-Ore YtD'!$E:$E,$C10)-SUM($D10:F10),0) -> 148 | H10: =IF((H$1*1)<=MAX('DB Costi-Ore YtD'!$A:$A),SUMIFS('DB Costi-Ore YtD'!$F:$F,'DB Costi-Ore YtD'!$A:$A,H$1,'DB Costi-Ore YtD'!$B:$B,$A10,'DB Costi-Ore YtD'!$E:$E,$C10)-SUM($D10:G10),0) -> 140 | I10: =IF((I$1*1)<=MAX('DB Costi-Ore YtD'!$A:$A),SUMIFS('DB Costi-Ore YtD'!$F:$F,'DB Costi-Ore YtD'!$A:$A,I$1,'DB Costi-Ore YtD'!$B:$B,$A10,'DB Costi-Ore YtD'!$E:$E,$C10)-SUM($D10:H10),0) -> 60 | J10: =IF((J$1*1)<=MAX('DB Costi-Ore YtD'!$A:$A),SUMIFS('DB Costi-Ore YtD'!$F:$F,'DB Costi-Ore YtD'!$A:$A,J$1,'DB Costi-Ore YtD'!$B:$B,$A10,'DB Costi-Ore YtD'!$E:$E,$C10)-SUM($D10:I10),0) -> 0 | K10: =IF((K$1*1)<=MAX('DB Costi-Ore YtD'!$A:$A),SUMIFS('DB Costi-Ore YtD'!$F:$F,'DB Costi-Ore YtD'!$A:$A,K$1,'DB Costi-Ore YtD'!$B:$B,$A10,'DB Costi-Ore YtD'!$E:$E,$C10)-SUM($D10:J10),0) -> 0 | L10: =IF((L$1*1)<=MAX('DB Costi-Ore YtD'!$A:$A),SUMIFS('DB Costi-Ore YtD'!$F:$F,'DB Costi-Ore YtD'!$A:$A,L$1,'DB Costi-Ore YtD'!$B:$B,$A10,'DB Costi-Ore YtD'!$E:$E,$C10)-SUM($D10:K10),0) -> 0 | ... O10: =IF((O$1*1)<=MAX('DB Costi-Ore YtD'!$A:$A),SUMIFS('DB Costi-Ore YtD'!$F:$F,'DB Costi-Ore YtD'!$A:$A,O$1,'DB Costi-Ore YtD'!$B:$B,$A10,'DB Costi-Ore YtD'!$E:$E,$C10)-SUM($D10:N10),0) -> 0
A11: 310 | B11: ALDEGHERI MARA | C11: P05 - PROTOTIPIA PDT | D11: =IF((D$1*1)<=MAX('DB Costi-Ore YtD'!$A:$A),SUMIFS('DB Costi-Ore YtD'!$F:$F,'DB Costi-Ore YtD'!$A:$A,D$1,'DB Costi-Ore YtD'!$B:$B,$A11,'DB Costi-Ore YtD'!$E:$E,$C11),0) -> 91.25 | E11: =IF((E$1*1)<=MAX('DB Costi-Ore YtD'!$A:$A),SUMIFS('DB Costi-Ore YtD'!$F:$F,'DB Costi-Ore YtD'!$A:$A,E$1,'DB Costi-Ore YtD'!$B:$B,$A11,'DB Costi-Ore YtD'!$E:$E,$C11)-SUM($D11:D11),0) -> 134 | F11: =IF((F$1*1)<=MAX('DB Costi-Ore YtD'!$A:$A),SUMIFS('DB Costi-Ore YtD'!$F:$F,'DB Costi-Ore YtD'!$A:$A,F$1,'DB Costi-Ore YtD'!$B:$B,$A11,'DB Costi-Ore YtD'!$E:$E,$C11)-SUM($D11:E11),0) -> 142 | G11: =IF((G$1*1)<=MAX('DB Costi-Ore YtD'!$A:$A),SUMIFS('DB Costi-Ore YtD'!$F:$F,'DB Costi-Ore YtD'!$A:$A,G$1,'DB Costi-Ore YtD'!$B:$B,$A11,'DB Costi-Ore YtD'!$E:$E,$C11)-SUM($D11:F11),0) -> 128.5 | H11: =IF((H$1*1)<=MAX('DB Costi-Ore YtD'!$A:$A),SUMIFS('DB Costi-Ore YtD'!$F:$F,'DB Costi-Ore YtD'!$A:$A,H$1,'DB Costi-Ore YtD'!$B:$B,$A11,'DB Costi-Ore YtD'!$E:$E,$C11)-SUM($D11:G11),0) -> 126.5 | I11: =IF((I$1*1)<=MAX('DB Costi-Ore YtD'!$A:$A),SUMIFS('DB Costi-Ore YtD'!$F:$F,'DB Costi-Ore YtD'!$A:$A,I$1,'DB Costi-Ore YtD'!$B:$B,$A11,'DB Costi-Ore YtD'!$E:$E,$C11)-SUM($D11:H11),0) -> 83 | J11: =IF((J$1*1)<=MAX('DB Costi-Ore YtD'!$A:$A),SUMIFS('DB Costi-Ore YtD'!$F:$F,'DB Costi-Ore YtD'!$A:$A,J$1,'DB Costi-Ore YtD'!$B:$B,$A11,'DB Costi-Ore YtD'!$E:$E,$C11)-SUM($D11:I11),0) -> 0 | K11: =IF((K$1*1)<=MAX('DB Costi-Ore YtD'!$A:$A),SUMIFS('DB Costi-Ore YtD'!$F:$F,'DB Costi-Ore YtD'!$A:$A,K$1,'DB Costi-Ore YtD'!$B:$B,$A11,'DB Costi-Ore YtD'!$E:$E,$C11)-SUM($D11:J11),0) -> 0 | L11: =IF((L$1*1)<=MAX('DB Costi-Ore YtD'!$A:$A),SUMIFS('DB Costi-Ore YtD'!$F:$F,'DB Costi-Ore YtD'!$A:$A,L$1,'DB Costi-Ore YtD'!$B:$B,$A11,'DB Costi-Ore YtD'!$E:$E,$C11)-SUM($D11:K11),0) -> 0 | ... O11: =IF((O$1*1)<=MAX('DB Costi-Ore YtD'!$A:$A),SUMIFS('DB Costi-Ore YtD'!$F:$F,'DB Costi-Ore YtD'!$A:$A,O$1,'DB Costi-Ore YtD'!$B:$B,$A11,'DB Costi-Ore YtD'!$E:$E,$C11)-SUM($D11:N11),0) -> 0
A12: 640 | B12: DEDAJ EGLANTINA | C12: P05 - PROTOTIPIA PDT | D12: =IF((D$1*1)<=MAX('DB Costi-Ore YtD'!$A:$A),SUMIFS('DB Costi-Ore YtD'!$F:$F,'DB Costi-Ore YtD'!$A:$A,D$1,'DB Costi-Ore YtD'!$B:$B,$A12,'DB Costi-Ore YtD'!$E:$E,$C12),0) -> 127.5 | E12: =IF((E$1*1)<=MAX('DB Costi-Ore YtD'!$A:$A),SUMIFS('DB Costi-Ore YtD'!$F:$F,'DB Costi-Ore YtD'!$A:$A,E$1,'DB Costi-Ore YtD'!$B:$B,$A12,'DB Costi-Ore YtD'!$E:$E,$C12)-SUM($D12:D12),0) -> 150 | F12: =IF((F$1*1)<=MAX('DB Costi-Ore YtD'!$A:$A),SUMIFS('DB Costi-Ore YtD'!$F:$F,'DB Costi-Ore YtD'!$A:$A,F$1,'DB Costi-Ore YtD'!$B:$B,$A12,'DB Costi-Ore YtD'!$E:$E,$C12)-SUM($D12:E12),0) -> 148 | G12: =IF((G$1*1)<=MAX('DB Costi-Ore YtD'!$A:$A),SUMIFS('DB Costi-Ore YtD'!$F:$F,'DB Costi-Ore YtD'!$A:$A,G$1,'DB Costi-Ore YtD'!$B:$B,$A12,'DB Costi-Ore YtD'!$E:$E,$C12)-SUM($D12:F12),0) -> 121 | H12: =IF((H$1*1)<=MAX('DB Costi-Ore YtD'!$A:$A),SUMIFS('DB Costi-Ore YtD'!$F:$F,'DB Costi-Ore YtD'!$A:$A,H$1,'DB Costi-Ore YtD'!$B:$B,$A12,'DB Costi-Ore YtD'!$E:$E,$C12)-SUM($D12:G12),0) -> 134 | I12: =IF((I$1*1)<=MAX('DB Costi-Ore YtD'!$A:$A),SUMIFS('DB Costi-Ore YtD'!$F:$F,'DB Costi-Ore YtD'!$A:$A,I$1,'DB Costi-Ore YtD'!$B:$B,$A12,'DB Costi-Ore YtD'!$E:$E,$C12)-SUM($D12:H12),0) -> 151 | J12: =IF((J$1*1)<=MAX('DB Costi-Ore YtD'!$A:$A),SUMIFS('DB Costi-Ore YtD'!$F:$F,'DB Costi-Ore YtD'!$A:$A,J$1,'DB Costi-Ore YtD'!$B:$B,$A12,'DB Costi-Ore YtD'!$E:$E,$C12)-SUM($D12:I12),0) -> 0 | K12: =IF((K$1*1)<=MAX('DB Costi-Ore YtD'!$A:$A),SUMIFS('DB Costi-Ore YtD'!$F:$F,'DB Costi-Ore YtD'!$A:$A,K$1,'DB Costi-Ore YtD'!$B:$B,$A12,'DB Costi-Ore YtD'!$E:$E,$C12)-SUM($D12:J12),0) -> 0 | L12: =IF((L$1*1)<=MAX('DB Costi-Ore YtD'!$A:$A),SUMIFS('DB Costi-Ore YtD'!$F:$F,'DB Costi-Ore YtD'!$A:$A,L$1,'DB Costi-Ore YtD'!$B:$B,$A12,'DB Costi-Ore YtD'!$E:$E,$C12)-SUM($D12:K12),0) -> 0 | ... O12: =IF((O$1*1)<=MAX('DB Costi-Ore YtD'!$A:$A),SUMIFS('DB Costi-Ore YtD'!$F:$F,'DB Costi-Ore YtD'!$A:$A,O$1,'DB Costi-Ore YtD'!$B:$B,$A12,'DB Costi-Ore YtD'!$E:$E,$C12)-SUM($D12:N12),0) -> 0
