Workbook
Name _aliq_irap: [1]Tax!$D$61
Name _aliq_ires: [1]Tax!$D$60
Name _capitale_iniziale: #REF!
Name _company: [2]COVER!$B$3
Name _data_fin: #REF!
Name _data_inizio: #REF!
Name _durata_anni: #REF!
Name _inflazione: [3]cover!$B$11
Name _inflazione_mese: '[1]3.sensitivity'!$D$10
Name _intervallo_mese: #REF!
Name _newbond: [1]cover!$E$37
Name _num_rate: #REF!
Name _periodicita: #REF!
Name _rata: #REF!
Name _Scala: [2]COVER!$B$4
Name _spese_extra: #REF!
Name _tab_periodi: #REF!
Name _tablePU: [1]PU!$A$1:$B$18
Name _tasso_annuale: #REF!
Name _tasso_mutuo: #REF!
Name _tasso_VAN: #REF!
Name _tipo_periodo: #REF!
Name Altezza: #REF!
Name ArticoloFornitore: #REF!
Name CampoEX: #REF!
Name CampoEx1: #REF!
Name CampoEx2: #REF!
Name Codice: #REF!
Name ColFornitore1: #REF!
Name ColFornitore10: #REF!
Name ColFornitore11: #REF!
Name ColFornitore12: #REF!
Name ColFornitore13: #REF!
Name ColFornitore14: #REF!
Name ColFornitore15: #REF!
Name ColFornitore16: #REF!
Name ColFornitore17: #REF!
Name ColFornitore18: #REF!
Name ColFornitore19: #REF!
Name ColFornitore2: #REF!
Name ColFornitore20: #REF!
Name ColFornitore3: #REF!
Name ColFornitore4: #REF!
Name ColFornitore5: #REF!
Name ColFornitore6: #REF!
Name ColFornitore7: #REF!
Name ColFornitore8: #REF!
Name ColFornitore9: #REF!
Name Colore1: #REF!
Name Colore10: #REF!
Name Colore11: #REF!
Name Colore12: #REF!
Name Colore13: #REF!
Name Colore14: #REF!
Name Colore15: #REF!
Name Colore16: #REF!
Name Colore17: #REF!
Name Colore18: #REF!
Name Colore19: #REF!
Name Colore2: #REF!

Sheet INDICE
A2: Mese di Analisi | B2: 45838
A6: Ripartizione Manodopera Diretta
A7: Manodopera diretta di produzione | B7: PERDI | C7: 0.7
A8: Costi del personale diretto improduttivo | B8: PERIM | C8: 0.3

Sheet FOGLI PER REPORT -->

Sheet Grafici
A1: SEZIONE 1
A77: SEZIONE 2
K96: Breakdown MdC | L96: Act 12.2020 | M96: Act 12.2021 | N96: Act 12.2022 | O96: Act 12.2023 | P96: Act 12.2024 | Q96: Fct 12.2025
K97: Ricavi Totali | L97: =DB_Grafici!B64 -> 13187.454 | M97: =DB_Grafici!C64 -> 6668.3968 | N97: =DB_Grafici!D64 -> 5925.2624 | O97: =DB_Grafici!E64 -> 6006.0651 | P97: =DB_Grafici!F64 -> 7209.174 | Q97: =DB_Grafici!G64 -> 7625.0438
K98: Costi Variabili | L98: =SUM(CE_Sintetico!J9:J11)*-1 -> 8423.951 | M98: =SUM(CE_Sintetico!K9:K11)*-1 -> 3558.3326 | N98: =SUM(CE_Sintetico!L9:L11)*-1 -> 2105.6039 | O98: =SUM(CE_Sintetico!M9:M11)*-1 -> 3589.3427 | P98: =SUM(CE_Sintetico!N9:N11)*-1 -> 2635.8387 | Q98: =+SUM(CE_Esteso!K8:K11)*-1 -> 3311.4536
K99: di cui Consumi MP/SL | L99: =CE_Sintetico!J9 -> -1825.4343 | M99: =CE_Sintetico!K9 -> -1182.6431 | N99: =CE_Sintetico!L9 -> -340.13104 | O99: =CE_Sintetico!M9 -> -1092.4301 | P99: =CE_Sintetico!N9 -> -527.36397 | Q99: =+SUM(CE_Esteso!K8:K9) -> -633.54427
K100: di cui Lavorazioni Esterne | L100: =CE_Sintetico!J10 -> -4793.8641 | M100: =CE_Sintetico!K10 -> -458.0877 | N100: =CE_Sintetico!L10 -> -890.82406 | O100: =CE_Sintetico!M10 -> -1345.237 | P100: =CE_Sintetico!N10 -> -839.90733 | Q100: =+CE_Esteso!K10 -> -1102.4473
K101: di cui Manodopera Diretta | L101: =CE_Sintetico!J11 -> -1804.6526 | M101: =CE_Sintetico!K11 -> -1917.6018 | N101: =CE_Sintetico!L11 -> -874.64877 | O101: =CE_Sintetico!M11 -> -1151.6756 | P101: =CE_Sintetico!N11 -> -1268.5674 | Q101: =+CE_Esteso!K11 -> -1575.462
K102: Margine di Contribuzione | L102: =L97-L98 -> 4763.5035 | M102: =M97-M98 -> 3110.0641 | N102: =N97-N98 -> 3819.6586 | O102: =O97-O98 -> 2416.7225 | P102: =P97-P98 -> 4573.3352 | Q102: =Q97-Q98 -> 4313.5902
K103: MdC (%) | L103: =L102/L97 -> 0.36121478 | M103: =M102/M97 -> 0.46638858 | N103: =N102/N97 -> 0.64463956 | O103: =O102/O97 -> 0.40238033 | P103: =P102/P97 -> 0.63437715 | Q103: =Q102/Q97 -> 0.5657135
K115: Composizione Ricavi Commerciali | L115: ="Bdg 0"&MONTH(INDICE!$B$2)&"."&YEAR(INDICE!$B$2) -> Bdg 06.2025 | M115: ="Act 0"&MONTH(INDICE!$B$2)&"."&YEAR(INDICE!$B$2) -> Act 06.2025 | N115: Scostam. | O115: Scost (%)
J116: 07011200 | K116: =PROPER(LOWER(INDEX(Mappatura_PdC!C:C,MATCH(J116,Mappatura_PdC!B:B,0)))) -> Incassi Per Corrispettivi | L116: =-SUMIFS(DB_Complessivo!$E:$E,DB_Complessivo!$A:$A,"BDG",DB_Complessivo!$C:$C,$J116,DB_Complessivo!$B:$B,INDICE!$B$2)/1000 -> 96 | M116: =-SUMIFS(DB_Complessivo!$E:$E,DB_Complessivo!$A:$A,"ACT",DB_Complessivo!$C:$C,$J116,DB_Complessivo!$B:$B,INDICE!$B$2)/1000 -> 145.43466 | N116: =M116-L116 -> 49.43466 | O116: =IFERROR(N116/L116,"") -> 0.51494438
K117: Ricavi Netti di Vendita | L117: =+SUM(L118:L126) -> 3116 | M117: =+SUM(M118:M126) -> 3278.7257 | N117: =M117-L117 -> 162.72568 | O117: =IFERROR(N117/L117,"") -> 0.052222619
J118: 07011001 | K118: ="Di cui "&PROPER(LOWER(INDEX(Mappatura_PdC!C:C,MATCH(J118,Mappatura_PdC!B:B,0)))) -> Di cui Vendite B2B | L118: =-SUMIFS(DB_Complessivo!$E:$E,DB_Complessivo!$A:$A,"BDG",DB_Complessivo!$C:$C,$J118,DB_Complessivo!$B:$B,INDICE!$B$2)/1000 -> 3016 | M118: =-SUMIFS(DB_Complessivo!$E:$E,DB_Complessivo!$A:$A,"ACT",DB_Complessivo!$C:$C,$J118,DB_Complessivo!$B:$B,INDICE!$B$2)/1000 -> 3060.2934 | N118: =M118-L118 -> 44.29339 | O118: =IFERROR(N118/L118,"") -> 0.014686137
J119: 07011003 | K119: ="Di cui "&PROPER(LOWER(INDEX(Mappatura_PdC!C:C,MATCH(J119,Mappatura_PdC!B:B,0)))) -> Di cui Vendite Botteghe Altromercato | L119: =-SUMIFS(DB_Complessivo!$E:$E,DB_Complessivo!$A:$A,"BDG",DB_Complessivo!$C:$C,$J119,DB_Complessivo!$B:$B,INDICE!$B$2)/1000 -> 0 | M119: =-SUMIFS(DB_Complessivo!$E:$E,DB_Complessivo!$A:$A,"ACT",DB_Complessivo!$C:$C,$J119,DB_Complessivo!$B:$B,INDICE!$B$2)/1000 -> -1.03832 | N119: =M119-L119 -> -1.03832 | O119: =IFERROR(N119/L119,"")
J120: 07011004 | K120: ="Di cui "&PROPER(LOWER(INDEX(Mappatura_PdC!C:C,MATCH(J120,Mappatura_PdC!B:B,0)))) -> Di cui Ricavi Delle Vendite Altri | L120: =-SUMIFS(DB_Complessivo!$E:$E,DB_Complessivo!$A:$A,"BDG",DB_Complessivo!$C:$C,$J120,DB_Complessivo!$B:$B,INDICE!$B$2)/1000 -> 0 | M120: =-SUMIFS(DB_Complessivo!$E:$E,DB_Complessivo!$A:$A,"ACT",DB_Complessivo!$C:$C,$J120,DB_Complessivo!$B:$B,INDICE!$B$2)/1000 -> 2.40877 | N120: =M120-L120 -> 2.40877 | O120: =IFERROR(N120/L120,"")
J121: 07011007 | K121: ="Di cui "&PROPER(LOWER(INDEX(Mappatura_PdC!C:C,MATCH(J121,Mappatura_PdC!B:B,0)))) -> Di cui Vendita Tessuti | L121: =-SUMIFS(DB_Complessivo!$E:$E,DB_Complessivo!$A:$A,"BDG",DB_Complessivo!$C:$C,$J121,DB_Complessivo!$B:$B,INDICE!$B$2)/1000 -> 0 | M121: =-SUMIFS(DB_Complessivo!$E:$E,DB_Complessivo!$A:$A,"ACT",DB_Complessivo!$C:$C,$J121,DB_Complessivo!$B:$B,INDICE!$B$2)/1000 -> 2.0568 | N121: =M121-L121 -> 2.0568 | O121: =IFERROR(N121/L121,"")
J122: 07011008 | K122: ="Di cui "&PROPER(LOWER(INDEX(Mappatura_PdC!C:C,MATCH(J122,Mappatura_PdC!B:B,0)))) -> Di cui Servizi B2B | L122: =-SUMIFS(DB_Complessivo!$E:$E,DB_Complessivo!$A:$A,"BDG",DB_Complessivo!$C:$C,$J122,DB_Complessivo!$B:$B,INDICE!$B$2)/1000 -> 0 | M122: =-SUMIFS(DB_Complessivo!$E:$E,DB_Complessivo!$A:$A,"ACT",DB_Complessivo!$C:$C,$J122,DB_Complessivo!$B:$B,INDICE!$B$2)/1000 -> 12.006 | N122: =M122-L122 -> 12.006 | O122: =IFERROR(N122/L122,"")
J123: 07011009 | K123: ="Di cui "&PROPER(LOWER(INDEX(Mappatura_PdC!C:C,MATCH(J123,Mappatura_PdC!B:B,0)))) -> Di cui Ricavi Da Eventi Istituzionali | L123: =-SUMIFS(DB_Complessivo!$E:$E,DB_Complessivo!$A:$A,"BDG",DB_Complessivo!$C:$C,$J123,DB_Complessivo!$B:$B,INDICE!$B$2)/1000 -> 95 | M123: =-SUMIFS(DB_Complessivo!$E:$E,DB_Complessivo!$A:$A,"ACT",DB_Complessivo!$C:$C,$J123,DB_Complessivo!$B:$B,INDICE!$B$2)/1000 -> 59.7512 | N123: =M123-L123 -> -35.2488 | O123: =IFERROR(N123/L123,"") -> -0.37104
J124: 07011100 | K124: ="Di cui "&PROPER(LOWER(INDEX(Mappatura_PdC!C:C,MATCH(J124,Mappatura_PdC!B:B,0)))) -> Di cui Ricavi Da Prestazione Servizi | L124: =-SUMIFS(DB_Complessivo!$E:$E,DB_Complessivo!$A:$A,"BDG",DB_Complessivo!$C:$C,$J124,DB_Complessivo!$B:$B,INDICE!$B$2)/1000 -> 5 | M124: =-SUMIFS(DB_Complessivo!$E:$E,DB_Complessivo!$A:$A,"ACT",DB_Complessivo!$C:$C,$J124,DB_Complessivo!$B:$B,INDICE!$B$2)/1000 -> 0 | N124: =M124-L124 -> -5 | O124: =IFERROR(N124/L124,"") -> -1
J125: 07011101 | K125: ="Di cui "&PROPER(LOWER(INDEX(Mappatura_PdC!C:C,MATCH(J125,Mappatura_PdC!B:B,0)))) -> Di cui Prestazioni Di Servizi Yeah | L125: =-SUMIFS(DB_Complessivo!$E:$E,DB_Complessivo!$A:$A,"BDG",DB_Complessivo!$C:$C,$J125,DB_Complessivo!$B:$B,INDICE!$B$2)/1000 -> 0 | M125: =-SUMIFS(DB_Complessivo!$E:$E,DB_Complessivo!$A:$A,"ACT",DB_Complessivo!$C:$C,$J125,DB_Complessivo!$B:$B,INDICE!$B$2)/1000 -> 143.962 | N125: =M125-L125 -> 143.962 | O125: =IFERROR(N125/L125,"")
J126: 07051004 | K126: ="Di cui "&PROPER(LOWER(INDEX(Mappatura_PdC!C:C,MATCH(J126,Mappatura_PdC!B:B,0)))) -> Di cui Resi Su Vendite | L126: =-SUMIFS(DB_Complessivo!$E:$E,DB_Complessivo!$A:$A,"BDG",DB_Complessivo!$C:$C,$J126,DB_Complessivo!$B:$B,INDICE!$B$2)/1000 -> 0 | M126: =-SUMIFS(DB_Complessivo!$E:$E,DB_Complessivo!$A:$A,"ACT",DB_Complessivo!$C:$C,$J126,DB_Complessivo!$B:$B,INDICE!$B$2)/1000 -> -0.71416 | N126: =M126-L126 -> -0.71416 | O126: =IFERROR(N126/L126,"")
A147: SEZIONE 3
A203: SEZIONE 4
A236: GRAFICO FATTURATO

Sheet DB_Grafici
A1: SEZIONE 1
B3: ="Act 0"&MONTH(INDICE!$B$2)&"."&YEAR(INDICE!$B$2) -> Act 06.2025 | C3: ="Bdg 0"&MONTH(INDICE!$B$2)&"."&YEAR(INDICE!$B$2) -> Bdg 06.2025
A4: Ricavi | B4: =CE_Esteso!G7 -> 3842.6868 | C4: =+CE_Esteso!F7 -> 3543.5453
A5: MdC | B5: =+CE_Esteso!G12 -> 2178.0042 | C5: =+CE_Esteso!F12 -> 1876.9617
A6: Ebitda | B6: =+CE_Esteso!G27-SUM(CE_Esteso!G18,CE_Esteso!G25:G26) -> 93.7272 | C6: =+CE_Esteso!F27-SUM(CE_Esteso!F18,CE_Esteso!F25:F26) -> 30.758895
A7: Ebit | B7: =+CE_Esteso!G27 -> 26.51475 | C7: =+CE_Esteso!F27 -> -36.453645
B10: ="Act 0"&MONTH(INDICE!$B$2)&"."&YEAR(INDICE!B2)-1 -> Act 06.2024 | C10: ="Act 0"&MONTH(INDICE!$B$2)&"."&YEAR(INDICE!B2) -> Act 06.2025 | D10: ="Bdg 0"&MONTH(INDICE!$B$2)&"."&YEAR(INDICE!B2) -> Bdg 06.2025
A11: Ricavi | B11: =CE_Esteso!$D$7 -> 3718.5335 | C11: =CE_Esteso!$G$7 -> 3842.6868 | D11: =CE_Esteso!$F$7 -> 3543.5453
A12: MdC | B12: =+CE_Esteso!$D$12 -> 2711.8762 | C12: =+CE_Esteso!$G$12 -> 2178.0042 | D12: =+CE_Esteso!$F$12 -> 1876.9617
A13: Ebitda | B13: =+CE_Esteso!$D$27-SUM(CE_Esteso!$D$18,CE_Esteso!$D$25:$D$26) -> 957.31622 | C13: =+CE_Esteso!$G$27-SUM(CE_Esteso!$G$18,CE_Esteso!$G$25:$G$26) -> 93.7272 | D13: =+CE_Esteso!$F$27-SUM(CE_Esteso!$F$18,CE_Esteso!$F$25:$F$26) -> 30.758895
A14: Ebit | B14: =+CE_Esteso!$D$27 -> 901.13017 | C14: =+CE_Esteso!$G$27 -> 26.51475 | D14: =+CE_Esteso!$F$27 -> -36.453645
A16: Conto | B16: Descr. Conto | C16: Ricl | D16: Saldo | F16: Componenti Positive PFN
A17: 00031302 | B17: PARTECIPAZIONE IN BANCA POPOLARE DI SONDRIO | C17: C | D17: =SUMIFS(DB_Complessivo!E:E,DB_Complessivo!B:B,INDICE!$B$2,DB_Complessivo!C:C,$A17,DB_Complessivo!A:A,"ACT") -> 340 | F17: D | G17: Liquidità | H17: =SUMIFS($D$17:$D$43,$C$17:$C$43,$F17)/1000 -> 1102.995
A18: 00031303 | B18: PARTECIPAZIONE IN CGM FINANCE | C18: C | D18: =SUMIFS(DB_Complessivo!E:E,DB_Complessivo!B:B,INDICE!$B$2,DB_Complessivo!C:C,$A18,DB_Complessivo!A:A,"ACT") -> 2500 | F18: A | G18: Deposito CGM | H18: =SUMIFS($D$17:$D$43,$C$17:$C$43,$F18)/1000 -> 1898.8734
A19: 00031304 | B19: PARTECIPAZIONE IN COOPERFIDI ITALIA | C19: C | D19: =SUMIFS(DB_Complessivo!E:E,DB_Complessivo!B:B,INDICE!$B$2,DB_Complessivo!C:C,$A19,DB_Complessivo!A:A,"ACT") -> 250 | F19: B | G19: Polizze | H19: =SUMIFS($D$17:$D$43,$C$17:$C$43,$F19)/1000 -> 1055.0231
A20: 00032300 | B20: CREDITI VERSO ALTRI - POLIZZA ASSIC. INTESA | C20: B | D20: =SUMIFS(DB_Complessivo!E:E,DB_Complessivo!B:B,INDICE!$B$2,DB_Complessivo!C:C,$A20,DB_Complessivo!A:A,"ACT") -> 997500 | F20: C | G20: Altre Imm. Finanz. | H20: =SUMIFS($D$17:$D$43,$C$17:$C$43,$F20)/1000 -> 63.78852
A21: 00032301 | B21: CREDITI VERSO ALTRI - INT.POLIZZA ASS. INTESA | C21: B | D21: =SUMIFS(DB_Complessivo!E:E,DB_Complessivo!B:B,INDICE!$B$2,DB_Complessivo!C:C,$A21,DB_Complessivo!A:A,"ACT") -> 57523.07
A22: 00035000 | B22: STRUMENTI FINANZIARI DERIVATI ATTIVI | C22: C | D22: =SUMIFS(DB_Complessivo!E:E,DB_Complessivo!B:B,INDICE!$B$2,DB_Complessivo!C:C,$A22,DB_Complessivo!A:A,"ACT") -> 60698.52
A23: 02011001 | B23: CASSA | C23: D | D23: =SUMIFS(DB_Complessivo!E:E,DB_Complessivo!B:B,INDICE!$B$2,DB_Complessivo!C:C,$A23,DB_Complessivo!A:A,"ACT") -> 7314.83
A24: 02011002 | B24: CASSA CORRISPETTIVI | C24: D | D24: =SUMIFS(DB_Complessivo!E:E,DB_Complessivo!B:B,INDICE!$B$2,DB_Complessivo!C:C,$A24,DB_Complessivo!A:A,"ACT") -> 24179.808
A25: 02011003 | B25: CASSA NEGOZI | C25: D | D25: =SUMIFS(DB_Complessivo!E:E,DB_Complessivo!B:B,INDICE!$B$2,DB_Complessivo!C:C,$A25,DB_Complessivo!A:A,"ACT") -> 2408.05
A26: 02011004 | B26: CARTA PREPAGATA 5088 MAESTRELLO | C26: D | D26: =SUMIFS(DB_Complessivo!E:E,DB_Complessivo!B:B,INDICE!$B$2,DB_Complessivo!C:C,$A26,DB_Complessivo!A:A,"ACT") -> 1951.57
A27: 02011005 | B27: CARTA PREPAGATA 5062 CROIN | C27: D | D27: =SUMIFS(DB_Complessivo!E:E,DB_Complessivo!B:B,INDICE!$B$2,DB_Complessivo!C:C,$A27,DB_Complessivo!A:A,"ACT") -> 0
A28: 02020001 | B28: UNICREDIT C/C | C28: D | D28: =SUMIFS(DB_Complessivo!E:E,DB_Complessivo!B:B,INDICE!$B$2,DB_Complessivo!C:C,$A28,DB_Complessivo!A:A,"ACT") -> 334360.54
A29: 02020002 | B29: BANCA POP. SONDRIO C/C | C29: D | D29: =SUMIFS(DB_Complessivo!E:E,DB_Complessivo!B:B,INDICE!$B$2,DB_Complessivo!C:C,$A29,DB_Complessivo!A:A,"ACT") -> 158.54
A30: 02020005 | B30: CREVAL C/C | C30: D | D30: =SUMIFS(DB_Complessivo!E:E,DB_Complessivo!B:B,INDICE!$B$2,DB_Complessivo!C:C,$A30,DB_Complessivo!A:A,"ACT") -> 0
A31: 02020006 | B31: BPM C/C | C31: D | D31: =SUMIFS(DB_Complessivo!E:E,DB_Complessivo!B:B,INDICE!$B$2,DB_Complessivo!C:C,$A31,DB_Complessivo!A:A,"ACT") -> 35631.34
A32: 02020007 | B32: BANCA POP. SONDRIO YEAH C/C | C32: D | D32: =SUMIFS(DB_Complessivo!E:E,DB_Complessivo!B:B,INDICE!$B$2,DB_Complessivo!C:C,$A32,DB_Complessivo!A:A,"ACT") -> 225538.55
... A43: 02020031 | B43: DEPOSITO 2115 CGM FINANCE | C43: A | D43: =SUMIFS(DB_Complessivo!E:E,DB_Complessivo!B:B,INDICE!$B$2,DB_Complessivo!C:C,$A43,DB_Complessivo!A:A,"ACT") -> 898810
A45: Conto | B45: Descr. Conto | C45: Saldo
A46: 05011206 | B46: UBI Ponte | C46: =-SUMIFS(DB_Complessivo!E:E,DB_Complessivo!B:B,INDICE!$B$2,DB_Complessivo!C:C,$A46,DB_Complessivo!A:A,"ACT")/1000 -> 135.17967 | G46: Componenti Positive PFN | H46: =SUM(H17:H20) -> 4120.68
A47: 05011210 | B47: Credit Agricole | C47: =-SUMIFS(DB_Complessivo!E:E,DB_Complessivo!B:B,INDICE!$B$2,DB_Complessivo!C:C,$A47,DB_Complessivo!A:A,"ACT")/1000 -> 201.99893 | G47: Componenti Negative PFN | H47: =SUM(C46:C52) -> 2062.2307
A48: 05011212 | B48: UBI B/76180/1 | C48: =-SUMIFS(DB_Complessivo!E:E,DB_Complessivo!B:B,INDICE!$B$2,DB_Complessivo!C:C,$A48,DB_Complessivo!A:A,"ACT")/1000 -> 158.61724
A49: 05011213 | B49: BPM 04878755 | C49: =-SUMIFS(DB_Complessivo!E:E,DB_Complessivo!B:B,INDICE!$B$2,DB_Complessivo!C:C,$A49,DB_Complessivo!A:A,"ACT")/1000 -> 29.2961 | H49: =SUM(M16:M53) -> 0
A50: 05011216 | B50: UBI 76180/00 | C50: =-SUMIFS(DB_Complessivo!E:E,DB_Complessivo!B:B,INDICE!$B$2,DB_Complessivo!C:C,$A50,DB_Complessivo!A:A,"ACT")/1000 -> 101.70099 | H50: =+(H46-H47)*1000 -> 2058449.3
A51: 05011217 | B51: UNICREDIT 8931002 | C51: =-SUMIFS(DB_Complessivo!E:E,DB_Complessivo!B:B,INDICE!$B$2,DB_Complessivo!C:C,$A51,DB_Complessivo!A:A,"ACT")/1000 -> 1419.6158 | H51: =+H49-H50 -> -2058449.3
A52: 05011304 | B52: SIMEST 51339/EC/FP | C52: =-SUMIFS(DB_Complessivo!E:E,DB_Complessivo!B:B,INDICE!$B$2,DB_Complessivo!C:C,$A52,DB_Complessivo!A:A,"ACT")/1000 -> 15.822
A56: SEZIONE 2
B59: ="Act 0"&MONTH(INDICE!$B$2)&"."&YEAR(INDICE!$B$2)-1 -> Act 06.2024 | C59: ="Bdg 0"&MONTH(INDICE!$B$2)&"."&YEAR(INDICE!$B$2) -> Bdg 06.2025 | D59: ="Act 0"&MONTH(INDICE!$B$2)&"."&YEAR(INDICE!$B$2) -> Act 06.2025
A60: Ricavi | B60: =CE_Sintetico!D8 -> 3718.5335 | C60: =CE_Sintetico!E8 -> 3543.5453 | D60: =CE_Sintetico!F8 -> 3842.6868
...

Sheet CE_Sintetico
C2: Conto Economico "Sintetico" | D2: PY | E2: REV_BDG | F2: ACT
C3: EUR/000 | D3: =EOMONTH(INDICE!B2,-12) -> 45473 | E3: =EOMONTH(INDICE!B2,0) -> 45838 | F3: =EOMONTH(INDICE!B2,0) -> 45838 | J3: 44196 | K3: 44561 | L3: 44926 | M3: 45291 | N3: 45657
A4: RIC | C4: Ricavi Netti di Vendita | D4: =-SUMIFS(DB_Complessivo!$E:$E,DB_Complessivo!$A:$A,"ACT",DB_Complessivo!$J:$J,$A4,DB_Complessivo!$B:$B,D$3)/1000 -> 3007.6994 | E4: =-SUMIFS(DB_Complessivo!$E:$E,DB_Complessivo!$A:$A,$E$2,DB_Complessivo!$J:$J,$A4,DB_Complessivo!$B:$B,E$3)/1000 -> 3057.6796 | F4: =-SUMIFS(DB_Complessivo!$E:$E,DB_Complessivo!$A:$A,"ACT",DB_Complessivo!$J:$J,$A4,DB_Complessivo!$B:$B,F$3)/1000 -> 3134.7637 | J4: =-SUMIFS(DB_Complessivo!$E:$E,DB_Complessivo!$A:$A,"ACT",DB_Complessivo!$J:$J,$A4,DB_Complessivo!$B:$B,J$3)/1000 -> 7370.1443 | K4: =-SUMIFS(DB_Complessivo!$E:$E,DB_Complessivo!$A:$A,"ACT",DB_Complessivo!$J:$J,$A4,DB_Complessivo!$B:$B,K$3)/1000 -> 3089.6107 | L4: =-SUMIFS(DB_Complessivo!$E:$E,DB_Complessivo!$A:$A,"ACT",DB_Complessivo!$J:$J,$A4,DB_Complessivo!$B:$B,L$3)/1000 -> 4290.7315 | M4: =-SUMIFS(DB_Complessivo!$E:$E,DB_Complessivo!$A:$A,"ACT",DB_Complessivo!$J:$J,$A4,DB_Complessivo!$B:$B,M$3)/1000 -> 3828.3514 | N4: =-SUMIFS(DB_Complessivo!$E:$E,DB_Complessivo!$A:$A,"ACT",DB_Complessivo!$J:$J,$A4,DB_Complessivo!$B:$B,N$3)/1000 -> 5644.8126
A5: CORR | C5: Corrispettivi | D5: =-SUMIFS(DB_Complessivo!$E:$E,DB_Complessivo!$A:$A,"ACT",DB_Complessivo!$J:$J,$A5,DB_Complessivo!$B:$B,D$3)/1000 -> 583.8182 | E5: =-SUMIFS(DB_Complessivo!$E:$E,DB_Complessivo!$A:$A,$E$2,DB_Complessivo!$J:$J,$A5,DB_Complessivo!$B:$B,E$3)/1000 -> 145.36444 | F5: =-SUMIFS(DB_Complessivo!$E:$E,DB_Complessivo!$A:$A,"ACT",DB_Complessivo!$J:$J,$A5,DB_Complessivo!$B:$B,F$3)/1000 -> 145.43466 | J5: =-SUMIFS(DB_Complessivo!$E:$E,DB_Complessivo!$A:$A,"ACT",DB_Complessivo!$J:$J,$A5,DB_Complessivo!$B:$B,J$3)/1000 -> 1321.2355 | K5: =-SUMIFS(DB_Complessivo!$E:$E,DB_Complessivo!$A:$A,"ACT",DB_Complessivo!$J:$J,$A5,DB_Complessivo!$B:$B,K$3)/1000 -> 1480.6083 | L5: =-SUMIFS(DB_Complessivo!$E:$E,DB_Complessivo!$A:$A,"ACT",DB_Complessivo!$J:$J,$A5,DB_Complessivo!$B:$B,L$3)/1000 -> 1720.3795 | M5: =-SUMIFS(DB_Complessivo!$E:$E,DB_Complessivo!$A:$A,"ACT",DB_Complessivo!$J:$J,$A5,DB_Complessivo!$B:$B,M$3)/1000 -> 1701.8199 | N5: =-SUMIFS(DB_Complessivo!$E:$E,DB_Complessivo!$A:$A,"ACT",DB_Complessivo!$J:$J,$A5,DB_Complessivo!$B:$B,N$3)/1000 -> 825.32082
A6: VARPF | C6: Variazione magazzino PF | D6: =-SUMIFS(DB_Complessivo!$E:$E,DB_Complessivo!$A:$A,"ACT",DB_Complessivo!$J:$J,$A6,DB_Complessivo!$B:$B,D$3)/1000 -> -378.34423 | E6: =-SUMIFS(DB_Complessivo!$E:$E,DB_Complessivo!$A:$A,$E$2,DB_Complessivo!$J:$J,$A6,DB_Complessivo!$B:$B,E$3)/1000 -> 50.48681 | F6: =-SUMIFS(DB_Complessivo!$E:$E,DB_Complessivo!$A:$A,"ACT",DB_Complessivo!$J:$J,$A6,DB_Complessivo!$B:$B,F$3)/1000 -> -30.72334 | J6: =-SUMIFS(DB_Complessivo!$E:$E,DB_Complessivo!$A:$A,"ACT",DB_Complessivo!$J:$J,$A6,DB_Complessivo!$B:$B,J$3)/1000 -> 2698.6681 | K6: =-SUMIFS(DB_Complessivo!$E:$E,DB_Complessivo!$A:$A,"ACT",DB_Complessivo!$J:$J,$A6,DB_Complessivo!$B:$B,K$3)/1000 -> -2428.6984 | L6: =-SUMIFS(DB_Complessivo!$E:$E,DB_Complessivo!$A:$A,"ACT",DB_Complessivo!$J:$J,$A6,DB_Complessivo!$B:$B,L$3)/1000 -> -675.3404 | M6: =-SUMIFS(DB_Complessivo!$E:$E,DB_Complessivo!$A:$A,"ACT",DB_Complessivo!$J:$J,$A6,DB_Complessivo!$B:$B,M$3)/1000 -> -56.15042 | N6: =-SUMIFS(DB_Complessivo!$E:$E,DB_Complessivo!$A:$A,"ACT",DB_Complessivo!$J:$J,$A6,DB_Complessivo!$B:$B,N$3)/1000 -> -113.78036
A7: ALTRI | C7: Altri Ricavi | D7: =-SUMIFS(DB_Complessivo!$E:$E,DB_Complessivo!$A:$A,"ACT",DB_Complessivo!$J:$J,$A7,DB_Complessivo!$B:$B,D$3)/1000 -> 505.36009 | E7: =-SUMIFS(DB_Complessivo!$E:$E,DB_Complessivo!$A:$A,$E$2,DB_Complessivo!$J:$J,$A7,DB_Complessivo!$B:$B,E$3)/1000 -> 290.01446 | F7: =-SUMIFS(DB_Complessivo!$E:$E,DB_Complessivo!$A:$A,"ACT",DB_Complessivo!$J:$J,$A7,DB_Complessivo!$B:$B,F$3)/1000 -> 593.21178 | J7: =-SUMIFS(DB_Complessivo!$E:$E,DB_Complessivo!$A:$A,"ACT",DB_Complessivo!$J:$J,$A7,DB_Complessivo!$B:$B,J$3)/1000 -> 1797.4066 | K7: =-SUMIFS(DB_Complessivo!$E:$E,DB_Complessivo!$A:$A,"ACT",DB_Complessivo!$J:$J,$A7,DB_Complessivo!$B:$B,K$3)/1000 -> 4526.8762 | L7: =-SUMIFS(DB_Complessivo!$E:$E,DB_Complessivo!$A:$A,"ACT",DB_Complessivo!$J:$J,$A7,DB_Complessivo!$B:$B,L$3)/1000 -> 589.49188 | M7: =-SUMIFS(DB_Complessivo!$E:$E,DB_Complessivo!$A:$A,"ACT",DB_Complessivo!$J:$J,$A7,DB_Complessivo!$B:$B,M$3)/1000 -> 532.04425 | N7: =-SUMIFS(DB_Complessivo!$E:$E,DB_Complessivo!$A:$A,"ACT",DB_Complessivo!$J:$J,$A7,DB_Complessivo!$B:$B,N$3)/1000 -> 852.82091
C8: Ricavi Tot | D8: =SUM(D4:D7) -> 3718.5335 | E8: =SUM(E4:E7) -> 3543.5453 | F8: =SUM(F4:F7) -> 3842.6868 | J8: =SUM(J4:J7) -> 13187.454 | K8: =SUM(K4:K7) -> 6668.3968 | L8: =SUM(L4:L7) -> 5925.2624 | M8: =SUM(M4:M7) -> 6006.0651 | N8: =SUM(N4:N7) -> 7209.174
A9: ACQ | C9: Consumi | D9: =-SUMIFS(DB_Complessivo!$E:$E,DB_Complessivo!$A:$A,"ACT",DB_Complessivo!$J:$J,$A9,DB_Complessivo!$B:$B,D$3)/1000 -> -8.29416 | E9: =-SUMIFS(DB_Complessivo!$E:$E,DB_Complessivo!$A:$A,$E$2,DB_Complessivo!$J:$J,$A9,DB_Complessivo!$B:$B,E$3)/1000 -> -304.70786 | F9: =-SUMIFS(DB_Complessivo!$E:$E,DB_Complessivo!$A:$A,"ACT",DB_Complessivo!$J:$J,$A9,DB_Complessivo!$B:$B,F$3)/1000 -> -365.43326 | J9: =-SUMIFS(DB_Complessivo!$E:$E,DB_Complessivo!$A:$A,"ACT",DB_Complessivo!$J:$J,$A9,DB_Complessivo!$B:$B,J$3)/1000 -> -1825.4343 | K9: =-SUMIFS(DB_Complessivo!$E:$E,DB_Complessivo!$A:$A,"ACT",DB_Complessivo!$J:$J,$A9,DB_Complessivo!$B:$B,K$3)/1000 -> -1182.6431 | L9: =-SUMIFS(DB_Complessivo!$E:$E,DB_Complessivo!$A:$A,"ACT",DB_Complessivo!$J:$J,$A9,DB_Complessivo!$B:$B,L$3)/1000 -> -340.13104 | M9: =-SUMIFS(DB_Complessivo!$E:$E,DB_Complessivo!$A:$A,"ACT",DB_Complessivo!$J:$J,$A9,DB_Complessivo!$B:$B,M$3)/1000 -> -1092.4301 | N9: =-SUMIFS(DB_Complessivo!$E:$E,DB_Complessivo!$A:$A,"ACT",DB_Complessivo!$J:$J,$A9,DB_Complessivo!$B:$B,N$3)/1000 -> -527.36397
A10: LAV | C10: Lavorazioni esterne | D10: =-SUMIFS(DB_Complessivo!$E:$E,DB_Complessivo!$A:$A,"ACT",DB_Complessivo!$J:$J,$A10,DB_Complessivo!$B:$B,D$3)/1000 -> -354.46345 | E10: =-SUMIFS(DB_Complessivo!$E:$E,DB_Complessivo!$A:$A,$E$2,DB_Complessivo!$J:$J,$A10,DB_Complessivo!$B:$B,E$3)/1000 -> -566.4114 | F10: =-SUMIFS(DB_Complessivo!$E:$E,DB_Complessivo!$A:$A,"ACT",DB_Complessivo!$J:$J,$A10,DB_Complessivo!$B:$B,F$3)/1000 -> -519.22252 | J10: =-SUMIFS(DB_Complessivo!$E:$E,DB_Complessivo!$A:$A,"ACT",DB_Complessivo!$J:$J,$A10,DB_Complessivo!$B:$B,J$3)/1000 -> -4793.8641 | K10: =-SUMIFS(DB_Complessivo!$E:$E,DB_Complessivo!$A:$A,"ACT",DB_Complessivo!$J:$J,$A10,DB_Complessivo!$B:$B,K$3)/1000 -> -458.0877 | L10: =-SUMIFS(DB_Complessivo!$E:$E,DB_Complessivo!$A:$A,"ACT",DB_Complessivo!$J:$J,$A10,DB_Complessivo!$B:$B,L$3)/1000 -> -890.82406 | M10: =-SUMIFS(DB_Complessivo!$E:$E,DB_Complessivo!$A:$A,"ACT",DB_Complessivo!$J:$J,$A10,DB_Complessivo!$B:$B,M$3)/1000 -> -1345.237 | N10: =-SUMIFS(DB_Complessivo!$E:$E,DB_Complessivo!$A:$A,"ACT",DB_Complessivo!$J:$J,$A10,DB_Complessivo!$B:$B,N$3)/1000 -> -839.90733
A11: dir | C11: Costo del personale diretto | D11: =-SUMIFS(DB_Complessivo!$E:$E,DB_Complessivo!$A:$A,"ACT",DB_Complessivo!$J:$J,$A11,DB_Complessivo!$B:$B,D$3)/1000 -> -643.8996 | E11: =-SUMIFS(DB_Complessivo!$E:$E,DB_Complessivo!$A:$A,$E$2,DB_Complessivo!$J:$J,$A11,DB_Complessivo!$B:$B,E$3)/1000*70% -> -556.82503 | F11: =-SUMIFS(DB_Complessivo!$E:$E,DB_Complessivo!$A:$A,"ACT",DB_Complessivo!$J:$J,$A11,DB_Complessivo!$B:$B,F$3)/1000 -> -780.02684 | J11: =-SUMIFS(DB_Complessivo!$E:$E,DB_Complessivo!$A:$A,"ACT",DB_Complessivo!$J:$J,$A11,DB_Complessivo!$B:$B,J$3)/1000 -> -1804.6526 | K11: =-SUMIFS(DB_Complessivo!$E:$E,DB_Complessivo!$A:$A,"ACT",DB_Complessivo!$J:$J,$A11,DB_Complessivo!$B:$B,K$3)/1000 -> -1917.6018 | L11: =-SUMIFS(DB_Complessivo!$E:$E,DB_Complessivo!$A:$A,"ACT",DB_Complessivo!$J:$J,$A11,DB_Complessivo!$B:$B,L$3)/1000 -> -874.64877 | M11: =-SUMIFS(DB_Complessivo!$E:$E,DB_Complessivo!$A:$A,"ACT",DB_Complessivo!$J:$J,$A11,DB_Complessivo!$B:$B,M$3)/1000 -> -1151.6756 | N11: =-SUMIFS(DB_Complessivo!$E:$E,DB_Complessivo!$A:$A,"ACT",DB_Complessivo!$J:$J,$A11,DB_Complessivo!$B:$B,N$3)/1000 -> -1268.5674
C12: Margine di Contribuzione | D12: =SUM(D8:D11) -> 2711.8762 | E12: =SUM(E8:E11) -> 2115.601 | F12: =SUM(F8:F11) -> 2178.0042 | J12: =SUM(J8:J11) -> 4763.5035 | K12: =SUM(K8:K11) -> 3110.0641 | L12: =SUM(L8:L11) -> 3819.6586 | M12: =SUM(M8:M11) -> 2416.7225 | N12: =SUM(N8:N11) -> 4573.3352
C13: % Margine di Contribuzione | D13: =D12/D$8 -> 0.7292865 | E13: =E12/E$8 -> 0.59702948 | F13: =F12/F$8 -> 0.56679201 | J13: =J12/J$8 -> 0.36121478 | K13: =K12/K$8 -> 0.46638858 | L13: =L12/L$8 -> 0.64463956 | M13: =M12/M$8 -> 0.40238033 | N13: =N12/N$8 -> 0.63437715
A14: PRD | C14: Altri costi di produzione | D14: =-SUMIFS(DB_Complessivo!$E:$E,DB_Complessivo!$A:$A,"ACT",DB_Complessivo!$J:$J,$A14,DB_Complessivo!$B:$B,D$3)/1000 -> -81.11524 | E14: =-SUMIFS(DB_Complessivo!$E:$E,DB_Complessivo!$A:$A,$E$2,DB_Complessivo!$J:$J,$A14,DB_Complessivo!$B:$B,E$3)/1000 -> -103.07902 | F14: =-SUMIFS(DB_Complessivo!$E:$E,DB_Complessivo!$A:$A,"ACT",DB_Complessivo!$J:$J,$A14,DB_Complessivo!$B:$B,F$3)/1000 -> -106.59596 | J14: =-SUMIFS(DB_Complessivo!$E:$E,DB_Complessivo!$A:$A,"ACT",DB_Complessivo!$J:$J,$A14,DB_Complessivo!$B:$B,J$3)/1000 -> -228.3328 | K14: =-SUMIFS(DB_Complessivo!$E:$E,DB_Complessivo!$A:$A,"ACT",DB_Complessivo!$J:$J,$A14,DB_Complessivo!$B:$B,K$3)/1000 -> -192.74006 | L14: =-SUMIFS(DB_Complessivo!$E:$E,DB_Complessivo!$A:$A,"ACT",DB_Complessivo!$J:$J,$A14,DB_Complessivo!$B:$B,L$3)/1000 -> -255.39126 | M14: =-SUMIFS(DB_Complessivo!$E:$E,DB_Complessivo!$A:$A,"ACT",DB_Complessivo!$J:$J,$A14,DB_Complessivo!$B:$B,M$3)/1000 -> -292.18367 | N14: =-SUMIFS(DB_Complessivo!$E:$E,DB_Complessivo!$A:$A,"ACT",DB_Complessivo!$J:$J,$A14,DB_Complessivo!$B:$B,N$3)/1000 -> -180.57237
A15: PAY | C15: Costo del personale indiretto | D15: =-SUMIFS(DB_Complessivo!$E:$E,DB_Complessivo!$A:$A,"ACT",DB_Complessivo!$J:$J,$A15,DB_Complessivo!$B:$B,D$3)/1000 -> -1163.1673 | E15: =-SUMIFS(DB_Complessivo!$E:$E,DB_Complessivo!$A:$A,$E$2,DB_Complessivo!$J:$J,$A15,DB_Complessivo!$B:$B,E$3)/1000-SUMIFS(DB_Complessivo!$E:$E,DB_Complessivo!$A:$A,$E$2,DB_Complessivo!$J:$J,$A11,DB_Complessivo!$B:$B,E$3)/1000*30% -> -1487.85 | F15: =-SUMIFS(DB_Complessivo!$E:$E,DB_Complessivo!$A:$A,"ACT",DB_Complessivo!$J:$J,$A15,DB_Complessivo!$B:$B,F$3)/1000 -> -1371.1321 | J15: =-SUMIFS(DB_Complessivo!$E:$E,DB_Complessivo!$A:$A,"ACT",DB_Complessivo!$J:$J,$A15,DB_Complessivo!$B:$B,J$3)/1000 -> -773.42256 | K15: =-SUMIFS(DB_Complessivo!$E:$E,DB_Complessivo!$A:$A,"ACT",DB_Complessivo!$J:$J,$A15,DB_Complessivo!$B:$B,K$3)/1000 -> -821.82934 | L15: =-SUMIFS(DB_Complessivo!$E:$E,DB_Complessivo!$A:$A,"ACT",DB_Complessivo!$J:$J,$A15,DB_Complessivo!$B:$B,L$3)/1000 -> -2271.9612 | M15: =-SUMIFS(DB_Complessivo!$E:$E,DB_Complessivo!$A:$A,"ACT",DB_Complessivo!$J:$J,$A15,DB_Complessivo!$B:$B,M$3)/1000 -> -2336.1136 | N15: =-SUMIFS(DB_Complessivo!$E:$E,DB_Complessivo!$A:$A,"ACT",DB_Complessivo!$J:$J,$A15,DB_Complessivo!$B:$B,N$3)/1000 -> -2291.1535
A16: AFF | C16: Affitti | D16: =-SUMIFS(DB_Complessivo!$E:$E,DB_Complessivo!$A:$A,"ACT",DB_Complessivo!$J:$J,$A16,DB_Complessivo!$B:$B,D$3)/1000 -> -85.26118 | E16: =-SUMIFS(DB_Complessivo!$E:$E,DB_Complessivo!$A:$A,$E$2,DB_Complessivo!$J:$J,$A16,DB_Complessivo!$B:$B,E$3)/1000 -> -38.6754 | F16: =-SUMIFS(DB_Complessivo!$E:$E,DB_Complessivo!$A:$A,"ACT",DB_Complessivo!$J:$J,$A16,DB_Complessivo!$B:$B,F$3)/1000 -> -46.5754 | J16: =-SUMIFS(DB_Complessivo!$E:$E,DB_Complessivo!$A:$A,"ACT",DB_Complessivo!$J:$J,$A16,DB_Complessivo!$B:$B,J$3)/1000 -> -168.45069 | K16: =-SUMIFS(DB_Complessivo!$E:$E,DB_Complessivo!$A:$A,"ACT",DB_Complessivo!$J:$J,$A16,DB_Complessivo!$B:$B,K$3)/1000 -> -186.66432 | L16: =-SUMIFS(DB_Complessivo!$E:$E,DB_Complessivo!$A:$A,"ACT",DB_Complessivo!$J:$J,$A16,DB_Complessivo!$B:$B,L$3)/1000 -> -205.82747 | M16: =-SUMIFS(DB_Complessivo!$E:$E,DB_Complessivo!$A:$A,"ACT",DB_Complessivo!$J:$J,$A16,DB_Complessivo!$B:$B,M$3)/1000 -> -249.02661 | N16: =-SUMIFS(DB_Complessivo!$E:$E,DB_Complessivo!$A:$A,"ACT",DB_Complessivo!$J:$J,$A16,DB_Complessivo!$B:$B,N$3)/1000 -> -125.09451
A17: COSTI | C17: Costi generali, commerciali ed amm. | D17: =-SUMIFS(DB_Complessivo!$E:$E,DB_Complessivo!$A:$A,"ACT",DB_Complessivo!$J:$J,$A17,DB_Complessivo!$B:$B,D$3)/1000 -> -425.01635 | E17: =-SUMIFS(DB_Complessivo!$E:$E,DB_Complessivo!$A:$A,$E$2,DB_Complessivo!$J:$J,$A17,DB_Complessivo!$B:$B,E$3)/1000 -> -455.23768 | F17: =-SUMIFS(DB_Complessivo!$E:$E,DB_Complessivo!$A:$A,"ACT",DB_Complessivo!$J:$J,$A17,DB_Complessivo!$B:$B,F$3)/1000 -> -559.97346 | J17: =-SUMIFS(DB_Complessivo!$E:$E,DB_Complessivo!$A:$A,"ACT",DB_Complessivo!$J:$J,$A17,DB_Complessivo!$B:$B,J$3)/1000 -> -1048.786 | K17: =-SUMIFS(DB_Complessivo!$E:$E,DB_Complessivo!$A:$A,"ACT",DB_Complessivo!$J:$J,$A17,DB_Complessivo!$B:$B,K$3)/1000 -> -1005.9921 | L17: =-SUMIFS(DB_Complessivo!$E:$E,DB_Complessivo!$A:$A,"ACT",DB_Complessivo!$J:$J,$A17,DB_Complessivo!$B:$B,L$3)/1000 -> -1221.4475 | M17: =-SUMIFS(DB_Complessivo!$E:$E,DB_Complessivo!$A:$A,"ACT",DB_Complessivo!$J:$J,$A17,DB_Complessivo!$B:$B,M$3)/1000 -> -1157.5486 | N17: =-SUMIFS(DB_Complessivo!$E:$E,DB_Complessivo!$A:$A,"ACT",DB_Complessivo!$J:$J,$A17,DB_Complessivo!$B:$B,N$3)/1000 -> -1097.1855
C18: EBITDA | D18: =SUM(D12,D14:D17) -> 957.31622 | E18: =SUM(E12,E14:E17) -> 30.758895 | F18: =SUM(F12,F14:F17) -> 93.7272 | J18: =SUM(J12,J14:J17) -> 2544.5114 | K18: =SUM(K12,K14:K17) -> 902.83833 | L18: =SUM(L12,L14:L17) -> -134.96884 | M18: =SUM(M12,M14:M17) -> -1618.1501 | N18: =SUM(N12,N14:N17) -> 879.32932
C19: % EBITDA | D19: =D18/D$8 -> 0.25744456 | E19: =E18/E$8 -> 0.0086802601 | F19: =F18/F$8 -> 0.024391059 | J19: =J18/J$8 -> 0.1929494 | K19: =K18/K$8 -> 0.13539061 | L19: =L18/L$8 -> -0.022778542 | M19: =M18/M$8 -> -0.26941934 | N19: =N18/N$8 -> 0.12197366
A20: AMM | C20: Ammortamenti | D20: =-SUMIFS(DB_Complessivo!$E:$E,DB_Complessivo!$A:$A,"ACT",DB_Complessivo!$J:$J,$A20,DB_Complessivo!$B:$B,D$3)/1000 -> -56.186048 | E20: =-SUMIFS(DB_Complessivo!$E:$E,DB_Complessivo!$A:$A,$E$2,DB_Complessivo!$J:$J,$A20,DB_Complessivo!$B:$B,E$3)/1000 -> -67.21254 | F20: =-SUMIFS(DB_Complessivo!$E:$E,DB_Complessivo!$A:$A,"ACT",DB_Complessivo!$J:$J,$A20,DB_Complessivo!$B:$B,F$3)/1000 -> -67.21245 | J20: =-SUMIFS(DB_Complessivo!$E:$E,DB_Complessivo!$A:$A,"ACT",DB_Complessivo!$J:$J,$A20,DB_Complessivo!$B:$B,J$3)/1000 -> -164.51532 | K20: =-SUMIFS(DB_Complessivo!$E:$E,DB_Complessivo!$A:$A,"ACT",DB_Complessivo!$J:$J,$A20,DB_Complessivo!$B:$B,K$3)/1000 -> -198.29228 | L20: =-SUMIFS(DB_Complessivo!$E:$E,DB_Complessivo!$A:$A,"ACT",DB_Complessivo!$J:$J,$A20,DB_Complessivo!$B:$B,L$3)/1000 -> -157.96159 | M20: =-SUMIFS(DB_Complessivo!$E:$E,DB_Complessivo!$A:$A,"ACT",DB_Complessivo!$J:$J,$A20,DB_Complessivo!$B:$B,M$3)/1000 -> -130.40508 | N20: =-SUMIFS(DB_Complessivo!$E:$E,DB_Complessivo!$A:$A,"ACT",DB_Complessivo!$J:$J,$A20,DB_Complessivo!$B:$B,N$3)/1000 -> -122.444
A21: ACC | C21: Accantonamenti | D21: =-SUMIFS(DB_Complessivo!$E:$E,DB_Complessivo!$A:$A,"ACT",DB_Complessivo!$J:$J,$A21,DB_Complessivo!$B:$B,D$3)/1000 -> 0 | E21: =-SUMIFS(DB_Complessivo!$E:$E,DB_Complessivo!$A:$A,$E$2,DB_Complessivo!$J:$J,$A21,DB_Complessivo!$B:$B,E$3)/1000 -> 0 | F21: =-SUMIFS(DB_Complessivo!$E:$E,DB_Complessivo!$A:$A,"ACT",DB_Complessivo!$J:$J,$A21,DB_Complessivo!$B:$B,F$3)/1000 -> 0 | J21: =-SUMIFS(DB_Complessivo!$E:$E,DB_Complessivo!$A:$A,"ACT",DB_Complessivo!$J:$J,$A21,DB_Complessivo!$B:$B,J$3)/1000 -> -2427 | K21: =-SUMIFS(DB_Complessivo!$E:$E,DB_Complessivo!$A:$A,"ACT",DB_Complessivo!$J:$J,$A21,DB_Complessivo!$B:$B,K$3)/1000 -> -808.99081 | L21: =-SUMIFS(DB_Complessivo!$E:$E,DB_Complessivo!$A:$A,"ACT",DB_Complessivo!$J:$J,$A21,DB_Complessivo!$B:$B,L$3)/1000 -> -2016.5399 | M21: =-SUMIFS(DB_Complessivo!$E:$E,DB_Complessivo!$A:$A,"ACT",DB_Complessivo!$J:$J,$A21,DB_Complessivo!$B:$B,M$3)/1000 -> 0 | N21: =-SUMIFS(DB_Complessivo!$E:$E,DB_Complessivo!$A:$A,"ACT",DB_Complessivo!$J:$J,$A21,DB_Complessivo!$B:$B,N$3)/1000 -> 0
C22: EBIT | D22: =SUM(D18,D20:D21) -> 901.13017 | E22: =SUM(E18,E20:E21) -> -36.453645 | F22: =SUM(F18,F20:F21) -> 26.51475 | J22: =SUM(J18,J20:J21) -> -47.00393 | K22: =SUM(K18,K20:K21) -> -104.44476 | L22: =SUM(L18,L20:L21) -> -2309.4704 | M22: =SUM(M18,M20:M21) -> -1748.5552 | N22: =SUM(N18,N20:N21) -> 756.88532
C23: % EBIT | D23: =D22/D$8 -> 0.24233483 | E23: =E22/E$8 -> -0.010287337 | F23: =F22/F$8 -> 0.006900055 | J23: =J22/J$8 -> -0.0035642914 | K23: =K22/K$8 -> -0.01566265 | L23: =L22/L$8 -> -0.38976676 | M23: =M22/M$8 -> -0.29113157 | N23: =N22/N$8 -> 0.10498919
A24: FIN | C24: Gestione Finanziaria | D24: =-SUMIFS(DB_Complessivo!$E:$E,DB_Complessivo!$A:$A,"ACT",DB_Complessivo!$J:$J,$A24,DB_Complessivo!$B:$B,D$3)/1000 -> -44.34164 | E24: =-SUMIFS(DB_Complessivo!$E:$E,DB_Complessivo!$A:$A,$E$2,DB_Complessivo!$J:$J,$A24,DB_Complessivo!$B:$B,E$3)/1000 -> 0 | F24: =-SUMIFS(DB_Complessivo!$E:$E,DB_Complessivo!$A:$A,"ACT",DB_Complessivo!$J:$J,$A24,DB_Complessivo!$B:$B,F$3)/1000 -> 11.67779 | J24: =-SUMIFS(DB_Complessivo!$E:$E,DB_Complessivo!$A:$A,"ACT",DB_Complessivo!$J:$J,$A24,DB_Complessivo!$B:$B,J$3)/1000 -> -18.59043 | K24: =-SUMIFS(DB_Complessivo!$E:$E,DB_Complessivo!$A:$A,"ACT",DB_Complessivo!$J:$J,$A24,DB_Complessivo!$B:$B,K$3)/1000 -> -24.9416 | L24: =-SUMIFS(DB_Complessivo!$E:$E,DB_Complessivo!$A:$A,"ACT",DB_Complessivo!$J:$J,$A24,DB_Complessivo!$B:$B,L$3)/1000 -> -14.27967 | M24: =-SUMIFS(DB_Complessivo!$E:$E,DB_Complessivo!$A:$A,"ACT",DB_Complessivo!$J:$J,$A24,DB_Complessivo!$B:$B,M$3)/1000 -> 69.02285 | N24: =-SUMIFS(DB_Complessivo!$E:$E,DB_Complessivo!$A:$A,"ACT",DB_Complessivo!$J:$J,$A24,DB_Complessivo!$B:$B,N$3)/1000 -> 44.33652
A25: EXT | C25: Gestione Straordinaria | D25: =-SUMIFS(DB_Complessivo!$E:$E,DB_Complessivo!$A:$A,"ACT",DB_Complessivo!$J:$J,$A25,DB_Complessivo!$B:$B,D$3)/1000 -> 33.568 | E25: =-SUMIFS(DB_Complessivo!$E:$E,DB_Complessivo!$A:$A,$E$2,DB_Complessivo!$J:$J,$A25,DB_Complessivo!$B:$B,E$3)/1000 -> -49.87874 | F25: =-SUMIFS(DB_Complessivo!$E:$E,DB_Complessivo!$A:$A,"ACT",DB_Complessivo!$J:$J,$A25,DB_Complessivo!$B:$B,F$3)/1000 -> 37.29463 | J25: =-SUMIFS(DB_Complessivo!$E:$E,DB_Complessivo!$A:$A,"ACT",DB_Complessivo!$J:$J,$A25,DB_Complessivo!$B:$B,J$3)/1000 -> 98.74265 | K25: =-SUMIFS(DB_Complessivo!$E:$E,DB_Complessivo!$A:$A,"ACT",DB_Complessivo!$J:$J,$A25,DB_Complessivo!$B:$B,K$3)/1000 -> 180.1279 | L25: =-SUMIFS(DB_Complessivo!$E:$E,DB_Complessivo!$A:$A,"ACT",DB_Complessivo!$J:$J,$A25,DB_Complessivo!$B:$B,L$3)/1000 -> 2393.0702 | M25: =-SUMIFS(DB_Complessivo!$E:$E,DB_Complessivo!$A:$A,"ACT",DB_Complessivo!$J:$J,$A25,DB_Complessivo!$B:$B,M$3)/1000 -> 1732.986 | N25: =-SUMIFS(DB_Complessivo!$E:$E,DB_Complessivo!$A:$A,"ACT",DB_Complessivo!$J:$J,$A25,DB_Complessivo!$B:$B,N$3)/1000 -> 139.317
C26: EBT | D26: =SUM(D22,D24:D25) -> 890.35653 | E26: =SUM(E22,E24:E25) -> -86.332385 | F26: =SUM(F22,F24:F25) -> 75.48717 | J26: =SUM(J22,J24:J25) -> 33.14829 | K26: =SUM(K22,K24:K25) -> 50.741535 | L26: =SUM(L22,L24:L25) -> 69.32017 | M26: =SUM(M22,M24:M25) -> 53.453745 | N26: =SUM(N22,N24:N25) -> 940.53884
A27: TAX | C27: Imposte | D27: =-SUMIFS(DB_Complessivo!$E:$E,DB_Complessivo!$A:$A,"ACT",DB_Complessivo!$J:$J,$A27,DB_Complessivo!$B:$B,D$3)/1000 -> 0 | E27: =-SUMIFS(DB_Complessivo!$E:$E,DB_Complessivo!$A:$A,$E$2,DB_Complessivo!$J:$J,$A27,DB_Complessivo!$B:$B,E$3)/1000 -> 0 | F27: =-SUMIFS(DB_Complessivo!$E:$E,DB_Complessivo!$A:$A,"ACT",DB_Complessivo!$J:$J,$A27,DB_Complessivo!$B:$B,F$3)/1000 -> 0 | J27: =-SUMIFS(DB_Complessivo!$E:$E,DB_Complessivo!$A:$A,"ACT",DB_Complessivo!$J:$J,$A27,DB_Complessivo!$B:$B,J$3)/1000 -> 0 | K27: =-SUMIFS(DB_Complessivo!$E:$E,DB_Complessivo!$A:$A,"ACT",DB_Complessivo!$J:$J,$A27,DB_Complessivo!$B:$B,K$3)/1000 -> 0 | L27: =-SUMIFS(DB_Complessivo!$E:$E,DB_Complessivo!$A:$A,"ACT",DB_Complessivo!$J:$J,$A27,DB_Complessivo!$B:$B,L$3)/1000 -> -0.948 | M27: =-SUMIFS(DB_Complessivo!$E:$E,DB_Complessivo!$A:$A,"ACT",DB_Complessivo!$J:$J,$A27,DB_Complessivo!$B:$B,M$3)/1000 -> 0 | N27: =-SUMIFS(DB_Complessivo!$E:$E,DB_Complessivo!$A:$A,"ACT",DB_Complessivo!$J:$J,$A27,DB_Complessivo!$B:$B,N$3)/1000 -> 0
C28: Risultato d'esercizio | D28: =SUM(D26:D27) -> 890.35653 | E28: =SUM(E26:E27) -> -86.332385 | F28: =SUM(F26:F27) -> 75.48717 | J28: =SUM(J26:J27) -> 33.14829 | K28: =SUM(K26:K27) -> 50.741535 | L28: =SUM(L26:L27) -> 68.37217 | M28: =SUM(M26:M27) -> 53.453745 | N28: =SUM(N26:N27) -> 940.53884

Sheet CE_Esteso
C1: CONTO ECONOMICO di PROGETTO QUID | D1: PY | F1: REV_BDG | G1: ACT | H1: DELTA | I1: DELTA (%) | K1: PJ 2025
C2: EUR/000 | D2: =EOMONTH(INDICE!$B$2,-12) -> 45473 | F2: =EOMONTH(INDICE!$B$2,0) -> 45838 | G2: =EOMONTH(INDICE!$B$2,0) -> 45838 | H2: ACT vs BDG | I2: ACT vs BDG | K2: FCT 2025
A3: RICOP | C3: Ricavi Netti di Vendita | D3: =-SUMIFS(DB_Complessivo!$E:$E,DB_Complessivo!$A:$A,"ACT",DB_Complessivo!$B:$B,D$2,DB_Complessivo!$H:$H,$A3)/1000 -> 3007.6994 | F3: =-SUMIFS(DB_Complessivo!$E:$E,DB_Complessivo!$A:$A,$F$1,DB_Complessivo!$B:$B,F$2,DB_Complessivo!$H:$H,$A3)/1000 -> 3057.6796 | G3: =-SUMIFS(DB_Complessivo!$E:$E,DB_Complessivo!$A:$A,"ACT",DB_Complessivo!$B:$B,G$2,DB_Complessivo!$H:$H,$A3)/1000 -> 3134.7637 | H3: =G3-F3 -> 77.084109 | I3: =IFERROR((G3-F3)/ABS(F3),"") -> 0.025210002 | K3: =+SUM(FCT!D3:O3) -> 6180.0423 | L3: x
A4: CORR | C4: Corrispettivi | D4: =-SUMIFS(DB_Complessivo!$E:$E,DB_Complessivo!$A:$A,"ACT",DB_Complessivo!$B:$B,D$2,DB_Complessivo!$H:$H,$A4)/1000 -> 583.8182 | F4: =-SUMIFS(DB_Complessivo!$E:$E,DB_Complessivo!$A:$A,$F$1,DB_Complessivo!$B:$B,F$2,DB_Complessivo!$H:$H,$A4)/1000 -> 145.36444 | G4: =-SUMIFS(DB_Complessivo!$E:$E,DB_Complessivo!$A:$A,"ACT",DB_Complessivo!$B:$B,G$2,DB_Complessivo!$H:$H,$A4)/1000 -> 145.43466 | H4: =G4-F4 -> 0.07022 | I4: =IFERROR((G4-F4)/ABS(F4),"") -> 0.00048306174 | K4: =+SUM(FCT!D4:O4) -> 216.43466 | L4: x
A5: VARPF | C5: Variazione magazzino PF | D5: =-SUMIFS(DB_Complessivo!$E:$E,DB_Complessivo!$A:$A,"ACT",DB_Complessivo!$B:$B,D$2,DB_Complessivo!$H:$H,$A5)/1000 -> -378.34423 | F5: =-SUMIFS(DB_Complessivo!$E:$E,DB_Complessivo!$A:$A,$F$1,DB_Complessivo!$B:$B,F$2,DB_Complessivo!$H:$H,$A5)/1000 -> 50.48681 | G5: =-SUMIFS(DB_Complessivo!$E:$E,DB_Complessivo!$A:$A,"ACT",DB_Complessivo!$B:$B,G$2,DB_Complessivo!$H:$H,$A5)/1000 -> -30.72334 | H5: =G5-F5 -> -81.21015 | I5: =IFERROR((G5-F5)/ABS(F5),"") -> -1.6085419 | K5: =+SUM(FCT!D5:O5) -> -30.72334 | L5: x
A6: ALTRI | C6: Altri Ricavi | D6: =-SUMIFS(DB_Complessivo!$E:$E,DB_Complessivo!$A:$A,"ACT",DB_Complessivo!$B:$B,D$2,DB_Complessivo!$H:$H,$A6)/1000 -> 505.36009 | F6: =-SUMIFS(DB_Complessivo!$E:$E,DB_Complessivo!$A:$A,$F$1,DB_Complessivo!$B:$B,F$2,DB_Complessivo!$H:$H,$A6)/1000 -> 290.01446 | G6: =-SUMIFS(DB_Complessivo!$E:$E,DB_Complessivo!$A:$A,"ACT",DB_Complessivo!$B:$B,G$2,DB_Complessivo!$H:$H,$A6)/1000 -> 593.21178 | H6: =G6-F6 -> 303.19732 | I6: =IFERROR((G6-F6)/ABS(F6),"") -> 1.0454559 | K6: =+SUM(FCT!D6:O6) -> 1259.2901 | L6: x
A7: SUBTOTALE | C7: Ricavi | D7: =SUM(D3:D6) -> 3718.5335 | F7: =SUM(F3:F6) -> 3543.5453 | G7: =SUM(G3:G6) -> 3842.6868 | H7: =G7-F7 -> 299.1415 | I7: =IFERROR((G7-F7)/ABS(F7),"") -> 0.084418704 | K7: =SUM(K3:K6) -> 7625.0438
A8: ACQDI | C8: Acquisti diretti di produzione | D8: =-SUMIFS(DB_Complessivo!$E:$E,DB_Complessivo!$A:$A,"ACT",DB_Complessivo!$B:$B,D$2,DB_Complessivo!$H:$H,$A8)/1000 -> -262.589 | F8: =-SUMIFS(DB_Complessivo!$E:$E,DB_Complessivo!$A:$A,$F$1,DB_Complessivo!$B:$B,F$2,DB_Complessivo!$H:$H,$A8)/1000 -> -254.76535 | G8: =-SUMIFS(DB_Complessivo!$E:$E,DB_Complessivo!$A:$A,"ACT",DB_Complessivo!$B:$B,G$2,DB_Complessivo!$H:$H,$A8)/1000 -> -313.83995 | H8: =G8-F8 -> -59.074598 | I8: =IFERROR((G8-F8)/ABS(F8),"") -> -0.23187846 | K8: =+SUM(FCT!D8:O8) -> -581.95096 | L8: x
A9: VARMP | C9: Variazioni magazzino MP / SL | D9: =-SUMIFS(DB_Complessivo!$E:$E,DB_Complessivo!$A:$A,"ACT",DB_Complessivo!$B:$B,D$2,DB_Complessivo!$H:$H,$A9)/1000 -> 254.29484 | F9: =-SUMIFS(DB_Complessivo!$E:$E,DB_Complessivo!$A:$A,$F$1,DB_Complessivo!$B:$B,F$2,DB_Complessivo!$H:$H,$A9)/1000 -> -49.94251 | G9: =-SUMIFS(DB_Complessivo!$E:$E,DB_Complessivo!$A:$A,"ACT",DB_Complessivo!$B:$B,G$2,DB_Complessivo!$H:$H,$A9)/1000 -> -51.59331 | H9: =G9-F9 -> -1.6508 | I9: =IFERROR((G9-F9)/ABS(F9),"") -> -0.033054005 | K9: =+SUM(FCT!D9:O9) -> -51.59331 | L9: x
A10: SERDI | C10: Lavorazioni esterne | D10: =-SUMIFS(DB_Complessivo!$E:$E,DB_Complessivo!$A:$A,"ACT",DB_Complessivo!$B:$B,D$2,DB_Complessivo!$H:$H,$A10)/1000 -> -354.46345 | F10: =-SUMIFS(DB_Complessivo!$E:$E,DB_Complessivo!$A:$A,$F$1,DB_Complessivo!$B:$B,F$2,DB_Complessivo!$H:$H,$A10)/1000 -> -566.4114 | G10: =-SUMIFS(DB_Complessivo!$E:$E,DB_Complessivo!$A:$A,"ACT",DB_Complessivo!$B:$B,G$2,DB_Complessivo!$H:$H,$A10)/1000 -> -519.22252 | H10: =G10-F10 -> 47.18888 | I10: =IFERROR((G10-F10)/ABS(F10),"") -> 0.083312024 | K10: =+SUM(FCT!D10:O10) -> -1102.4473 | L10: x
A11: PERDI | C11: Manodopera diretta di produzione | D11: =-SUMIFS(DB_Complessivo!$E:$E,DB_Complessivo!$A:$A,"ACT",DB_Complessivo!$B:$B,D$2,DB_Complessivo!$H:$H,$A11)/1000 -> -643.8996 | F11: =-SUMIFS(DB_Complessivo!$E:$E,DB_Complessivo!$A:$A,$F$1,DB_Complessivo!$B:$B,F$2,DB_Complessivo!$H:$H,$A11)/1000 -> -795.46433 | G11: =-SUMIFS(DB_Complessivo!$E:$E,DB_Complessivo!$A:$A,"ACT",DB_Complessivo!$B:$B,G$2,DB_Complessivo!$H:$H,$A11)/1000 -> -780.02684 | H11: =G11-F11 -> 15.437484 | I11: =IFERROR((G11-F11)/ABS(F11),"") -> 0.019406884 | K11: =+SUM(FCT!D11:O11) -> -1575.462 | L11: x
A12: SUBTOTALE | C12: Margine Diretto di Produzione | D12: =SUM(D7:D11) -> 2711.8762 | F12: =SUM(F7:F11) -> 1876.9617 | G12: =SUM(G7:G11) -> 2178.0042 | H12: =G12-F12 -> 301.04247 | I12: =IFERROR((G12-F12)/ABS(F12),"") -> 0.16038818 | K12: =SUM(K7:K11) -> 4313.5902
A13: SUBTOTALE | C13: Margine diretto di produzione (%) | D13: =IFERROR(D12/D$7,"") -> 0.7292865 | F13: =IFERROR(F12/F$7,"") -> 0.52968469 | G13: =IFERROR(G12/G$7,"") -> 0.56679201 | H13: =G13-F13 -> 0.037107316 | I13: =IFERROR((G13-F13)/ABS(F13),"") -> 0.070055481 | K13: =IFERROR(K12/K$7,"") -> 0.5657135
A14: ACQIN | C14: Acquisti indiretti di fabbrica | D14: =-SUMIFS(DB_Complessivo!$E:$E,DB_Complessivo!$A:$A,"ACT",DB_Complessivo!$B:$B,D$2,DB_Complessivo!$H:$H,$A14)/1000 -> -10.14771 | F14: =-SUMIFS(DB_Complessivo!$E:$E,DB_Complessivo!$A:$A,$F$1,DB_Complessivo!$B:$B,F$2,DB_Complessivo!$H:$H,$A14)/1000 -> -8.958456 | G14: =-SUMIFS(DB_Complessivo!$E:$E,DB_Complessivo!$A:$A,"ACT",DB_Complessivo!$B:$B,G$2,DB_Complessivo!$H:$H,$A14)/1000 -> -9.83135 | H14: =G14-F14 -> -0.872894 | I14: =IFERROR((G14-F14)/ABS(F14),"") -> -0.097437996 | K14: =+SUM(FCT!D14:O14) -> -14.875142 | L14: x
A15: PERIM | C15: Costi del personale diretto improduttivo | D15: =-SUMIFS(DB_Complessivo!$E:$E,DB_Complessivo!$A:$A,"ACT",DB_Complessivo!$B:$B,D$2,DB_Complessivo!$H:$H,$A15)/1000 -> -275.95697 | F15: =-SUMIFS(DB_Complessivo!$E:$E,DB_Complessivo!$A:$A,$F$1,DB_Complessivo!$B:$B,F$2,DB_Complessivo!$H:$H,$A15)/1000 -> -340.91328 | G15: =-SUMIFS(DB_Complessivo!$E:$E,DB_Complessivo!$A:$A,"ACT",DB_Complessivo!$B:$B,G$2,DB_Complessivo!$H:$H,$A15)/1000 -> -334.29722 | H15: =G15-F15 -> 6.6160645 | I15: =IFERROR((G15-F15)/ABS(F15),"") -> 0.019406884 | K15: =+SUM(FCT!D15:O15) -> -675.19799
A16: PERIN | C16: Costi del Personale indiretto di fabbrica | D16: =-SUMIFS(DB_Complessivo!$E:$E,DB_Complessivo!$A:$A,"ACT",DB_Complessivo!$B:$B,D$2,DB_Complessivo!$H:$H,$A16)/1000 -> -278.62387 | F16: =-SUMIFS(DB_Complessivo!$E:$E,DB_Complessivo!$A:$A,$F$1,DB_Complessivo!$B:$B,F$2,DB_Complessivo!$H:$H,$A16)/1000 -> -411.44048 | G16: =-SUMIFS(DB_Complessivo!$E:$E,DB_Complessivo!$A:$A,"ACT",DB_Complessivo!$B:$B,G$2,DB_Complessivo!$H:$H,$A16)/1000 -> -406.57358 | H16: =G16-F16 -> 4.8668985 | I16: =IFERROR((G16-F16)/ABS(F16),"") -> 0.011828925 | K16: =+SUM(FCT!D16:O16) -> -786.76095
A17: SERIN | C17: Servizi indiretti di fabbrica | D17: =-SUMIFS(DB_Complessivo!$E:$E,DB_Complessivo!$A:$A,"ACT",DB_Complessivo!$B:$B,D$2,DB_Complessivo!$H:$H,$A17)/1000 -> -70.96753 | F17: =-SUMIFS(DB_Complessivo!$E:$E,DB_Complessivo!$A:$A,$F$1,DB_Complessivo!$B:$B,F$2,DB_Complessivo!$H:$H,$A17)/1000 -> -94.120566 | G17: =-SUMIFS(DB_Complessivo!$E:$E,DB_Complessivo!$A:$A,"ACT",DB_Complessivo!$B:$B,G$2,DB_Complessivo!$H:$H,$A17)/1000 -> -96.76461 | H17: =G17-F17 -> -2.644044 | I17: =IFERROR((G17-F17)/ABS(F17),"") -> -0.028092096 | K17: =+SUM(FCT!D17:O17) -> -222.74969 | L17: x
A18: AMMIN | C18: Ammortamenti indiretti di fabbrica | D18: =-SUMIFS(DB_Complessivo!$E:$E,DB_Complessivo!$A:$A,"ACT",DB_Complessivo!$B:$B,D$2,DB_Complessivo!$H:$H,$A18)/1000 -> -39.921 | F18: =-SUMIFS(DB_Complessivo!$E:$E,DB_Complessivo!$A:$A,$F$1,DB_Complessivo!$B:$B,F$2,DB_Complessivo!$H:$H,$A18)/1000 -> -43.92702 | G18: =-SUMIFS(DB_Complessivo!$E:$E,DB_Complessivo!$A:$A,"ACT",DB_Complessivo!$B:$B,G$2,DB_Complessivo!$H:$H,$A18)/1000 -> -43.92693 | H18: =G18-F18 -> 9e-05 | I18: =IFERROR((G18-F18)/ABS(F18),"") -> 2.0488528e-06 | K18: =+SUM(FCT!D18:O18) -> -87.85395 | L18: x
A19: SUBTOTALE | C19: Margine Indiretto di Fabbrica | D19: =SUM(D12,D14:D18) -> 2036.2592 | F19: =SUM(F12,F14:F18) -> 977.60188 | G19: =SUM(G12,G14:G18) -> 1286.6105 | H19: =G19-F19 -> 309.00858 | I19: =IFERROR((G19-F19)/ABS(F19),"") -> 0.31608836 | K19: =SUM(K12,K14:K18) -> 2526.1525
A20: SUBTOTALE | C20: Margine indiretto di fabbrica (%) | D20: =IFERROR(D19/D$7,"") -> 0.54759737 | F20: =IFERROR(F19/F$7,"") -> 0.27588243 | G20: =IFERROR(G19/G$7,"") -> 0.33482054 | H20: =G20-F20 -> 0.05893811 | I20: =IFERROR((G20-F20)/ABS(F20),"") -> 0.21363488 | K20: =IFERROR(K19/K$7,"") -> 0.33129679
A21: PERST | C21: Costi del personale di struttura | D21: =-SUMIFS(DB_Complessivo!$E:$E,DB_Complessivo!$A:$A,"ACT",DB_Complessivo!$B:$B,D$2,DB_Complessivo!$H:$H,$A21)/1000 -> -608.58641 | F21: =-SUMIFS(DB_Complessivo!$E:$E,DB_Complessivo!$A:$A,$F$1,DB_Complessivo!$B:$B,F$2,DB_Complessivo!$H:$H,$A21)/1000 -> -496.85693 | G21: =-SUMIFS(DB_Complessivo!$E:$E,DB_Complessivo!$A:$A,"ACT",DB_Complessivo!$B:$B,G$2,DB_Complessivo!$H:$H,$A21)/1000 -> -630.26133 | H21: =G21-F21 -> -133.4044 | I21: =IFERROR((G21-F21)/ABS(F21),"") -> -0.26849661 | K21: =+SUM(FCT!D21:O21) -> -1098.8008
A22: SERST | C22: Servizi di struttura | D22: =-SUMIFS(DB_Complessivo!$E:$E,DB_Complessivo!$A:$A,"ACT",DB_Complessivo!$B:$B,D$2,DB_Complessivo!$H:$H,$A22)/1000 -> -279.21442 | F22: =-SUMIFS(DB_Complessivo!$E:$E,DB_Complessivo!$A:$A,$F$1,DB_Complessivo!$B:$B,F$2,DB_Complessivo!$H:$H,$A22)/1000 -> -311.56084 | G22: =-SUMIFS(DB_Complessivo!$E:$E,DB_Complessivo!$A:$A,"ACT",DB_Complessivo!$B:$B,G$2,DB_Complessivo!$H:$H,$A22)/1000 -> -385.23776 | H22: =G22-F22 -> -73.676923 | I22: =IFERROR((G22-F22)/ABS(F22),"") -> -0.23647684 | K22: =+SUM(FCT!D22:O22) -> -619.7632 | L22: x
A23: AFFIT | C23: Affitti | D23: =-SUMIFS(DB_Complessivo!$E:$E,DB_Complessivo!$A:$A,"ACT",DB_Complessivo!$B:$B,D$2,DB_Complessivo!$H:$H,$A23)/1000 -> -85.26118 | F23: =-SUMIFS(DB_Complessivo!$E:$E,DB_Complessivo!$A:$A,$F$1,DB_Complessivo!$B:$B,F$2,DB_Complessivo!$H:$H,$A23)/1000 -> -38.6754 | G23: =-SUMIFS(DB_Complessivo!$E:$E,DB_Complessivo!$A:$A,"ACT",DB_Complessivo!$B:$B,G$2,DB_Complessivo!$H:$H,$A23)/1000 -> -46.5754 | H23: =G23-F23 -> -7.9 | I23: =IFERROR((G23-F23)/ABS(F23),"") -> -0.20426421 | K23: =+SUM(FCT!D23:O23) -> -88.7008 | L23: x
A24: COSGS | C24: Costi generali di struttura | D24: =-SUMIFS(DB_Complessivo!$E:$E,DB_Complessivo!$A:$A,"ACT",DB_Complessivo!$B:$B,D$2,DB_Complessivo!$H:$H,$A24)/1000 -> -145.80193 | F24: =-SUMIFS(DB_Complessivo!$E:$E,DB_Complessivo!$A:$A,$F$1,DB_Complessivo!$B:$B,F$2,DB_Complessivo!$H:$H,$A24)/1000 -> -143.67684 | G24: =-SUMIFS(DB_Complessivo!$E:$E,DB_Complessivo!$A:$A,"ACT",DB_Complessivo!$B:$B,G$2,DB_Complessivo!$H:$H,$A24)/1000 -> -174.7357 | H24: =G24-F24 -> -31.058861 | I24: =IFERROR((G24-F24)/ABS(F24),"") -> -0.21617166 | K24: =+SUM(FCT!D24:O24) -> -298.18387 | L24: x
A25: AMMST | C25: Ammortamenti di struttura | D25: =-SUMIFS(DB_Complessivo!$E:$E,DB_Complessivo!$A:$A,"ACT",DB_Complessivo!$B:$B,D$2,DB_Complessivo!$H:$H,$A25)/1000 -> -16.265048 | F25: =-SUMIFS(DB_Complessivo!$E:$E,DB_Complessivo!$A:$A,$F$1,DB_Complessivo!$B:$B,F$2,DB_Complessivo!$H:$H,$A25)/1000 -> -23.28552 | G25: =-SUMIFS(DB_Complessivo!$E:$E,DB_Complessivo!$A:$A,"ACT",DB_Complessivo!$B:$B,G$2,DB_Complessivo!$H:$H,$A25)/1000 -> -23.28552 | H25: =G25-F25 -> 0 | I25: =IFERROR((G25-F25)/ABS(F25),"") -> 0 | K25: =+SUM(FCT!D25:O25) -> -46.57104 | L25: x
A26: ACC | C26: Accantonamenti | D26: =-SUMIFS(DB_Complessivo!$E:$E,DB_Complessivo!$A:$A,"ACT",DB_Complessivo!$B:$B,D$2,DB_Complessivo!$H:$H,$A26)/1000 -> 0 | F26: =-SUMIFS(DB_Complessivo!$E:$E,DB_Complessivo!$A:$A,$F$1,DB_Complessivo!$B:$B,F$2,DB_Complessivo!$H:$H,$A26)/1000 -> 0 | G26: =-SUMIFS(DB_Complessivo!$E:$E,DB_Complessivo!$A:$A,"ACT",DB_Complessivo!$B:$B,G$2,DB_Complessivo!$H:$H,$A26)/1000 -> 0 | H26: =G26-F26 -> 0 | I26: =IFERROR((G26-F26)/ABS(F26),"") | K26: =+SUM(FCT!D26:O26) -> 0
A27: SUBTOTALE | C27: Risultato Operativo | D27: =SUM(D19,D21:D26) -> 901.13017 | F27: =SUM(F19,F21:F26) -> -36.453645 | G27: =SUM(G19,G21:G26) -> 26.51475 | H27: =G27-F27 -> 62.968395 | I27: =IFERROR((G27-F27)/ABS(F27),"") -> 1.7273552 | K27: =SUM(K19,K21:K26) -> 374.13276
A28: SUBTOTALE | C28: EBIT (%) | D28: =IFERROR(D27/D$7,"") -> 0.24233483 | F28: =IFERROR(F27/F$7,"") -> -0.010287337 | G28: =IFERROR(G27/G$7,"") -> 0.006900055 | H28: =G28-F28 -> 0.017187392 | I28: =IFERROR((G28-F28)/ABS(F28),"") -> 1.6707328 | K28: =IFERROR(K27/K$7,"") -> 0.04906631
A29: ONFIN | C29: Gestione Finanziaria | D29: =-SUMIFS(DB_Complessivo!$E:$E,DB_Complessivo!$A:$A,"ACT",DB_Complessivo!$B:$B,D$2,DB_Complessivo!$H:$H,$A29)/1000 -> -44.34164 | F29: =-SUMIFS(DB_Complessivo!$E:$E,DB_Complessivo!$A:$A,$F$1,DB_Complessivo!$B:$B,F$2,DB_Complessivo!$H:$H,$A29)/1000 -> 0 | G29: =-SUMIFS(DB_Complessivo!$E:$E,DB_Complessivo!$A:$A,"ACT",DB_Complessivo!$B:$B,G$2,DB_Complessivo!$H:$H,$A29)/1000 -> 11.67779 | H29: =G29-F29 -> 11.67779 | I29: =IFERROR((G29-F29)/ABS(F29),"") | K29: =+SUM(FCT!D29:O29) -> 11.67779
A30: ONSTR | C30: Gestione Straordinaria e Non Core | D30: =-SUMIFS(DB_Complessivo!$E:$E,DB_Complessivo!$A:$A,"ACT",DB_Complessivo!$B:$B,D$2,DB_Complessivo!$H:$H,$A30)/1000 -> 33.568 | F30: =-SUMIFS(DB_Complessivo!$E:$E,DB_Complessivo!$A:$A,$F$1,DB_Complessivo!$B:$B,F$2,DB_Complessivo!$H:$H,$A30)/1000 -> -49.87874 | G30: =-SUMIFS(DB_Complessivo!$E:$E,DB_Complessivo!$A:$A,"ACT",DB_Complessivo!$B:$B,G$2,DB_Complessivo!$H:$H,$A30)/1000 -> 37.29463 | H30: =G30-F30 -> 87.17337 | I30: =IFERROR((G30-F30)/ABS(F30),"") -> 1.7477059 | K30: =+SUM(FCT!D30:O30) -> 37.29463
A31: SUBTOTALE | C31: EBT | D31: =SUM(D27,D29:D30) -> 890.35653 | F31: =SUM(F27,F29:F30) -> -86.332385 | G31: =SUM(G27,G29:G30) -> 75.48717 | H31: =G31-F31 -> 161.81956 | I31: =IFERROR((G31-F31)/ABS(F31),"") -> 1.8743784 | K31: =SUM(K27,K29:K30) -> 423.10518
A32: TAX | C32: - Imposte | D32: =-SUMIFS(DB_Complessivo!$E:$E,DB_Complessivo!$A:$A,"ACT",DB_Complessivo!$B:$B,D$2,DB_Complessivo!$H:$H,$A32)/1000 -> 0 | F32: =-SUMIFS(DB_Complessivo!$E:$E,DB_Complessivo!$A:$A,$F$1,DB_Complessivo!$B:$B,F$2,DB_Complessivo!$H:$H,$A32)/1000 -> 0 | G32: =-SUMIFS(DB_Complessivo!$E:$E,DB_Complessivo!$A:$A,"ACT",DB_Complessivo!$B:$B,G$2,DB_Complessivo!$H:$H,$A32)/1000 -> 0 | H32: =G32-F32 -> 0 | I32: =IFERROR((G32-F32)/ABS(F32),"") | K32: 0
A33: SUBTOTALE | C33: Utile/perdita di esercizio | D33: =SUM(D31:D32) -> 890.35653 | F33: =SUM(F31:F32) -> -86.332385 | G33: =SUM(G31:G32) -> 75.48717 | H33: =G33-F33 -> 161.81956 | I33: =IFERROR((G33-F33)/ABS(F33),"") -> 1.8743784 | K33: =SUM(K31:K32) -> 423.10518

Sheet SP_CIN
C1: STATO PATRIMONIALE di PROGETTO QUID
C2: EUR/000 | D2: 45657 | E2: =INDICE!B2 -> 45838 | H2: 45657 | I2: =E2 -> 45838
C4: Immobilizzazioni Immateriali Nette | D4: =INDEX(SP!4:4,MATCH(D2,SP!2:2,0)) -> 83.93744 | E4: =INDEX(SP!4:4,MATCH(E2,SP!2:2,0)) -> 71.35754 | G4: Debiti a Breve (Liquidità) | H4: =-SUMIFS(DB_Complessivo!$E:$E,DB_Complessivo!$A:$A,"ACT",DB_Complessivo!$H:$H,$K4,DB_Complessivo!$B:$B,D$2)/1000 -> -2755.6611 | I4: =-SUMIFS(DB_Complessivo!$E:$E,DB_Complessivo!$A:$A,"ACT",DB_Complessivo!$H:$H,$K4,DB_Complessivo!$B:$B,E$2)/1000 -> -3022.1902 | K4: 36.LIQ
C5: Immobilizzazioni Materiali Nette | D5: =INDEX(SP!7:7,MATCH(D2,SP!2:2,0)) -> 1007.7579 | E5: =INDEX(SP!7:7,MATCH(E2,SP!2:2,0)) -> 993.70459 | G5: Utilizzo Linee Anticipo Fatture | H5: =-SUMIFS(DB_Complessivo!$E:$E,DB_Complessivo!$A:$A,"ACT",DB_Complessivo!$H:$H,$K5,DB_Complessivo!$B:$B,D$2)/1000 -> 492.45933 | I5: =-SUMIFS(DB_Complessivo!$E:$E,DB_Complessivo!$A:$A,"ACT",DB_Complessivo!$H:$H,$K5,DB_Complessivo!$B:$B,E$2)/1000 -> 20.32174 | K5: 36.ANT
A6: 38.TFR | C6: Fondo TFR | D6: =SUMIFS(DB_Complessivo!$E:$E,DB_Complessivo!$A:$A,"ACT",DB_Complessivo!$H:$H,$A6,DB_Complessivo!$B:$B,D$2)/1000 -> -674.25167 | E6: =SUMIFS(DB_Complessivo!$E:$E,DB_Complessivo!$A:$A,"ACT",DB_Complessivo!$H:$H,$A6,DB_Complessivo!$B:$B,E$2)/1000 -> -733.2327 | G6: PFN a Breve Termine | H6: =+SUM(H4:H5) -> -2263.2018 | I6: =+SUM(I4:I5) -> -3001.8684
A7: 33.PROV | C7: Altri Fondi | D7: =SUMIFS(DB_Complessivo!$E:$E,DB_Complessivo!$A:$A,"ACT",DB_Complessivo!$H:$H,$A7,DB_Complessivo!$B:$B,D$2)/1000 -> -518.56361 | E7: =SUMIFS(DB_Complessivo!$E:$E,DB_Complessivo!$A:$A,"ACT",DB_Complessivo!$H:$H,$A7,DB_Complessivo!$B:$B,E$2)/1000 -> -574.2685 | K7: 37.DFIN
C8: ATTIVO FISSO NETTO | D8: =SUM(D4:D7) -> -101.11996 | E8: =SUM(E4:E7) -> -242.43907 | G8: Debiti Finanziari (MLT) | H8: =-SUMIFS(DB_Complessivo!$E:$E,DB_Complessivo!$A:$A,"ACT",DB_Complessivo!$H:$H,$K7,DB_Complessivo!$B:$B,D$2)/1000 -> 2345.1617 | I8: =-SUMIFS(DB_Complessivo!$E:$E,DB_Complessivo!$A:$A,"ACT",DB_Complessivo!$H:$H,$K7,DB_Complessivo!$B:$B,E$2)/1000 -> 2062.2307 | K8: 25.I.FIN
G9: Immobilizzazioni Finanziarie | H9: =-SUMIFS(DB_Complessivo!$E:$E,DB_Complessivo!$A:$A,"ACT",DB_Complessivo!$H:$H,$K8,DB_Complessivo!$B:$B,D$2)/1000 -> -1140.2291 | I9: =-SUMIFS(DB_Complessivo!$E:$E,DB_Complessivo!$A:$A,"ACT",DB_Complessivo!$H:$H,$K8,DB_Complessivo!$B:$B,E$2)/1000 -> -1118.8116
A10: 26.MAG | C10: Rimanenze | D10: =SUMIFS(DB_Complessivo!$E:$E,DB_Complessivo!$A:$A,"ACT",DB_Complessivo!$H:$H,$A10,DB_Complessivo!$B:$B,D$2)/1000 -> 573.3745 | E10: =SUMIFS(DB_Complessivo!$E:$E,DB_Complessivo!$A:$A,"ACT",DB_Complessivo!$H:$H,$A10,DB_Complessivo!$B:$B,E$2)/1000 -> 491.05785 | G10: PFN a ML Termine | H10: =SUM(H8:H9) -> 1204.9326 | I10: =SUM(I8:I9) -> 943.41911
A11: 27.CLI | C11: Crediti Commerciali | D11: =SUMIFS(DB_Complessivo!$E:$E,DB_Complessivo!$A:$A,"ACT",DB_Complessivo!$H:$H,$A11,DB_Complessivo!$B:$B,D$2)/1000 -> 1965.6162 | E11: =SUMIFS(DB_Complessivo!$E:$E,DB_Complessivo!$A:$A,"ACT",DB_Complessivo!$H:$H,$A11,DB_Complessivo!$B:$B,E$2)/1000 -> 1353.2129
A12: 28.FOR | C12: Debiti Commerciali | D12: =SUMIFS(DB_Complessivo!$E:$E,DB_Complessivo!$A:$A,"ACT",DB_Complessivo!$H:$H,$A12,DB_Complessivo!$B:$B,D$2)/1000 -> -786.79147 | E12: =SUMIFS(DB_Complessivo!$E:$E,DB_Complessivo!$A:$A,"ACT",DB_Complessivo!$H:$H,$A12,DB_Complessivo!$B:$B,E$2)/1000 -> -827.84899 | G12: POSIZIONE FINANZIARIA NETTA | H12: =H6+H10 -> -1058.2692 | I12: =I6+I10 -> -2058.4493
A13: 29.AC | C13: Altri Crediti | D13: =SUMIFS(DB_Complessivo!$E:$E,DB_Complessivo!$A:$A,"ACT",DB_Complessivo!$H:$H,$A13,DB_Complessivo!$B:$B,D$2)/1000 -> 270.18941 | E13: =SUMIFS(DB_Complessivo!$E:$E,DB_Complessivo!$A:$A,"ACT",DB_Complessivo!$H:$H,$A13,DB_Complessivo!$B:$B,E$2)/1000 -> 374.77313 | K13: 34.CS
A14: 30.AD | C14: Altri Debiti | D14: =SUMIFS(DB_Complessivo!$E:$E,DB_Complessivo!$A:$A,"ACT",DB_Complessivo!$H:$H,$A14,DB_Complessivo!$B:$B,D$2)/1000 -> -648.42184 | E14: =SUMIFS(DB_Complessivo!$E:$E,DB_Complessivo!$A:$A,"ACT",DB_Complessivo!$H:$H,$A14,DB_Complessivo!$B:$B,E$2)/1000 -> -701.66725 | G14: Capitale | H14: =-SUMIFS(DB_Complessivo!$E:$E,DB_Complessivo!$A:$A,"ACT",DB_Complessivo!$H:$H,$K13,DB_Complessivo!$B:$B,D$2)/1000 -> 907.3 | I14: =-SUMIFS(DB_Complessivo!$E:$E,DB_Complessivo!$A:$A,"ACT",DB_Complessivo!$H:$H,$K13,DB_Complessivo!$B:$B,E$2)/1000 -> 951.3 | K14: 35.RIS
A15: 55.DIP | C15: Debiti verso Dipendenti | D15: =SUMIFS(DB_Complessivo!$E:$E,DB_Complessivo!$A:$A,"ACT",DB_Complessivo!$H:$H,$A15,DB_Complessivo!$B:$B,D$2)/1000 -> -244.82115 | E15: =SUMIFS(DB_Complessivo!$E:$E,DB_Complessivo!$A:$A,"ACT",DB_Complessivo!$H:$H,$A15,DB_Complessivo!$B:$B,E$2)/1000 -> -435.97225 | G15: Riserve | H15: =-SUMIFS(DB_Complessivo!$E:$E,DB_Complessivo!$A:$A,"ACT",DB_Complessivo!$H:$H,$K14,DB_Complessivo!$B:$B,D$2)/1000 -> 282.49888 | I15: =-SUMIFS(DB_Complessivo!$E:$E,DB_Complessivo!$A:$A,"ACT",DB_Complessivo!$H:$H,$K14,DB_Complessivo!$B:$B,E$2)/1000 -> 1075.5199
A16: 31.PTN | C16: Posizione Tributaria Netta | D16: =SUMIFS(DB_Complessivo!$E:$E,DB_Complessivo!$A:$A,"ACT",DB_Complessivo!$H:$H,$A16,DB_Complessivo!$B:$B,D$2)/1000 -> 44.04288 | E16: =SUMIFS(DB_Complessivo!$E:$E,DB_Complessivo!$A:$A,"ACT",DB_Complessivo!$H:$H,$A16,DB_Complessivo!$B:$B,E$2)/1000 -> 32.74144 | G16: Utile/Perdita di Esercizio | H16: =+SP!D38 -> 940.53884 | I16: =INDEX(SP!38:38,MATCH(I2,SP!2:2,0)) -> 75.48717
A17: 32.IC | C17: Posizione Intercompany | D17: =SUMIFS(DB_Complessivo!$E:$E,DB_Complessivo!$A:$A,"ACT",DB_Complessivo!$H:$H,$A17,DB_Complessivo!$B:$B,D$2)/1000 -> 0 | E17: =SUMIFS(DB_Complessivo!$E:$E,DB_Complessivo!$A:$A,"ACT",DB_Complessivo!$H:$H,$A17,DB_Complessivo!$B:$B,E$2)/1000 -> 0 | G17: PATRIMONIO NETTO | H17: =SUM(H14:H16) -> 2130.3377 | I17: =SUM(I14:I16) -> 2102.307
C18: CAPITALE CIRCOLANTE NETTO OPERATIVO | D18: =SUM(D10:D17) -> 1173.1885 | E18: =SUM(E10:E17) -> 286.29679
C20: CAPITALE INVESTITO NETTO OPERATIVO | D20: =SUM(D8,D18) -> 1072.0685 | E20: =SUM(E8,E18) -> 43.857723 | G20: TOTALE FONTI FINANZIARIE | H20: =SUM(H12,H17) -> 1072.0685 | I20: =SUM(I12,I17) -> 43.857723
C39: Check | D39: =D20-H20 -> 0 | E39: =E20-I20 -> 1.7053026e-13

Sheet RICLASSIFICATI -->

Sheet CE_CEE
B1: Riclassifica IV Direttiva CEE | C1: =+INDICE!B2 -> 45838 | D1: 45657
A3: A) | B3: A) VALORE DELLA PRODUZIONE | C3: =+SUM(C4:C6) -> 3857893.6 | D3: =+SUM(D4:D6) -> 7465208.9
A4: A.1) | B4: 1) ricavi delle vendite e delle prestazioni | C4: =-SUMIFS(DB_Complessivo!$E:$E,DB_Complessivo!$B:$B,C$1,DB_Complessivo!$A:$A,"ACT",DB_Complessivo!$L:$L,$A4) -> 3280198.3 | D4: =-SUMIFS(DB_Complessivo!$E:$E,DB_Complessivo!$B:$B,D$1,DB_Complessivo!$A:$A,"ACT",DB_Complessivo!$L:$L,$A4) -> 6470133.4
A5: A.2) | B5: 2) variazioni delle rimanenze di prodotti in corso di lavorazione, semilavorati e finiti | C5: =-SUMIFS(DB_Complessivo!$E:$E,DB_Complessivo!$B:$B,C$1,DB_Complessivo!$A:$A,"ACT",DB_Complessivo!$L:$L,$A5) -> -30723.34 | D5: =-SUMIFS(DB_Complessivo!$E:$E,DB_Complessivo!$B:$B,D$1,DB_Complessivo!$A:$A,"ACT",DB_Complessivo!$L:$L,$A5) -> -113780.36
A6: A.5) | B6: 5) altri ricavi e proventi, con separata indicazione dei contributi in conto esercizio | C6: =-SUMIFS(DB_Complessivo!$E:$E,DB_Complessivo!$B:$B,C$1,DB_Complessivo!$A:$A,"ACT",DB_Complessivo!$L:$L,$A6) -> 608418.58 | D6: =-SUMIFS(DB_Complessivo!$E:$E,DB_Complessivo!$B:$B,D$1,DB_Complessivo!$A:$A,"ACT",DB_Complessivo!$L:$L,$A6) -> 1108855.9
A8: B) | B8: B) COSTI DELLA PRODUZIONE | C8: =+SUM(C9:C16) -> 3794084.2 | D8: =+SUM(D9:D16) -> 6569006.6
A9: B.6) | B9: 6) per materie prime, suddidiarie, di consumo e di merci | C9: =SUMIFS(DB_Complessivo!$E:$E,DB_Complessivo!$B:$B,C$1,DB_Complessivo!$A:$A,"ACT",DB_Complessivo!$L:$L,$A9) -> 338334.64 | D9: =SUMIFS(DB_Complessivo!$E:$E,DB_Complessivo!$B:$B,D$1,DB_Complessivo!$A:$A,"ACT",DB_Complessivo!$L:$L,$A9) -> 711929.55
A10: B.7) | B10: 7) per servizi | C10: =SUMIFS(DB_Complessivo!$E:$E,DB_Complessivo!$B:$B,C$1,DB_Complessivo!$A:$A,"ACT",DB_Complessivo!$L:$L,$A10) -> 1114124 | D10: =SUMIFS(DB_Complessivo!$E:$E,DB_Complessivo!$B:$B,D$1,DB_Complessivo!$A:$A,"ACT",DB_Complessivo!$L:$L,$A10) -> 1955676.5
A11: B.8) | B11: 8) per godimento di beni di terzi | C11: =SUMIFS(DB_Complessivo!$E:$E,DB_Complessivo!$B:$B,C$1,DB_Complessivo!$A:$A,"ACT",DB_Complessivo!$L:$L,$A11) -> 69418.2 | D11: =SUMIFS(DB_Complessivo!$E:$E,DB_Complessivo!$B:$B,D$1,DB_Complessivo!$A:$A,"ACT",DB_Complessivo!$L:$L,$A11) -> 188758.52
